2024-05-08 20:39:40,047 (66573/MainThread) litecli.main ERROR - sql: 'select * from movies -S;', error: OperationalError('near "-": syntax error')
2024-05-08 20:39:40,049 (66573/MainThread) litecli.main ERROR - traceback: 'Traceback (most recent call last):\n  File "/opt/homebrew/Cellar/litecli/1.11.0/libexec/lib/python3.12/site-packages/litecli/sqlexecute.py", line 125, in run\n    for result in special.execute(cur, sql):\n                  ^^^^^^^^^^^^^^^^^^^^^^^^^\n  File "/opt/homebrew/Cellar/litecli/1.11.0/libexec/lib/python3.12/site-packages/litecli/packages/special/main.py", line 109, in execute\n    raise CommandNotFound\nlitecli.packages.special.main.CommandNotFound\n\nDuring handling of the above exception, another exception occurred:\n\nTraceback (most recent call last):\n  File "/opt/homebrew/Cellar/litecli/1.11.0/libexec/lib/python3.12/site-packages/litecli/main.py", line 453, in one_iteration\n    for title, cur, headers, status in res:\n  File "/opt/homebrew/Cellar/litecli/1.11.0/libexec/lib/python3.12/site-packages/litecli/sqlexecute.py", line 132, in run\n    cur.execute(sql)\nsqlite3.OperationalError: near "-": syntax error\n'
2024-05-08 20:40:15,147 (66875/MainThread) litecli.main ERROR - sql: 'select * from movies -S;', error: OperationalError('near "-": syntax error')
2024-05-08 20:40:15,149 (66875/MainThread) litecli.main ERROR - traceback: 'Traceback (most recent call last):\n  File "/opt/homebrew/Cellar/litecli/1.11.0/libexec/lib/python3.12/site-packages/litecli/sqlexecute.py", line 125, in run\n    for result in special.execute(cur, sql):\n                  ^^^^^^^^^^^^^^^^^^^^^^^^^\n  File "/opt/homebrew/Cellar/litecli/1.11.0/libexec/lib/python3.12/site-packages/litecli/packages/special/main.py", line 109, in execute\n    raise CommandNotFound\nlitecli.packages.special.main.CommandNotFound\n\nDuring handling of the above exception, another exception occurred:\n\nTraceback (most recent call last):\n  File "/opt/homebrew/Cellar/litecli/1.11.0/libexec/lib/python3.12/site-packages/litecli/main.py", line 453, in one_iteration\n    for title, cur, headers, status in res:\n  File "/opt/homebrew/Cellar/litecli/1.11.0/libexec/lib/python3.12/site-packages/litecli/sqlexecute.py", line 132, in run\n    cur.execute(sql)\nsqlite3.OperationalError: near "-": syntax error\n'
2024-05-08 20:40:22,937 (66875/MainThread) litecli.main ERROR - sql: 'c', error: OperationalError('near "c": syntax error')
2024-05-08 20:40:22,937 (66875/MainThread) litecli.main ERROR - traceback: 'Traceback (most recent call last):\n  File "/opt/homebrew/Cellar/litecli/1.11.0/libexec/lib/python3.12/site-packages/litecli/sqlexecute.py", line 125, in run\n    for result in special.execute(cur, sql):\n                  ^^^^^^^^^^^^^^^^^^^^^^^^^\n  File "/opt/homebrew/Cellar/litecli/1.11.0/libexec/lib/python3.12/site-packages/litecli/packages/special/main.py", line 109, in execute\n    raise CommandNotFound\nlitecli.packages.special.main.CommandNotFound\n\nDuring handling of the above exception, another exception occurred:\n\nTraceback (most recent call last):\n  File "/opt/homebrew/Cellar/litecli/1.11.0/libexec/lib/python3.12/site-packages/litecli/main.py", line 453, in one_iteration\n    for title, cur, headers, status in res:\n  File "/opt/homebrew/Cellar/litecli/1.11.0/libexec/lib/python3.12/site-packages/litecli/sqlexecute.py", line 132, in run\n    cur.execute(sql)\nsqlite3.OperationalError: near "c": syntax error\n'
2024-05-08 20:42:51,657 (67304/MainThread) litecli.main ERROR - sql: 'clear', error: OperationalError('near "clear": syntax error')
2024-05-08 20:42:51,659 (67304/MainThread) litecli.main ERROR - traceback: 'Traceback (most recent call last):\n  File "/opt/homebrew/Cellar/litecli/1.11.0/libexec/lib/python3.12/site-packages/litecli/sqlexecute.py", line 125, in run\n    for result in special.execute(cur, sql):\n                  ^^^^^^^^^^^^^^^^^^^^^^^^^\n  File "/opt/homebrew/Cellar/litecli/1.11.0/libexec/lib/python3.12/site-packages/litecli/packages/special/main.py", line 109, in execute\n    raise CommandNotFound\nlitecli.packages.special.main.CommandNotFound\n\nDuring handling of the above exception, another exception occurred:\n\nTraceback (most recent call last):\n  File "/opt/homebrew/Cellar/litecli/1.11.0/libexec/lib/python3.12/site-packages/litecli/main.py", line 453, in one_iteration\n    for title, cur, headers, status in res:\n  File "/opt/homebrew/Cellar/litecli/1.11.0/libexec/lib/python3.12/site-packages/litecli/sqlexecute.py", line 132, in run\n    cur.execute(sql)\nsqlite3.OperationalError: near "clear": syntax error\n'
2024-05-08 20:43:13,839 (67304/MainThread) litecli.main ERROR - sql: '.albums;', error: OperationalError('near ".": syntax error')
2024-05-08 20:43:13,839 (67304/MainThread) litecli.main ERROR - traceback: 'Traceback (most recent call last):\n  File "/opt/homebrew/Cellar/litecli/1.11.0/libexec/lib/python3.12/site-packages/litecli/sqlexecute.py", line 125, in run\n    for result in special.execute(cur, sql):\n                  ^^^^^^^^^^^^^^^^^^^^^^^^^\n  File "/opt/homebrew/Cellar/litecli/1.11.0/libexec/lib/python3.12/site-packages/litecli/packages/special/main.py", line 109, in execute\n    raise CommandNotFound\nlitecli.packages.special.main.CommandNotFound\n\nDuring handling of the above exception, another exception occurred:\n\nTraceback (most recent call last):\n  File "/opt/homebrew/Cellar/litecli/1.11.0/libexec/lib/python3.12/site-packages/litecli/main.py", line 453, in one_iteration\n    for title, cur, headers, status in res:\n  File "/opt/homebrew/Cellar/litecli/1.11.0/libexec/lib/python3.12/site-packages/litecli/sqlexecute.py", line 132, in run\n    cur.execute(sql)\nsqlite3.OperationalError: near ".": syntax error\n'
2024-05-08 20:43:16,361 (67304/MainThread) litecli.main ERROR - sql: 'albums;', error: OperationalError('near "albums": syntax error')
2024-05-08 20:43:16,362 (67304/MainThread) litecli.main ERROR - traceback: 'Traceback (most recent call last):\n  File "/opt/homebrew/Cellar/litecli/1.11.0/libexec/lib/python3.12/site-packages/litecli/sqlexecute.py", line 125, in run\n    for result in special.execute(cur, sql):\n                  ^^^^^^^^^^^^^^^^^^^^^^^^^\n  File "/opt/homebrew/Cellar/litecli/1.11.0/libexec/lib/python3.12/site-packages/litecli/packages/special/main.py", line 109, in execute\n    raise CommandNotFound\nlitecli.packages.special.main.CommandNotFound\n\nDuring handling of the above exception, another exception occurred:\n\nTraceback (most recent call last):\n  File "/opt/homebrew/Cellar/litecli/1.11.0/libexec/lib/python3.12/site-packages/litecli/main.py", line 453, in one_iteration\n    for title, cur, headers, status in res:\n  File "/opt/homebrew/Cellar/litecli/1.11.0/libexec/lib/python3.12/site-packages/litecli/sqlexecute.py", line 132, in run\n    cur.execute(sql)\nsqlite3.OperationalError: near "albums": syntax error\n'
2024-05-08 20:43:17,644 (67304/MainThread) litecli.main ERROR - sql: '.', error: OperationalError('near ".": syntax error')
2024-05-08 20:43:17,645 (67304/MainThread) litecli.main ERROR - traceback: 'Traceback (most recent call last):\n  File "/opt/homebrew/Cellar/litecli/1.11.0/libexec/lib/python3.12/site-packages/litecli/sqlexecute.py", line 125, in run\n    for result in special.execute(cur, sql):\n                  ^^^^^^^^^^^^^^^^^^^^^^^^^\n  File "/opt/homebrew/Cellar/litecli/1.11.0/libexec/lib/python3.12/site-packages/litecli/packages/special/main.py", line 109, in execute\n    raise CommandNotFound\nlitecli.packages.special.main.CommandNotFound\n\nDuring handling of the above exception, another exception occurred:\n\nTraceback (most recent call last):\n  File "/opt/homebrew/Cellar/litecli/1.11.0/libexec/lib/python3.12/site-packages/litecli/main.py", line 453, in one_iteration\n    for title, cur, headers, status in res:\n  File "/opt/homebrew/Cellar/litecli/1.11.0/libexec/lib/python3.12/site-packages/litecli/sqlexecute.py", line 132, in run\n    cur.execute(sql)\nsqlite3.OperationalError: near ".": syntax error\n'
2024-05-08 21:34:00,240 (75653/MainThread) litecli.main ERROR - sql: 'SELECT * FROM movies WHERE title ILIKE "%and%";\n', error: OperationalError('near "ILIKE": syntax error')
2024-05-08 21:34:00,242 (75653/MainThread) litecli.main ERROR - traceback: 'Traceback (most recent call last):\n  File "/opt/homebrew/Cellar/litecli/1.11.0/libexec/lib/python3.12/site-packages/litecli/sqlexecute.py", line 125, in run\n    for result in special.execute(cur, sql):\n                  ^^^^^^^^^^^^^^^^^^^^^^^^^\n  File "/opt/homebrew/Cellar/litecli/1.11.0/libexec/lib/python3.12/site-packages/litecli/packages/special/main.py", line 109, in execute\n    raise CommandNotFound\nlitecli.packages.special.main.CommandNotFound\n\nDuring handling of the above exception, another exception occurred:\n\nTraceback (most recent call last):\n  File "/opt/homebrew/Cellar/litecli/1.11.0/libexec/lib/python3.12/site-packages/litecli/main.py", line 453, in one_iteration\n    for title, cur, headers, status in res:\n  File "/opt/homebrew/Cellar/litecli/1.11.0/libexec/lib/python3.12/site-packages/litecli/sqlexecute.py", line 132, in run\n    cur.execute(sql)\nsqlite3.OperationalError: near "ILIKE": syntax error\n'
2024-05-08 23:10:11,680 (90597/MainThread) litecli.main ERROR - sql: 'select * from films;', error: OperationalError('no such table: films')
2024-05-08 23:10:11,682 (90597/MainThread) litecli.main ERROR - traceback: 'Traceback (most recent call last):\n  File "/opt/homebrew/Cellar/litecli/1.11.0/libexec/lib/python3.12/site-packages/litecli/sqlexecute.py", line 125, in run\n    for result in special.execute(cur, sql):\n                  ^^^^^^^^^^^^^^^^^^^^^^^^^\n  File "/opt/homebrew/Cellar/litecli/1.11.0/libexec/lib/python3.12/site-packages/litecli/packages/special/main.py", line 109, in execute\n    raise CommandNotFound\nlitecli.packages.special.main.CommandNotFound\n\nDuring handling of the above exception, another exception occurred:\n\nTraceback (most recent call last):\n  File "/opt/homebrew/Cellar/litecli/1.11.0/libexec/lib/python3.12/site-packages/litecli/main.py", line 453, in one_iteration\n    for title, cur, headers, status in res:\n  File "/opt/homebrew/Cellar/litecli/1.11.0/libexec/lib/python3.12/site-packages/litecli/sqlexecute.py", line 132, in run\n    cur.execute(sql)\nsqlite3.OperationalError: no such table: films\n'
2024-05-08 23:10:49,041 (90746/MainThread) litecli.main ERROR - sql: 'select * from films;', error: OperationalError('no such table: films')
2024-05-08 23:10:49,044 (90746/MainThread) litecli.main ERROR - traceback: 'Traceback (most recent call last):\n  File "/opt/homebrew/Cellar/litecli/1.11.0/libexec/lib/python3.12/site-packages/litecli/sqlexecute.py", line 125, in run\n    for result in special.execute(cur, sql):\n                  ^^^^^^^^^^^^^^^^^^^^^^^^^\n  File "/opt/homebrew/Cellar/litecli/1.11.0/libexec/lib/python3.12/site-packages/litecli/packages/special/main.py", line 109, in execute\n    raise CommandNotFound\nlitecli.packages.special.main.CommandNotFound\n\nDuring handling of the above exception, another exception occurred:\n\nTraceback (most recent call last):\n  File "/opt/homebrew/Cellar/litecli/1.11.0/libexec/lib/python3.12/site-packages/litecli/main.py", line 453, in one_iteration\n    for title, cur, headers, status in res:\n  File "/opt/homebrew/Cellar/litecli/1.11.0/libexec/lib/python3.12/site-packages/litecli/sqlexecute.py", line 132, in run\n    cur.execute(sql)\nsqlite3.OperationalError: no such table: films\n'
2024-05-08 23:10:51,828 (90746/MainThread) litecli.main ERROR - sql: 'select * from movies;', error: OperationalError('no such table: movies')
2024-05-08 23:10:51,828 (90746/MainThread) litecli.main ERROR - traceback: 'Traceback (most recent call last):\n  File "/opt/homebrew/Cellar/litecli/1.11.0/libexec/lib/python3.12/site-packages/litecli/sqlexecute.py", line 125, in run\n    for result in special.execute(cur, sql):\n                  ^^^^^^^^^^^^^^^^^^^^^^^^^\n  File "/opt/homebrew/Cellar/litecli/1.11.0/libexec/lib/python3.12/site-packages/litecli/packages/special/main.py", line 109, in execute\n    raise CommandNotFound\nlitecli.packages.special.main.CommandNotFound\n\nDuring handling of the above exception, another exception occurred:\n\nTraceback (most recent call last):\n  File "/opt/homebrew/Cellar/litecli/1.11.0/libexec/lib/python3.12/site-packages/litecli/main.py", line 453, in one_iteration\n    for title, cur, headers, status in res:\n  File "/opt/homebrew/Cellar/litecli/1.11.0/libexec/lib/python3.12/site-packages/litecli/sqlexecute.py", line 132, in run\n    cur.execute(sql)\nsqlite3.OperationalError: no such table: movies\n'
2024-05-08 23:15:45,345 (91708/MainThread) litecli.main ERROR - sql: 'c', error: OperationalError('near "c": syntax error')
2024-05-08 23:15:45,346 (91708/MainThread) litecli.main ERROR - traceback: 'Traceback (most recent call last):\n  File "/opt/homebrew/Cellar/litecli/1.11.0/libexec/lib/python3.12/site-packages/litecli/sqlexecute.py", line 125, in run\n    for result in special.execute(cur, sql):\n                  ^^^^^^^^^^^^^^^^^^^^^^^^^\n  File "/opt/homebrew/Cellar/litecli/1.11.0/libexec/lib/python3.12/site-packages/litecli/packages/special/main.py", line 109, in execute\n    raise CommandNotFound\nlitecli.packages.special.main.CommandNotFound\n\nDuring handling of the above exception, another exception occurred:\n\nTraceback (most recent call last):\n  File "/opt/homebrew/Cellar/litecli/1.11.0/libexec/lib/python3.12/site-packages/litecli/main.py", line 453, in one_iteration\n    for title, cur, headers, status in res:\n  File "/opt/homebrew/Cellar/litecli/1.11.0/libexec/lib/python3.12/site-packages/litecli/sqlexecute.py", line 132, in run\n    cur.execute(sql)\nsqlite3.OperationalError: near "c": syntax error\n'
2024-05-08 23:17:50,976 (91708/MainThread) litecli.main ERROR - sql: 'select * EXCEPT url_poster from films;', error: OperationalError('near "url_poster": syntax error')
2024-05-08 23:17:50,977 (91708/MainThread) litecli.main ERROR - traceback: 'Traceback (most recent call last):\n  File "/opt/homebrew/Cellar/litecli/1.11.0/libexec/lib/python3.12/site-packages/litecli/sqlexecute.py", line 125, in run\n    for result in special.execute(cur, sql):\n                  ^^^^^^^^^^^^^^^^^^^^^^^^^\n  File "/opt/homebrew/Cellar/litecli/1.11.0/libexec/lib/python3.12/site-packages/litecli/packages/special/main.py", line 109, in execute\n    raise CommandNotFound\nlitecli.packages.special.main.CommandNotFound\n\nDuring handling of the above exception, another exception occurred:\n\nTraceback (most recent call last):\n  File "/opt/homebrew/Cellar/litecli/1.11.0/libexec/lib/python3.12/site-packages/litecli/main.py", line 453, in one_iteration\n    for title, cur, headers, status in res:\n  File "/opt/homebrew/Cellar/litecli/1.11.0/libexec/lib/python3.12/site-packages/litecli/sqlexecute.py", line 132, in run\n    cur.execute(sql)\nsqlite3.OperationalError: near "url_poster": syntax error\n'
2024-05-08 23:18:11,838 (91708/MainThread) litecli.main ERROR - sql: 'select * EXCEPT url_poster from films;', error: OperationalError('near "url_poster": syntax error')
2024-05-08 23:18:11,838 (91708/MainThread) litecli.main ERROR - traceback: 'Traceback (most recent call last):\n  File "/opt/homebrew/Cellar/litecli/1.11.0/libexec/lib/python3.12/site-packages/litecli/sqlexecute.py", line 125, in run\n    for result in special.execute(cur, sql):\n                  ^^^^^^^^^^^^^^^^^^^^^^^^^\n  File "/opt/homebrew/Cellar/litecli/1.11.0/libexec/lib/python3.12/site-packages/litecli/packages/special/main.py", line 109, in execute\n    raise CommandNotFound\nlitecli.packages.special.main.CommandNotFound\n\nDuring handling of the above exception, another exception occurred:\n\nTraceback (most recent call last):\n  File "/opt/homebrew/Cellar/litecli/1.11.0/libexec/lib/python3.12/site-packages/litecli/main.py", line 453, in one_iteration\n    for title, cur, headers, status in res:\n  File "/opt/homebrew/Cellar/litecli/1.11.0/libexec/lib/python3.12/site-packages/litecli/sqlexecute.py", line 132, in run\n    cur.execute(sql)\nsqlite3.OperationalError: near "url_poster": syntax error\n'
2024-05-08 23:19:00,665 (91708/MainThread) litecli.main ERROR - sql: ':', error: OperationalError('unrecognized token: ":"')
2024-05-08 23:19:00,667 (91708/MainThread) litecli.main ERROR - traceback: 'Traceback (most recent call last):\n  File "/opt/homebrew/Cellar/litecli/1.11.0/libexec/lib/python3.12/site-packages/litecli/sqlexecute.py", line 125, in run\n    for result in special.execute(cur, sql):\n                  ^^^^^^^^^^^^^^^^^^^^^^^^^\n  File "/opt/homebrew/Cellar/litecli/1.11.0/libexec/lib/python3.12/site-packages/litecli/packages/special/main.py", line 109, in execute\n    raise CommandNotFound\nlitecli.packages.special.main.CommandNotFound\n\nDuring handling of the above exception, another exception occurred:\n\nTraceback (most recent call last):\n  File "/opt/homebrew/Cellar/litecli/1.11.0/libexec/lib/python3.12/site-packages/litecli/main.py", line 453, in one_iteration\n    for title, cur, headers, status in res:\n  File "/opt/homebrew/Cellar/litecli/1.11.0/libexec/lib/python3.12/site-packages/litecli/sqlexecute.py", line 132, in run\n    cur.execute(sql)\nsqlite3.OperationalError: unrecognized token: ":"\n'
2024-05-08 23:26:37,710 (91708/MainThread) litecli.main ERROR - sql: 'select * from movies;', error: OperationalError('no such table: movies')
2024-05-08 23:26:37,711 (91708/MainThread) litecli.main ERROR - traceback: 'Traceback (most recent call last):\n  File "/opt/homebrew/Cellar/litecli/1.11.0/libexec/lib/python3.12/site-packages/litecli/sqlexecute.py", line 125, in run\n    for result in special.execute(cur, sql):\n                  ^^^^^^^^^^^^^^^^^^^^^^^^^\n  File "/opt/homebrew/Cellar/litecli/1.11.0/libexec/lib/python3.12/site-packages/litecli/packages/special/main.py", line 109, in execute\n    raise CommandNotFound\nlitecli.packages.special.main.CommandNotFound\n\nDuring handling of the above exception, another exception occurred:\n\nTraceback (most recent call last):\n  File "/opt/homebrew/Cellar/litecli/1.11.0/libexec/lib/python3.12/site-packages/litecli/main.py", line 453, in one_iteration\n    for title, cur, headers, status in res:\n  File "/opt/homebrew/Cellar/litecli/1.11.0/libexec/lib/python3.12/site-packages/litecli/sqlexecute.py", line 132, in run\n    cur.execute(sql)\nsqlite3.OperationalError: no such table: movies\n'
2024-05-08 23:52:57,784 (91708/MainThread) litecli.main ERROR - sql: 'drop table films;', error: OperationalError('no such table: films')
2024-05-08 23:52:57,786 (91708/MainThread) litecli.main ERROR - traceback: 'Traceback (most recent call last):\n  File "/opt/homebrew/Cellar/litecli/1.11.0/libexec/lib/python3.12/site-packages/litecli/sqlexecute.py", line 125, in run\n    for result in special.execute(cur, sql):\n                  ^^^^^^^^^^^^^^^^^^^^^^^^^\n  File "/opt/homebrew/Cellar/litecli/1.11.0/libexec/lib/python3.12/site-packages/litecli/packages/special/main.py", line 109, in execute\n    raise CommandNotFound\nlitecli.packages.special.main.CommandNotFound\n\nDuring handling of the above exception, another exception occurred:\n\nTraceback (most recent call last):\n  File "/opt/homebrew/Cellar/litecli/1.11.0/libexec/lib/python3.12/site-packages/litecli/main.py", line 453, in one_iteration\n    for title, cur, headers, status in res:\n  File "/opt/homebrew/Cellar/litecli/1.11.0/libexec/lib/python3.12/site-packages/litecli/sqlexecute.py", line 132, in run\n    cur.execute(sql)\nsqlite3.OperationalError: no such table: films\n'
2024-05-08 23:54:09,233 (91708/MainThread) litecli.main ERROR - sql: 'drop table films;', error: OperationalError('no such table: films')
2024-05-08 23:54:09,235 (91708/MainThread) litecli.main ERROR - traceback: 'Traceback (most recent call last):\n  File "/opt/homebrew/Cellar/litecli/1.11.0/libexec/lib/python3.12/site-packages/litecli/sqlexecute.py", line 125, in run\n    for result in special.execute(cur, sql):\n                  ^^^^^^^^^^^^^^^^^^^^^^^^^\n  File "/opt/homebrew/Cellar/litecli/1.11.0/libexec/lib/python3.12/site-packages/litecli/packages/special/main.py", line 109, in execute\n    raise CommandNotFound\nlitecli.packages.special.main.CommandNotFound\n\nDuring handling of the above exception, another exception occurred:\n\nTraceback (most recent call last):\n  File "/opt/homebrew/Cellar/litecli/1.11.0/libexec/lib/python3.12/site-packages/litecli/main.py", line 453, in one_iteration\n    for title, cur, headers, status in res:\n  File "/opt/homebrew/Cellar/litecli/1.11.0/libexec/lib/python3.12/site-packages/litecli/sqlexecute.py", line 132, in run\n    cur.execute(sql)\nsqlite3.OperationalError: no such table: films\n'
2024-05-09 00:03:07,933 (91708/MainThread) litecli.main ERROR - sql: 'drop table films;', error: OperationalError('no such table: films')
2024-05-09 00:03:07,935 (91708/MainThread) litecli.main ERROR - traceback: 'Traceback (most recent call last):\n  File "/opt/homebrew/Cellar/litecli/1.11.0/libexec/lib/python3.12/site-packages/litecli/sqlexecute.py", line 125, in run\n    for result in special.execute(cur, sql):\n                  ^^^^^^^^^^^^^^^^^^^^^^^^^\n  File "/opt/homebrew/Cellar/litecli/1.11.0/libexec/lib/python3.12/site-packages/litecli/packages/special/main.py", line 109, in execute\n    raise CommandNotFound\nlitecli.packages.special.main.CommandNotFound\n\nDuring handling of the above exception, another exception occurred:\n\nTraceback (most recent call last):\n  File "/opt/homebrew/Cellar/litecli/1.11.0/libexec/lib/python3.12/site-packages/litecli/main.py", line 453, in one_iteration\n    for title, cur, headers, status in res:\n  File "/opt/homebrew/Cellar/litecli/1.11.0/libexec/lib/python3.12/site-packages/litecli/sqlexecute.py", line 132, in run\n    cur.execute(sql)\nsqlite3.OperationalError: no such table: films\n'
2024-05-09 00:05:20,364 (91708/MainThread) litecli.main ERROR - sql: 'drop table films;', error: OperationalError('no such table: films')
2024-05-09 00:05:20,366 (91708/MainThread) litecli.main ERROR - traceback: 'Traceback (most recent call last):\n  File "/opt/homebrew/Cellar/litecli/1.11.0/libexec/lib/python3.12/site-packages/litecli/sqlexecute.py", line 125, in run\n    for result in special.execute(cur, sql):\n                  ^^^^^^^^^^^^^^^^^^^^^^^^^\n  File "/opt/homebrew/Cellar/litecli/1.11.0/libexec/lib/python3.12/site-packages/litecli/packages/special/main.py", line 109, in execute\n    raise CommandNotFound\nlitecli.packages.special.main.CommandNotFound\n\nDuring handling of the above exception, another exception occurred:\n\nTraceback (most recent call last):\n  File "/opt/homebrew/Cellar/litecli/1.11.0/libexec/lib/python3.12/site-packages/litecli/main.py", line 453, in one_iteration\n    for title, cur, headers, status in res:\n  File "/opt/homebrew/Cellar/litecli/1.11.0/libexec/lib/python3.12/site-packages/litecli/sqlexecute.py", line 132, in run\n    cur.execute(sql)\nsqlite3.OperationalError: no such table: films\n'
2024-05-09 00:24:17,872 (91708/MainThread) litecli.main ERROR - sql: 'select count * from films;', error: OperationalError('near "from": syntax error')
2024-05-09 00:24:17,872 (91708/MainThread) litecli.main ERROR - traceback: 'Traceback (most recent call last):\n  File "/opt/homebrew/Cellar/litecli/1.11.0/libexec/lib/python3.12/site-packages/litecli/sqlexecute.py", line 125, in run\n    for result in special.execute(cur, sql):\n                  ^^^^^^^^^^^^^^^^^^^^^^^^^\n  File "/opt/homebrew/Cellar/litecli/1.11.0/libexec/lib/python3.12/site-packages/litecli/packages/special/main.py", line 109, in execute\n    raise CommandNotFound\nlitecli.packages.special.main.CommandNotFound\n\nDuring handling of the above exception, another exception occurred:\n\nTraceback (most recent call last):\n  File "/opt/homebrew/Cellar/litecli/1.11.0/libexec/lib/python3.12/site-packages/litecli/main.py", line 453, in one_iteration\n    for title, cur, headers, status in res:\n  File "/opt/homebrew/Cellar/litecli/1.11.0/libexec/lib/python3.12/site-packages/litecli/sqlexecute.py", line 132, in run\n    cur.execute(sql)\nsqlite3.OperationalError: near "from": syntax error\n'
2024-05-09 00:24:44,733 (91708/MainThread) litecli.main ERROR - sql: 'drop table films;', error: OperationalError('no such table: films')
2024-05-09 00:24:44,734 (91708/MainThread) litecli.main ERROR - traceback: 'Traceback (most recent call last):\n  File "/opt/homebrew/Cellar/litecli/1.11.0/libexec/lib/python3.12/site-packages/litecli/sqlexecute.py", line 125, in run\n    for result in special.execute(cur, sql):\n                  ^^^^^^^^^^^^^^^^^^^^^^^^^\n  File "/opt/homebrew/Cellar/litecli/1.11.0/libexec/lib/python3.12/site-packages/litecli/packages/special/main.py", line 109, in execute\n    raise CommandNotFound\nlitecli.packages.special.main.CommandNotFound\n\nDuring handling of the above exception, another exception occurred:\n\nTraceback (most recent call last):\n  File "/opt/homebrew/Cellar/litecli/1.11.0/libexec/lib/python3.12/site-packages/litecli/main.py", line 453, in one_iteration\n    for title, cur, headers, status in res:\n  File "/opt/homebrew/Cellar/litecli/1.11.0/libexec/lib/python3.12/site-packages/litecli/sqlexecute.py", line 132, in run\n    cur.execute(sql)\nsqlite3.OperationalError: no such table: films\n'
2024-05-09 00:28:04,285 (91708/MainThread) litecli.main ERROR - sql: 'c', error: OperationalError('near "c": syntax error')
2024-05-09 00:28:04,286 (91708/MainThread) litecli.main ERROR - traceback: 'Traceback (most recent call last):\n  File "/opt/homebrew/Cellar/litecli/1.11.0/libexec/lib/python3.12/site-packages/litecli/sqlexecute.py", line 125, in run\n    for result in special.execute(cur, sql):\n                  ^^^^^^^^^^^^^^^^^^^^^^^^^\n  File "/opt/homebrew/Cellar/litecli/1.11.0/libexec/lib/python3.12/site-packages/litecli/packages/special/main.py", line 109, in execute\n    raise CommandNotFound\nlitecli.packages.special.main.CommandNotFound\n\nDuring handling of the above exception, another exception occurred:\n\nTraceback (most recent call last):\n  File "/opt/homebrew/Cellar/litecli/1.11.0/libexec/lib/python3.12/site-packages/litecli/main.py", line 453, in one_iteration\n    for title, cur, headers, status in res:\n  File "/opt/homebrew/Cellar/litecli/1.11.0/libexec/lib/python3.12/site-packages/litecli/sqlexecute.py", line 132, in run\n    cur.execute(sql)\nsqlite3.OperationalError: near "c": syntax error\n'
2024-05-09 00:43:42,440 (7750/MainThread) litecli.main ERROR - sql: '.reload', error: OperationalError('near ".": syntax error')
2024-05-09 00:43:42,442 (7750/MainThread) litecli.main ERROR - traceback: 'Traceback (most recent call last):\n  File "/opt/homebrew/Cellar/litecli/1.11.0/libexec/lib/python3.12/site-packages/litecli/sqlexecute.py", line 125, in run\n    for result in special.execute(cur, sql):\n                  ^^^^^^^^^^^^^^^^^^^^^^^^^\n  File "/opt/homebrew/Cellar/litecli/1.11.0/libexec/lib/python3.12/site-packages/litecli/packages/special/main.py", line 109, in execute\n    raise CommandNotFound\nlitecli.packages.special.main.CommandNotFound\n\nDuring handling of the above exception, another exception occurred:\n\nTraceback (most recent call last):\n  File "/opt/homebrew/Cellar/litecli/1.11.0/libexec/lib/python3.12/site-packages/litecli/main.py", line 453, in one_iteration\n    for title, cur, headers, status in res:\n  File "/opt/homebrew/Cellar/litecli/1.11.0/libexec/lib/python3.12/site-packages/litecli/sqlexecute.py", line 132, in run\n    cur.execute(sql)\nsqlite3.OperationalError: near ".": syntax error\n'
2024-05-09 01:53:43,389 (75653/MainThread) litecli.main ERROR - sql: 'c', error: OperationalError('near "c": syntax error')
2024-05-09 01:53:43,391 (75653/MainThread) litecli.main ERROR - traceback: 'Traceback (most recent call last):\n  File "/opt/homebrew/Cellar/litecli/1.11.0/libexec/lib/python3.12/site-packages/litecli/sqlexecute.py", line 125, in run\n    for result in special.execute(cur, sql):\n                  ^^^^^^^^^^^^^^^^^^^^^^^^^\n  File "/opt/homebrew/Cellar/litecli/1.11.0/libexec/lib/python3.12/site-packages/litecli/packages/special/main.py", line 109, in execute\n    raise CommandNotFound\nlitecli.packages.special.main.CommandNotFound\n\nDuring handling of the above exception, another exception occurred:\n\nTraceback (most recent call last):\n  File "/opt/homebrew/Cellar/litecli/1.11.0/libexec/lib/python3.12/site-packages/litecli/main.py", line 453, in one_iteration\n    for title, cur, headers, status in res:\n  File "/opt/homebrew/Cellar/litecli/1.11.0/libexec/lib/python3.12/site-packages/litecli/sqlexecute.py", line 132, in run\n    cur.execute(sql)\nsqlite3.OperationalError: near "c": syntax error\n'
2024-05-11 13:38:48,278 (74828/MainThread) litecli.main ERROR - sql: 'ALTER TABLE employees RENAME COLUMN EmployeeId, Title TO employeeid, title;', error: OperationalError('near ",": syntax error')
2024-05-11 13:38:48,281 (74828/MainThread) litecli.main ERROR - traceback: 'Traceback (most recent call last):\n  File "/opt/homebrew/Cellar/litecli/1.11.0/libexec/lib/python3.12/site-packages/litecli/sqlexecute.py", line 125, in run\n    for result in special.execute(cur, sql):\n                  ^^^^^^^^^^^^^^^^^^^^^^^^^\n  File "/opt/homebrew/Cellar/litecli/1.11.0/libexec/lib/python3.12/site-packages/litecli/packages/special/main.py", line 109, in execute\n    raise CommandNotFound\nlitecli.packages.special.main.CommandNotFound\n\nDuring handling of the above exception, another exception occurred:\n\nTraceback (most recent call last):\n  File "/opt/homebrew/Cellar/litecli/1.11.0/libexec/lib/python3.12/site-packages/litecli/main.py", line 453, in one_iteration\n    for title, cur, headers, status in res:\n  File "/opt/homebrew/Cellar/litecli/1.11.0/libexec/lib/python3.12/site-packages/litecli/sqlexecute.py", line 132, in run\n    cur.execute(sql)\nsqlite3.OperationalError: near ",": syntax error\n'
2024-05-11 13:38:49,965 (74828/MainThread) litecli.main ERROR - sql: 'y', error: OperationalError('near "y": syntax error')
2024-05-11 13:38:49,965 (74828/MainThread) litecli.main ERROR - traceback: 'Traceback (most recent call last):\n  File "/opt/homebrew/Cellar/litecli/1.11.0/libexec/lib/python3.12/site-packages/litecli/sqlexecute.py", line 125, in run\n    for result in special.execute(cur, sql):\n                  ^^^^^^^^^^^^^^^^^^^^^^^^^\n  File "/opt/homebrew/Cellar/litecli/1.11.0/libexec/lib/python3.12/site-packages/litecli/packages/special/main.py", line 109, in execute\n    raise CommandNotFound\nlitecli.packages.special.main.CommandNotFound\n\nDuring handling of the above exception, another exception occurred:\n\nTraceback (most recent call last):\n  File "/opt/homebrew/Cellar/litecli/1.11.0/libexec/lib/python3.12/site-packages/litecli/main.py", line 453, in one_iteration\n    for title, cur, headers, status in res:\n  File "/opt/homebrew/Cellar/litecli/1.11.0/libexec/lib/python3.12/site-packages/litecli/sqlexecute.py", line 132, in run\n    cur.execute(sql)\nsqlite3.OperationalError: near "y": syntax error\n'
2024-05-11 13:38:54,488 (74828/MainThread) litecli.main ERROR - sql: 'ALTER TABLE employees RENAME COLUMN EmployeeId, Title TO employeeid, title;', error: OperationalError('near ",": syntax error')
2024-05-11 13:38:54,489 (74828/MainThread) litecli.main ERROR - traceback: 'Traceback (most recent call last):\n  File "/opt/homebrew/Cellar/litecli/1.11.0/libexec/lib/python3.12/site-packages/litecli/sqlexecute.py", line 125, in run\n    for result in special.execute(cur, sql):\n                  ^^^^^^^^^^^^^^^^^^^^^^^^^\n  File "/opt/homebrew/Cellar/litecli/1.11.0/libexec/lib/python3.12/site-packages/litecli/packages/special/main.py", line 109, in execute\n    raise CommandNotFound\nlitecli.packages.special.main.CommandNotFound\n\nDuring handling of the above exception, another exception occurred:\n\nTraceback (most recent call last):\n  File "/opt/homebrew/Cellar/litecli/1.11.0/libexec/lib/python3.12/site-packages/litecli/main.py", line 453, in one_iteration\n    for title, cur, headers, status in res:\n  File "/opt/homebrew/Cellar/litecli/1.11.0/libexec/lib/python3.12/site-packages/litecli/sqlexecute.py", line 132, in run\n    cur.execute(sql)\nsqlite3.OperationalError: near ",": syntax error\n'
2024-05-11 13:39:07,967 (74828/MainThread) litecli.main ERROR - sql: 'c', error: OperationalError('near "c": syntax error')
2024-05-11 13:39:07,967 (74828/MainThread) litecli.main ERROR - traceback: 'Traceback (most recent call last):\n  File "/opt/homebrew/Cellar/litecli/1.11.0/libexec/lib/python3.12/site-packages/litecli/sqlexecute.py", line 125, in run\n    for result in special.execute(cur, sql):\n                  ^^^^^^^^^^^^^^^^^^^^^^^^^\n  File "/opt/homebrew/Cellar/litecli/1.11.0/libexec/lib/python3.12/site-packages/litecli/packages/special/main.py", line 109, in execute\n    raise CommandNotFound\nlitecli.packages.special.main.CommandNotFound\n\nDuring handling of the above exception, another exception occurred:\n\nTraceback (most recent call last):\n  File "/opt/homebrew/Cellar/litecli/1.11.0/libexec/lib/python3.12/site-packages/litecli/main.py", line 453, in one_iteration\n    for title, cur, headers, status in res:\n  File "/opt/homebrew/Cellar/litecli/1.11.0/libexec/lib/python3.12/site-packages/litecli/sqlexecute.py", line 132, in run\n    cur.execute(sql)\nsqlite3.OperationalError: near "c": syntax error\n'
2024-05-11 13:41:57,877 (74828/MainThread) litecli.main ERROR - sql: 'select * movies;', error: OperationalError('near "movies": syntax error')
2024-05-11 13:41:57,878 (74828/MainThread) litecli.main ERROR - traceback: 'Traceback (most recent call last):\n  File "/opt/homebrew/Cellar/litecli/1.11.0/libexec/lib/python3.12/site-packages/litecli/sqlexecute.py", line 125, in run\n    for result in special.execute(cur, sql):\n                  ^^^^^^^^^^^^^^^^^^^^^^^^^\n  File "/opt/homebrew/Cellar/litecli/1.11.0/libexec/lib/python3.12/site-packages/litecli/packages/special/main.py", line 109, in execute\n    raise CommandNotFound\nlitecli.packages.special.main.CommandNotFound\n\nDuring handling of the above exception, another exception occurred:\n\nTraceback (most recent call last):\n  File "/opt/homebrew/Cellar/litecli/1.11.0/libexec/lib/python3.12/site-packages/litecli/main.py", line 453, in one_iteration\n    for title, cur, headers, status in res:\n  File "/opt/homebrew/Cellar/litecli/1.11.0/libexec/lib/python3.12/site-packages/litecli/sqlexecute.py", line 132, in run\n    cur.execute(sql)\nsqlite3.OperationalError: near "movies": syntax error\n'
2024-05-11 13:45:39,562 (74828/MainThread) litecli.main ERROR - sql: 'drop table movies, movie_directors;', error: OperationalError('near ",": syntax error')
2024-05-11 13:45:39,565 (74828/MainThread) litecli.main ERROR - traceback: 'Traceback (most recent call last):\n  File "/opt/homebrew/Cellar/litecli/1.11.0/libexec/lib/python3.12/site-packages/litecli/sqlexecute.py", line 125, in run\n    for result in special.execute(cur, sql):\n                  ^^^^^^^^^^^^^^^^^^^^^^^^^\n  File "/opt/homebrew/Cellar/litecli/1.11.0/libexec/lib/python3.12/site-packages/litecli/packages/special/main.py", line 109, in execute\n    raise CommandNotFound\nlitecli.packages.special.main.CommandNotFound\n\nDuring handling of the above exception, another exception occurred:\n\nTraceback (most recent call last):\n  File "/opt/homebrew/Cellar/litecli/1.11.0/libexec/lib/python3.12/site-packages/litecli/main.py", line 453, in one_iteration\n    for title, cur, headers, status in res:\n  File "/opt/homebrew/Cellar/litecli/1.11.0/libexec/lib/python3.12/site-packages/litecli/sqlexecute.py", line 132, in run\n    cur.execute(sql)\nsqlite3.OperationalError: near ",": syntax error\n'
2024-05-11 13:45:50,418 (74828/MainThread) litecli.main ERROR - sql: 'c', error: OperationalError('near "c": syntax error')
2024-05-11 13:45:50,419 (74828/MainThread) litecli.main ERROR - traceback: 'Traceback (most recent call last):\n  File "/opt/homebrew/Cellar/litecli/1.11.0/libexec/lib/python3.12/site-packages/litecli/sqlexecute.py", line 125, in run\n    for result in special.execute(cur, sql):\n                  ^^^^^^^^^^^^^^^^^^^^^^^^^\n  File "/opt/homebrew/Cellar/litecli/1.11.0/libexec/lib/python3.12/site-packages/litecli/packages/special/main.py", line 109, in execute\n    raise CommandNotFound\nlitecli.packages.special.main.CommandNotFound\n\nDuring handling of the above exception, another exception occurred:\n\nTraceback (most recent call last):\n  File "/opt/homebrew/Cellar/litecli/1.11.0/libexec/lib/python3.12/site-packages/litecli/main.py", line 453, in one_iteration\n    for title, cur, headers, status in res:\n  File "/opt/homebrew/Cellar/litecli/1.11.0/libexec/lib/python3.12/site-packages/litecli/sqlexecute.py", line 132, in run\n    cur.execute(sql)\nsqlite3.OperationalError: near "c": syntax error\n'
2024-05-11 13:55:16,572 (74828/MainThread) litecli.main ERROR - sql: '-- Step 1: Add a new column named "age" to the "employees" table\nALTER TABLE employees ADD COLUMN age INTEGER;\n\n-- Step 2: Update the "age" column with the calculated age values\nUPDATE employees\nSET age = (strftime(\'%Y\', \'now\') - strftime(\'%Y\', birthdate)) - (strftime(\'%m-%d\', \'now\') < strftime(\'%m-%d\', birthdate));\n', error: OperationalError('no such column: birthdate')
2024-05-11 13:55:16,573 (74828/MainThread) litecli.main ERROR - traceback: 'Traceback (most recent call last):\n  File "/opt/homebrew/Cellar/litecli/1.11.0/libexec/lib/python3.12/site-packages/litecli/sqlexecute.py", line 125, in run\n    for result in special.execute(cur, sql):\n                  ^^^^^^^^^^^^^^^^^^^^^^^^^\n  File "/opt/homebrew/Cellar/litecli/1.11.0/libexec/lib/python3.12/site-packages/litecli/packages/special/main.py", line 109, in execute\n    raise CommandNotFound\nlitecli.packages.special.main.CommandNotFound\n\nDuring handling of the above exception, another exception occurred:\n\nTraceback (most recent call last):\n  File "/opt/homebrew/Cellar/litecli/1.11.0/libexec/lib/python3.12/site-packages/litecli/main.py", line 453, in one_iteration\n    for title, cur, headers, status in res:\n  File "/opt/homebrew/Cellar/litecli/1.11.0/libexec/lib/python3.12/site-packages/litecli/sqlexecute.py", line 132, in run\n    cur.execute(sql)\nsqlite3.OperationalError: no such column: birthdate\n'
2024-05-11 13:56:03,735 (74828/MainThread) litecli.main ERROR - sql: "ALTER TABLE employees ADD COLUMN age INTEGER;\n\nUPDATE employees\nSET age = (strftime('%Y', 'now') - strftime('%Y', birth_date)) - (strftime('%m-%d', 'now') < strftime('%m-%d', birth_date));", error: OperationalError('duplicate column name: age')
2024-05-11 13:56:03,737 (74828/MainThread) litecli.main ERROR - traceback: 'Traceback (most recent call last):\n  File "/opt/homebrew/Cellar/litecli/1.11.0/libexec/lib/python3.12/site-packages/litecli/sqlexecute.py", line 125, in run\n    for result in special.execute(cur, sql):\n                  ^^^^^^^^^^^^^^^^^^^^^^^^^\n  File "/opt/homebrew/Cellar/litecli/1.11.0/libexec/lib/python3.12/site-packages/litecli/packages/special/main.py", line 109, in execute\n    raise CommandNotFound\nlitecli.packages.special.main.CommandNotFound\n\nDuring handling of the above exception, another exception occurred:\n\nTraceback (most recent call last):\n  File "/opt/homebrew/Cellar/litecli/1.11.0/libexec/lib/python3.12/site-packages/litecli/main.py", line 453, in one_iteration\n    for title, cur, headers, status in res:\n  File "/opt/homebrew/Cellar/litecli/1.11.0/libexec/lib/python3.12/site-packages/litecli/sqlexecute.py", line 132, in run\n    cur.execute(sql)\nsqlite3.OperationalError: duplicate column name: age\n'
2024-05-11 14:12:10,798 (78641/MainThread) litecli.main ERROR - sql: 'INSERT INTO employees name, surname, employee_id VALUES "Loi", "Tran", 1', error: OperationalError('near "name": syntax error')
2024-05-11 14:12:10,802 (78641/MainThread) litecli.main ERROR - traceback: 'Traceback (most recent call last):\n  File "/opt/homebrew/Cellar/litecli/1.11.0/libexec/lib/python3.12/site-packages/litecli/sqlexecute.py", line 125, in run\n    for result in special.execute(cur, sql):\n                  ^^^^^^^^^^^^^^^^^^^^^^^^^\n  File "/opt/homebrew/Cellar/litecli/1.11.0/libexec/lib/python3.12/site-packages/litecli/packages/special/main.py", line 109, in execute\n    raise CommandNotFound\nlitecli.packages.special.main.CommandNotFound\n\nDuring handling of the above exception, another exception occurred:\n\nTraceback (most recent call last):\n  File "/opt/homebrew/Cellar/litecli/1.11.0/libexec/lib/python3.12/site-packages/litecli/main.py", line 453, in one_iteration\n    for title, cur, headers, status in res:\n  File "/opt/homebrew/Cellar/litecli/1.11.0/libexec/lib/python3.12/site-packages/litecli/sqlexecute.py", line 132, in run\n    cur.execute(sql)\nsqlite3.OperationalError: near "name": syntax error\n'
2024-05-11 14:12:31,199 (78641/MainThread) litecli.main ERROR - sql: 'INSERT INTO employees (name, surname, employee_id) VALUES ("Loi", "Tran", 1)', error: IntegrityError('UNIQUE constraint failed: employees.employee_id')
2024-05-11 14:12:31,199 (78641/MainThread) litecli.main ERROR - traceback: 'Traceback (most recent call last):\n  File "/opt/homebrew/Cellar/litecli/1.11.0/libexec/lib/python3.12/site-packages/litecli/sqlexecute.py", line 125, in run\n    for result in special.execute(cur, sql):\n                  ^^^^^^^^^^^^^^^^^^^^^^^^^\n  File "/opt/homebrew/Cellar/litecli/1.11.0/libexec/lib/python3.12/site-packages/litecli/packages/special/main.py", line 109, in execute\n    raise CommandNotFound\nlitecli.packages.special.main.CommandNotFound\n\nDuring handling of the above exception, another exception occurred:\n\nTraceback (most recent call last):\n  File "/opt/homebrew/Cellar/litecli/1.11.0/libexec/lib/python3.12/site-packages/litecli/main.py", line 453, in one_iteration\n    for title, cur, headers, status in res:\n  File "/opt/homebrew/Cellar/litecli/1.11.0/libexec/lib/python3.12/site-packages/litecli/sqlexecute.py", line 132, in run\n    cur.execute(sql)\nsqlite3.IntegrityError: UNIQUE constraint failed: employees.employee_id\n'
2024-05-11 14:16:44,229 (78641/MainThread) litecli.main ERROR - sql: 'UPDATE employees\nSET\ntitle = "CEO",\nbirth_date = DATE(\'now\', \'-21 years\')\nhire_date = DATE(\'now\', \'-21 days\')\ncity = "San Francisco"\nstate = "Florida"\ncountry = "USA"\npostal = 94016\nemail = "loi@seepdeep.com"\nWHERE employee_id = 1;', error: OperationalError('near "hire_date": syntax error')
2024-05-11 14:16:44,230 (78641/MainThread) litecli.main ERROR - traceback: 'Traceback (most recent call last):\n  File "/opt/homebrew/Cellar/litecli/1.11.0/libexec/lib/python3.12/site-packages/litecli/sqlexecute.py", line 125, in run\n    for result in special.execute(cur, sql):\n                  ^^^^^^^^^^^^^^^^^^^^^^^^^\n  File "/opt/homebrew/Cellar/litecli/1.11.0/libexec/lib/python3.12/site-packages/litecli/packages/special/main.py", line 109, in execute\n    raise CommandNotFound\nlitecli.packages.special.main.CommandNotFound\n\nDuring handling of the above exception, another exception occurred:\n\nTraceback (most recent call last):\n  File "/opt/homebrew/Cellar/litecli/1.11.0/libexec/lib/python3.12/site-packages/litecli/main.py", line 453, in one_iteration\n    for title, cur, headers, status in res:\n  File "/opt/homebrew/Cellar/litecli/1.11.0/libexec/lib/python3.12/site-packages/litecli/sqlexecute.py", line 132, in run\n    cur.execute(sql)\nsqlite3.OperationalError: near "hire_date": syntax error\n'
2024-05-11 14:17:07,585 (78641/MainThread) litecli.main ERROR - sql: 'UPDATE employees\nSET\ntitle = "CEO",\nbirth_date = DATE(\'now\', \'-21 years\'),\nhire_date = DATE(\'now\', \'-21 days\'),\ncity = "San Francisco",\nstate = "Florida",\ncountry = "USA",\npostal = 94016,\nemail = "loi@seepdeep.com",\nWHERE employee_id = 1;', error: OperationalError('near "WHERE": syntax error')
2024-05-11 14:17:07,585 (78641/MainThread) litecli.main ERROR - traceback: 'Traceback (most recent call last):\n  File "/opt/homebrew/Cellar/litecli/1.11.0/libexec/lib/python3.12/site-packages/litecli/sqlexecute.py", line 125, in run\n    for result in special.execute(cur, sql):\n                  ^^^^^^^^^^^^^^^^^^^^^^^^^\n  File "/opt/homebrew/Cellar/litecli/1.11.0/libexec/lib/python3.12/site-packages/litecli/packages/special/main.py", line 109, in execute\n    raise CommandNotFound\nlitecli.packages.special.main.CommandNotFound\n\nDuring handling of the above exception, another exception occurred:\n\nTraceback (most recent call last):\n  File "/opt/homebrew/Cellar/litecli/1.11.0/libexec/lib/python3.12/site-packages/litecli/main.py", line 453, in one_iteration\n    for title, cur, headers, status in res:\n  File "/opt/homebrew/Cellar/litecli/1.11.0/libexec/lib/python3.12/site-packages/litecli/sqlexecute.py", line 132, in run\n    cur.execute(sql)\nsqlite3.OperationalError: near "WHERE": syntax error\n'
2024-05-11 14:17:14,394 (78641/MainThread) litecli.main ERROR - sql: 'UPDATE employees\nSET\ntitle = "CEO",\nbirth_date = DATE(\'now\', \'-21 years\'),\nhire_date = DATE(\'now\', \'-21 days\'),\ncity = "San Francisco",\nstate = "Florida",\ncountry = "USA",\npostal = 94016,\nemail = "loi@seepdeep.com"\nWHERE employee_id = 1;', error: OperationalError('no such column: postal')
2024-05-11 14:17:14,394 (78641/MainThread) litecli.main ERROR - traceback: 'Traceback (most recent call last):\n  File "/opt/homebrew/Cellar/litecli/1.11.0/libexec/lib/python3.12/site-packages/litecli/sqlexecute.py", line 125, in run\n    for result in special.execute(cur, sql):\n                  ^^^^^^^^^^^^^^^^^^^^^^^^^\n  File "/opt/homebrew/Cellar/litecli/1.11.0/libexec/lib/python3.12/site-packages/litecli/packages/special/main.py", line 109, in execute\n    raise CommandNotFound\nlitecli.packages.special.main.CommandNotFound\n\nDuring handling of the above exception, another exception occurred:\n\nTraceback (most recent call last):\n  File "/opt/homebrew/Cellar/litecli/1.11.0/libexec/lib/python3.12/site-packages/litecli/main.py", line 453, in one_iteration\n    for title, cur, headers, status in res:\n  File "/opt/homebrew/Cellar/litecli/1.11.0/libexec/lib/python3.12/site-packages/litecli/sqlexecute.py", line 132, in run\n    cur.execute(sql)\nsqlite3.OperationalError: no such column: postal\n'
2024-05-11 14:22:35,654 (78641/MainThread) litecli.main ERROR - sql: 'INSERT INTO employees (name, surname, hire_date)\nVALUES\n    (\'Charles\', \'Lee\', DATE(\'now\'), "charles@seepdeep.com"),\n    (\'Michael\', \'Do\', DATE(\'now\'), "michael@seepdeep.com"),\n    (\'Ben\', \'Dao\', DATE(\'now\'), "ben@seepdeep.com"),\n    (\'Peter\', \'Nguyen\', DATE(\'now\'), "peter@seepdeep.com"),\n    (\'Thuy\', \'Dao\', DATE(\'now\'), "thuy@seepdeep.com"),\n    (\'Uyen\', \'Nguyen\', DATE(\'now\'), "uyen@seepdeep.com"),\n    (\'Thanh\', \'Luu\', DATE(\'now\'), "thanh@seepdeep.com"),\n    (\'Thuy\', \'Linh\', DATE(\'now\'), "thanh@seepdeep.com"),\n    (\'Sang\', \'Nguyen\', DATE(\'now\'), "sang@seepdeep.com");', error: OperationalError('4 values for 3 columns')
2024-05-11 14:22:35,654 (78641/MainThread) litecli.main ERROR - traceback: 'Traceback (most recent call last):\n  File "/opt/homebrew/Cellar/litecli/1.11.0/libexec/lib/python3.12/site-packages/litecli/sqlexecute.py", line 125, in run\n    for result in special.execute(cur, sql):\n                  ^^^^^^^^^^^^^^^^^^^^^^^^^\n  File "/opt/homebrew/Cellar/litecli/1.11.0/libexec/lib/python3.12/site-packages/litecli/packages/special/main.py", line 109, in execute\n    raise CommandNotFound\nlitecli.packages.special.main.CommandNotFound\n\nDuring handling of the above exception, another exception occurred:\n\nTraceback (most recent call last):\n  File "/opt/homebrew/Cellar/litecli/1.11.0/libexec/lib/python3.12/site-packages/litecli/main.py", line 453, in one_iteration\n    for title, cur, headers, status in res:\n  File "/opt/homebrew/Cellar/litecli/1.11.0/libexec/lib/python3.12/site-packages/litecli/sqlexecute.py", line 132, in run\n    cur.execute(sql)\nsqlite3.OperationalError: 4 values for 3 columns\n'
2024-05-11 14:24:58,623 (78641/MainThread) litecli.main ERROR - sql: "UPDATE employees\nSET age = (strftime('%Y', 'now') - strftime('%Y', birth_date)) - (strftime('%m-%d', 'now') < strftime('%m-%d', birthdate));", error: OperationalError('no such column: birthdate')
2024-05-11 14:24:58,624 (78641/MainThread) litecli.main ERROR - traceback: 'Traceback (most recent call last):\n  File "/opt/homebrew/Cellar/litecli/1.11.0/libexec/lib/python3.12/site-packages/litecli/sqlexecute.py", line 125, in run\n    for result in special.execute(cur, sql):\n                  ^^^^^^^^^^^^^^^^^^^^^^^^^\n  File "/opt/homebrew/Cellar/litecli/1.11.0/libexec/lib/python3.12/site-packages/litecli/packages/special/main.py", line 109, in execute\n    raise CommandNotFound\nlitecli.packages.special.main.CommandNotFound\n\nDuring handling of the above exception, another exception occurred:\n\nTraceback (most recent call last):\n  File "/opt/homebrew/Cellar/litecli/1.11.0/libexec/lib/python3.12/site-packages/litecli/main.py", line 453, in one_iteration\n    for title, cur, headers, status in res:\n  File "/opt/homebrew/Cellar/litecli/1.11.0/libexec/lib/python3.12/site-packages/litecli/sqlexecute.py", line 132, in run\n    cur.execute(sql)\nsqlite3.OperationalError: no such column: birthdate\n'
2024-05-11 14:26:51,312 (78641/MainThread) litecli.main ERROR - sql: "UPDATE employees\nSET age = (strftime('%Y', 'now') - strftime('%Y', birth_date)) - (strftime('%m-%d', 'now') < strftime('%m-%d', birthdate));", error: OperationalError('no such column: birthdate')
2024-05-11 14:26:51,313 (78641/MainThread) litecli.main ERROR - traceback: 'Traceback (most recent call last):\n  File "/opt/homebrew/Cellar/litecli/1.11.0/libexec/lib/python3.12/site-packages/litecli/sqlexecute.py", line 125, in run\n    for result in special.execute(cur, sql):\n                  ^^^^^^^^^^^^^^^^^^^^^^^^^\n  File "/opt/homebrew/Cellar/litecli/1.11.0/libexec/lib/python3.12/site-packages/litecli/packages/special/main.py", line 109, in execute\n    raise CommandNotFound\nlitecli.packages.special.main.CommandNotFound\n\nDuring handling of the above exception, another exception occurred:\n\nTraceback (most recent call last):\n  File "/opt/homebrew/Cellar/litecli/1.11.0/libexec/lib/python3.12/site-packages/litecli/main.py", line 453, in one_iteration\n    for title, cur, headers, status in res:\n  File "/opt/homebrew/Cellar/litecli/1.11.0/libexec/lib/python3.12/site-packages/litecli/sqlexecute.py", line 132, in run\n    cur.execute(sql)\nsqlite3.OperationalError: no such column: birthdate\n'
2024-05-11 14:51:37,972 (82637/MainThread) litecli.main ERROR - sql: 'ALTER TABLE employees\nMODIFY COLUMN postal_code TEXT;', error: OperationalError('near "MODIFY": syntax error')
2024-05-11 14:51:37,976 (82637/MainThread) litecli.main ERROR - traceback: 'Traceback (most recent call last):\n  File "/opt/homebrew/Cellar/litecli/1.11.0/libexec/lib/python3.12/site-packages/litecli/sqlexecute.py", line 125, in run\n    for result in special.execute(cur, sql):\n                  ^^^^^^^^^^^^^^^^^^^^^^^^^\n  File "/opt/homebrew/Cellar/litecli/1.11.0/libexec/lib/python3.12/site-packages/litecli/packages/special/main.py", line 109, in execute\n    raise CommandNotFound\nlitecli.packages.special.main.CommandNotFound\n\nDuring handling of the above exception, another exception occurred:\n\nTraceback (most recent call last):\n  File "/opt/homebrew/Cellar/litecli/1.11.0/libexec/lib/python3.12/site-packages/litecli/main.py", line 453, in one_iteration\n    for title, cur, headers, status in res:\n  File "/opt/homebrew/Cellar/litecli/1.11.0/libexec/lib/python3.12/site-packages/litecli/sqlexecute.py", line 132, in run\n    cur.execute(sql)\nsqlite3.OperationalError: near "MODIFY": syntax error\n'
2024-05-11 15:09:30,988 (82637/MainThread) litecli.main ERROR - sql: 'alter table employees remove fax;', error: OperationalError('near "remove": syntax error')
2024-05-11 15:09:30,990 (82637/MainThread) litecli.main ERROR - traceback: 'Traceback (most recent call last):\n  File "/opt/homebrew/Cellar/litecli/1.11.0/libexec/lib/python3.12/site-packages/litecli/sqlexecute.py", line 125, in run\n    for result in special.execute(cur, sql):\n                  ^^^^^^^^^^^^^^^^^^^^^^^^^\n  File "/opt/homebrew/Cellar/litecli/1.11.0/libexec/lib/python3.12/site-packages/litecli/packages/special/main.py", line 109, in execute\n    raise CommandNotFound\nlitecli.packages.special.main.CommandNotFound\n\nDuring handling of the above exception, another exception occurred:\n\nTraceback (most recent call last):\n  File "/opt/homebrew/Cellar/litecli/1.11.0/libexec/lib/python3.12/site-packages/litecli/main.py", line 453, in one_iteration\n    for title, cur, headers, status in res:\n  File "/opt/homebrew/Cellar/litecli/1.11.0/libexec/lib/python3.12/site-packages/litecli/sqlexecute.py", line 132, in run\n    cur.execute(sql)\nsqlite3.OperationalError: near "remove": syntax error\n'
2024-05-11 16:02:10,222 (87749/MainThread) litecli.main ERROR - sql: 'SELECT name, \n       DATEDIFF(CURRENT_DATE(), hire_date) AS years_at_company \nFROM employees \nORDER BY years_at_company;', error: OperationalError('near "(": syntax error')
2024-05-11 16:02:10,227 (87749/MainThread) litecli.main ERROR - traceback: 'Traceback (most recent call last):\n  File "/opt/homebrew/Cellar/litecli/1.11.0/libexec/lib/python3.12/site-packages/litecli/sqlexecute.py", line 125, in run\n    for result in special.execute(cur, sql):\n                  ^^^^^^^^^^^^^^^^^^^^^^^^^\n  File "/opt/homebrew/Cellar/litecli/1.11.0/libexec/lib/python3.12/site-packages/litecli/packages/special/main.py", line 109, in execute\n    raise CommandNotFound\nlitecli.packages.special.main.CommandNotFound\n\nDuring handling of the above exception, another exception occurred:\n\nTraceback (most recent call last):\n  File "/opt/homebrew/Cellar/litecli/1.11.0/libexec/lib/python3.12/site-packages/litecli/main.py", line 453, in one_iteration\n    for title, cur, headers, status in res:\n  File "/opt/homebrew/Cellar/litecli/1.11.0/libexec/lib/python3.12/site-packages/litecli/sqlexecute.py", line 132, in run\n    cur.execute(sql)\nsqlite3.OperationalError: near "(": syntax error\n'
2024-05-11 16:02:23,464 (87749/MainThread) litecli.main ERROR - sql: 'SELECT \n    name, \n    TIMESTAMPDIFF(YEAR, hire_date, CURRENT_DATE()) AS years_at_company \nFROM \n    employees \nORDER BY \n    years_at_company;\n', error: OperationalError('near "(": syntax error')
2024-05-11 16:02:23,465 (87749/MainThread) litecli.main ERROR - traceback: 'Traceback (most recent call last):\n  File "/opt/homebrew/Cellar/litecli/1.11.0/libexec/lib/python3.12/site-packages/litecli/sqlexecute.py", line 125, in run\n    for result in special.execute(cur, sql):\n                  ^^^^^^^^^^^^^^^^^^^^^^^^^\n  File "/opt/homebrew/Cellar/litecli/1.11.0/libexec/lib/python3.12/site-packages/litecli/packages/special/main.py", line 109, in execute\n    raise CommandNotFound\nlitecli.packages.special.main.CommandNotFound\n\nDuring handling of the above exception, another exception occurred:\n\nTraceback (most recent call last):\n  File "/opt/homebrew/Cellar/litecli/1.11.0/libexec/lib/python3.12/site-packages/litecli/main.py", line 453, in one_iteration\n    for title, cur, headers, status in res:\n  File "/opt/homebrew/Cellar/litecli/1.11.0/libexec/lib/python3.12/site-packages/litecli/sqlexecute.py", line 132, in run\n    cur.execute(sql)\nsqlite3.OperationalError: near "(": syntax error\n'
2024-05-11 16:12:01,277 (87749/MainThread) litecli.main ERROR - sql: 'select * from depa;', error: OperationalError('no such table: depa')
2024-05-11 16:12:01,278 (87749/MainThread) litecli.main ERROR - traceback: 'Traceback (most recent call last):\n  File "/opt/homebrew/Cellar/litecli/1.11.0/libexec/lib/python3.12/site-packages/litecli/sqlexecute.py", line 125, in run\n    for result in special.execute(cur, sql):\n                  ^^^^^^^^^^^^^^^^^^^^^^^^^\n  File "/opt/homebrew/Cellar/litecli/1.11.0/libexec/lib/python3.12/site-packages/litecli/packages/special/main.py", line 109, in execute\n    raise CommandNotFound\nlitecli.packages.special.main.CommandNotFound\n\nDuring handling of the above exception, another exception occurred:\n\nTraceback (most recent call last):\n  File "/opt/homebrew/Cellar/litecli/1.11.0/libexec/lib/python3.12/site-packages/litecli/main.py", line 453, in one_iteration\n    for title, cur, headers, status in res:\n  File "/opt/homebrew/Cellar/litecli/1.11.0/libexec/lib/python3.12/site-packages/litecli/sqlexecute.py", line 132, in run\n    cur.execute(sql)\nsqlite3.OperationalError: no such table: depa\n'
2024-05-11 16:12:04,227 (87749/MainThread) litecli.main ERROR - sql: "select * from departments';", error: OperationalError('unrecognized token: "\'"')
2024-05-11 16:12:04,228 (87749/MainThread) litecli.main ERROR - traceback: 'Traceback (most recent call last):\n  File "/opt/homebrew/Cellar/litecli/1.11.0/libexec/lib/python3.12/site-packages/litecli/sqlexecute.py", line 125, in run\n    for result in special.execute(cur, sql):\n                  ^^^^^^^^^^^^^^^^^^^^^^^^^\n  File "/opt/homebrew/Cellar/litecli/1.11.0/libexec/lib/python3.12/site-packages/litecli/packages/special/main.py", line 109, in execute\n    raise CommandNotFound\nlitecli.packages.special.main.CommandNotFound\n\nDuring handling of the above exception, another exception occurred:\n\nTraceback (most recent call last):\n  File "/opt/homebrew/Cellar/litecli/1.11.0/libexec/lib/python3.12/site-packages/litecli/main.py", line 453, in one_iteration\n    for title, cur, headers, status in res:\n  File "/opt/homebrew/Cellar/litecli/1.11.0/libexec/lib/python3.12/site-packages/litecli/sqlexecute.py", line 132, in run\n    cur.execute(sql)\nsqlite3.OperationalError: unrecognized token: "\'"\n'
2024-05-11 16:35:28,057 (87749/MainThread) litecli.main ERROR - sql: 'ALTER TABLE employees\nADD COLUMN department_id INTEGER,\nADD FOREIGN KEY (department_id) REFERENCES departments(id);\n', error: OperationalError('near ",": syntax error')
2024-05-11 16:35:28,059 (87749/MainThread) litecli.main ERROR - traceback: 'Traceback (most recent call last):\n  File "/opt/homebrew/Cellar/litecli/1.11.0/libexec/lib/python3.12/site-packages/litecli/sqlexecute.py", line 125, in run\n    for result in special.execute(cur, sql):\n                  ^^^^^^^^^^^^^^^^^^^^^^^^^\n  File "/opt/homebrew/Cellar/litecli/1.11.0/libexec/lib/python3.12/site-packages/litecli/packages/special/main.py", line 109, in execute\n    raise CommandNotFound\nlitecli.packages.special.main.CommandNotFound\n\nDuring handling of the above exception, another exception occurred:\n\nTraceback (most recent call last):\n  File "/opt/homebrew/Cellar/litecli/1.11.0/libexec/lib/python3.12/site-packages/litecli/main.py", line 453, in one_iteration\n    for title, cur, headers, status in res:\n  File "/opt/homebrew/Cellar/litecli/1.11.0/libexec/lib/python3.12/site-packages/litecli/sqlexecute.py", line 132, in run\n    cur.execute(sql)\nsqlite3.OperationalError: near ",": syntax error\n'
2024-05-11 16:35:39,925 (87749/MainThread) litecli.main ERROR - sql: "-- Add the 'salary' column to the 'employees' table\nALTER TABLE employees\nADD COLUMN salary INTEGER;\n\n-- Add a foreign key constraint on the 'department_id' column in the 'employees' table\nALTER TABLE employees\nADD COLUMN department_id INTEGER,\nADD FOREIGN KEY (department_id) REFERENCES departments(id);\n", error: OperationalError('duplicate column name: salary')
2024-05-11 16:35:39,925 (87749/MainThread) litecli.main ERROR - traceback: 'Traceback (most recent call last):\n  File "/opt/homebrew/Cellar/litecli/1.11.0/libexec/lib/python3.12/site-packages/litecli/sqlexecute.py", line 125, in run\n    for result in special.execute(cur, sql):\n                  ^^^^^^^^^^^^^^^^^^^^^^^^^\n  File "/opt/homebrew/Cellar/litecli/1.11.0/libexec/lib/python3.12/site-packages/litecli/packages/special/main.py", line 109, in execute\n    raise CommandNotFound\nlitecli.packages.special.main.CommandNotFound\n\nDuring handling of the above exception, another exception occurred:\n\nTraceback (most recent call last):\n  File "/opt/homebrew/Cellar/litecli/1.11.0/libexec/lib/python3.12/site-packages/litecli/main.py", line 453, in one_iteration\n    for title, cur, headers, status in res:\n  File "/opt/homebrew/Cellar/litecli/1.11.0/libexec/lib/python3.12/site-packages/litecli/sqlexecute.py", line 132, in run\n    cur.execute(sql)\nsqlite3.OperationalError: duplicate column name: salary\n'
2024-05-11 16:35:52,038 (87749/MainThread) litecli.main ERROR - sql: 'ALTER TABLE employees\nADD COLUMN department_id INTEGER,\nADD FOREIGN KEY (department_id) REFERENCES departments(id);', error: OperationalError('near ",": syntax error')
2024-05-11 16:35:52,040 (87749/MainThread) litecli.main ERROR - traceback: 'Traceback (most recent call last):\n  File "/opt/homebrew/Cellar/litecli/1.11.0/libexec/lib/python3.12/site-packages/litecli/sqlexecute.py", line 125, in run\n    for result in special.execute(cur, sql):\n                  ^^^^^^^^^^^^^^^^^^^^^^^^^\n  File "/opt/homebrew/Cellar/litecli/1.11.0/libexec/lib/python3.12/site-packages/litecli/packages/special/main.py", line 109, in execute\n    raise CommandNotFound\nlitecli.packages.special.main.CommandNotFound\n\nDuring handling of the above exception, another exception occurred:\n\nTraceback (most recent call last):\n  File "/opt/homebrew/Cellar/litecli/1.11.0/libexec/lib/python3.12/site-packages/litecli/main.py", line 453, in one_iteration\n    for title, cur, headers, status in res:\n  File "/opt/homebrew/Cellar/litecli/1.11.0/libexec/lib/python3.12/site-packages/litecli/sqlexecute.py", line 132, in run\n    cur.execute(sql)\nsqlite3.OperationalError: near ",": syntax error\n'
2024-05-11 16:36:08,637 (87749/MainThread) litecli.main ERROR - sql: 'ALTER TABLE employees\nADD COLUMN department_id INTEGER\nADD FOREIGN KEY (department_id) REFERENCES departments(id);', error: OperationalError('near "ADD": syntax error')
2024-05-11 16:36:08,638 (87749/MainThread) litecli.main ERROR - traceback: 'Traceback (most recent call last):\n  File "/opt/homebrew/Cellar/litecli/1.11.0/libexec/lib/python3.12/site-packages/litecli/sqlexecute.py", line 125, in run\n    for result in special.execute(cur, sql):\n                  ^^^^^^^^^^^^^^^^^^^^^^^^^\n  File "/opt/homebrew/Cellar/litecli/1.11.0/libexec/lib/python3.12/site-packages/litecli/packages/special/main.py", line 109, in execute\n    raise CommandNotFound\nlitecli.packages.special.main.CommandNotFound\n\nDuring handling of the above exception, another exception occurred:\n\nTraceback (most recent call last):\n  File "/opt/homebrew/Cellar/litecli/1.11.0/libexec/lib/python3.12/site-packages/litecli/main.py", line 453, in one_iteration\n    for title, cur, headers, status in res:\n  File "/opt/homebrew/Cellar/litecli/1.11.0/libexec/lib/python3.12/site-packages/litecli/sqlexecute.py", line 132, in run\n    cur.execute(sql)\nsqlite3.OperationalError: near "ADD": syntax error\n'
2024-05-11 16:51:38,123 (87749/MainThread) litecli.main ERROR - sql: 'DELETE FROM employees\nWHERE id > 1;', error: OperationalError('no such column: id')
2024-05-11 16:51:38,125 (87749/MainThread) litecli.main ERROR - traceback: 'Traceback (most recent call last):\n  File "/opt/homebrew/Cellar/litecli/1.11.0/libexec/lib/python3.12/site-packages/litecli/sqlexecute.py", line 125, in run\n    for result in special.execute(cur, sql):\n                  ^^^^^^^^^^^^^^^^^^^^^^^^^\n  File "/opt/homebrew/Cellar/litecli/1.11.0/libexec/lib/python3.12/site-packages/litecli/packages/special/main.py", line 109, in execute\n    raise CommandNotFound\nlitecli.packages.special.main.CommandNotFound\n\nDuring handling of the above exception, another exception occurred:\n\nTraceback (most recent call last):\n  File "/opt/homebrew/Cellar/litecli/1.11.0/libexec/lib/python3.12/site-packages/litecli/main.py", line 453, in one_iteration\n    for title, cur, headers, status in res:\n  File "/opt/homebrew/Cellar/litecli/1.11.0/libexec/lib/python3.12/site-packages/litecli/sqlexecute.py", line 132, in run\n    cur.execute(sql)\nsqlite3.OperationalError: no such column: id\n'
2024-05-11 17:00:31,395 (87749/MainThread) litecli.main ERROR - sql: 'DELETE FROM employees\nWHERE id > 1;\n', error: OperationalError('no such column: id')
2024-05-11 17:00:31,397 (87749/MainThread) litecli.main ERROR - traceback: 'Traceback (most recent call last):\n  File "/opt/homebrew/Cellar/litecli/1.11.0/libexec/lib/python3.12/site-packages/litecli/sqlexecute.py", line 125, in run\n    for result in special.execute(cur, sql):\n                  ^^^^^^^^^^^^^^^^^^^^^^^^^\n  File "/opt/homebrew/Cellar/litecli/1.11.0/libexec/lib/python3.12/site-packages/litecli/packages/special/main.py", line 109, in execute\n    raise CommandNotFound\nlitecli.packages.special.main.CommandNotFound\n\nDuring handling of the above exception, another exception occurred:\n\nTraceback (most recent call last):\n  File "/opt/homebrew/Cellar/litecli/1.11.0/libexec/lib/python3.12/site-packages/litecli/main.py", line 453, in one_iteration\n    for title, cur, headers, status in res:\n  File "/opt/homebrew/Cellar/litecli/1.11.0/libexec/lib/python3.12/site-packages/litecli/sqlexecute.py", line 132, in run\n    cur.execute(sql)\nsqlite3.OperationalError: no such column: id\n'
2024-05-11 17:22:11,055 (87749/MainThread) litecli.main ERROR - sql: 'DELETE * from employees if employee_id > 1;', error: OperationalError('near "*": syntax error')
2024-05-11 17:22:11,056 (87749/MainThread) litecli.main ERROR - traceback: 'Traceback (most recent call last):\n  File "/opt/homebrew/Cellar/litecli/1.11.0/libexec/lib/python3.12/site-packages/litecli/sqlexecute.py", line 125, in run\n    for result in special.execute(cur, sql):\n                  ^^^^^^^^^^^^^^^^^^^^^^^^^\n  File "/opt/homebrew/Cellar/litecli/1.11.0/libexec/lib/python3.12/site-packages/litecli/packages/special/main.py", line 109, in execute\n    raise CommandNotFound\nlitecli.packages.special.main.CommandNotFound\n\nDuring handling of the above exception, another exception occurred:\n\nTraceback (most recent call last):\n  File "/opt/homebrew/Cellar/litecli/1.11.0/libexec/lib/python3.12/site-packages/litecli/main.py", line 453, in one_iteration\n    for title, cur, headers, status in res:\n  File "/opt/homebrew/Cellar/litecli/1.11.0/libexec/lib/python3.12/site-packages/litecli/sqlexecute.py", line 132, in run\n    cur.execute(sql)\nsqlite3.OperationalError: near "*": syntax error\n'
2024-05-11 17:22:15,724 (87749/MainThread) litecli.main ERROR - sql: 'DELETE from employees if employee_id > 1;', error: OperationalError('near "if": syntax error')
2024-05-11 17:22:15,724 (87749/MainThread) litecli.main ERROR - traceback: 'Traceback (most recent call last):\n  File "/opt/homebrew/Cellar/litecli/1.11.0/libexec/lib/python3.12/site-packages/litecli/sqlexecute.py", line 125, in run\n    for result in special.execute(cur, sql):\n                  ^^^^^^^^^^^^^^^^^^^^^^^^^\n  File "/opt/homebrew/Cellar/litecli/1.11.0/libexec/lib/python3.12/site-packages/litecli/packages/special/main.py", line 109, in execute\n    raise CommandNotFound\nlitecli.packages.special.main.CommandNotFound\n\nDuring handling of the above exception, another exception occurred:\n\nTraceback (most recent call last):\n  File "/opt/homebrew/Cellar/litecli/1.11.0/libexec/lib/python3.12/site-packages/litecli/main.py", line 453, in one_iteration\n    for title, cur, headers, status in res:\n  File "/opt/homebrew/Cellar/litecli/1.11.0/libexec/lib/python3.12/site-packages/litecli/sqlexecute.py", line 132, in run\n    cur.execute(sql)\nsqlite3.OperationalError: near "if": syntax error\n'
2024-05-11 17:27:32,594 (87749/MainThread) litecli.main ERROR - sql: ':q', error: OperationalError('near ":q": syntax error')
2024-05-11 17:27:32,595 (87749/MainThread) litecli.main ERROR - traceback: 'Traceback (most recent call last):\n  File "/opt/homebrew/Cellar/litecli/1.11.0/libexec/lib/python3.12/site-packages/litecli/sqlexecute.py", line 125, in run\n    for result in special.execute(cur, sql):\n                  ^^^^^^^^^^^^^^^^^^^^^^^^^\n  File "/opt/homebrew/Cellar/litecli/1.11.0/libexec/lib/python3.12/site-packages/litecli/packages/special/main.py", line 109, in execute\n    raise CommandNotFound\nlitecli.packages.special.main.CommandNotFound\n\nDuring handling of the above exception, another exception occurred:\n\nTraceback (most recent call last):\n  File "/opt/homebrew/Cellar/litecli/1.11.0/libexec/lib/python3.12/site-packages/litecli/main.py", line 453, in one_iteration\n    for title, cur, headers, status in res:\n  File "/opt/homebrew/Cellar/litecli/1.11.0/libexec/lib/python3.12/site-packages/litecli/sqlexecute.py", line 132, in run\n    cur.execute(sql)\nsqlite3.OperationalError: near ":q": syntax error\n'
2024-05-11 17:27:32,599 (87749/MainThread) litecli.main ERROR - sql: 'q', error: OperationalError('near "q": syntax error')
2024-05-11 17:27:32,600 (87749/MainThread) litecli.main ERROR - traceback: 'Traceback (most recent call last):\n  File "/opt/homebrew/Cellar/litecli/1.11.0/libexec/lib/python3.12/site-packages/litecli/sqlexecute.py", line 125, in run\n    for result in special.execute(cur, sql):\n                  ^^^^^^^^^^^^^^^^^^^^^^^^^\n  File "/opt/homebrew/Cellar/litecli/1.11.0/libexec/lib/python3.12/site-packages/litecli/packages/special/main.py", line 109, in execute\n    raise CommandNotFound\nlitecli.packages.special.main.CommandNotFound\n\nDuring handling of the above exception, another exception occurred:\n\nTraceback (most recent call last):\n  File "/opt/homebrew/Cellar/litecli/1.11.0/libexec/lib/python3.12/site-packages/litecli/main.py", line 453, in one_iteration\n    for title, cur, headers, status in res:\n  File "/opt/homebrew/Cellar/litecli/1.11.0/libexec/lib/python3.12/site-packages/litecli/sqlexecute.py", line 132, in run\n    cur.execute(sql)\nsqlite3.OperationalError: near "q": syntax error\n'
2024-05-11 17:38:15,766 (87749/MainThread) litecli.main ERROR - sql: 'qq', error: OperationalError('near "qq": syntax error')
2024-05-11 17:38:15,767 (87749/MainThread) litecli.main ERROR - traceback: 'Traceback (most recent call last):\n  File "/opt/homebrew/Cellar/litecli/1.11.0/libexec/lib/python3.12/site-packages/litecli/sqlexecute.py", line 125, in run\n    for result in special.execute(cur, sql):\n                  ^^^^^^^^^^^^^^^^^^^^^^^^^\n  File "/opt/homebrew/Cellar/litecli/1.11.0/libexec/lib/python3.12/site-packages/litecli/packages/special/main.py", line 109, in execute\n    raise CommandNotFound\nlitecli.packages.special.main.CommandNotFound\n\nDuring handling of the above exception, another exception occurred:\n\nTraceback (most recent call last):\n  File "/opt/homebrew/Cellar/litecli/1.11.0/libexec/lib/python3.12/site-packages/litecli/main.py", line 453, in one_iteration\n    for title, cur, headers, status in res:\n  File "/opt/homebrew/Cellar/litecli/1.11.0/libexec/lib/python3.12/site-packages/litecli/sqlexecute.py", line 132, in run\n    cur.execute(sql)\nsqlite3.OperationalError: near "qq": syntax error\n'
2024-05-11 17:38:15,770 (87749/MainThread) litecli.main ERROR - sql: 'q', error: OperationalError('near "q": syntax error')
2024-05-11 17:38:15,771 (87749/MainThread) litecli.main ERROR - traceback: 'Traceback (most recent call last):\n  File "/opt/homebrew/Cellar/litecli/1.11.0/libexec/lib/python3.12/site-packages/litecli/sqlexecute.py", line 125, in run\n    for result in special.execute(cur, sql):\n                  ^^^^^^^^^^^^^^^^^^^^^^^^^\n  File "/opt/homebrew/Cellar/litecli/1.11.0/libexec/lib/python3.12/site-packages/litecli/packages/special/main.py", line 109, in execute\n    raise CommandNotFound\nlitecli.packages.special.main.CommandNotFound\n\nDuring handling of the above exception, another exception occurred:\n\nTraceback (most recent call last):\n  File "/opt/homebrew/Cellar/litecli/1.11.0/libexec/lib/python3.12/site-packages/litecli/main.py", line 453, in one_iteration\n    for title, cur, headers, status in res:\n  File "/opt/homebrew/Cellar/litecli/1.11.0/libexec/lib/python3.12/site-packages/litecli/sqlexecute.py", line 132, in run\n    cur.execute(sql)\nsqlite3.OperationalError: near "q": syntax error\n'
2024-05-11 17:38:18,314 (87749/MainThread) litecli.main ERROR - sql: 'c', error: OperationalError('near "c": syntax error')
2024-05-11 17:38:18,315 (87749/MainThread) litecli.main ERROR - traceback: 'Traceback (most recent call last):\n  File "/opt/homebrew/Cellar/litecli/1.11.0/libexec/lib/python3.12/site-packages/litecli/sqlexecute.py", line 125, in run\n    for result in special.execute(cur, sql):\n                  ^^^^^^^^^^^^^^^^^^^^^^^^^\n  File "/opt/homebrew/Cellar/litecli/1.11.0/libexec/lib/python3.12/site-packages/litecli/packages/special/main.py", line 109, in execute\n    raise CommandNotFound\nlitecli.packages.special.main.CommandNotFound\n\nDuring handling of the above exception, another exception occurred:\n\nTraceback (most recent call last):\n  File "/opt/homebrew/Cellar/litecli/1.11.0/libexec/lib/python3.12/site-packages/litecli/main.py", line 453, in one_iteration\n    for title, cur, headers, status in res:\n  File "/opt/homebrew/Cellar/litecli/1.11.0/libexec/lib/python3.12/site-packages/litecli/sqlexecute.py", line 132, in run\n    cur.execute(sql)\nsqlite3.OperationalError: near "c": syntax error\n'
2024-05-11 18:34:35,440 (4609/MainThread) litecli.main ERROR - sql: 'qqq:qqq', error: OperationalError('near "qqq": syntax error')
2024-05-11 18:34:35,445 (4609/MainThread) litecli.main ERROR - traceback: 'Traceback (most recent call last):\n  File "/opt/homebrew/Cellar/litecli/1.11.0/libexec/lib/python3.12/site-packages/litecli/sqlexecute.py", line 125, in run\n    for result in special.execute(cur, sql):\n                  ^^^^^^^^^^^^^^^^^^^^^^^^^\n  File "/opt/homebrew/Cellar/litecli/1.11.0/libexec/lib/python3.12/site-packages/litecli/packages/special/main.py", line 109, in execute\n    raise CommandNotFound\nlitecli.packages.special.main.CommandNotFound\n\nDuring handling of the above exception, another exception occurred:\n\nTraceback (most recent call last):\n  File "/opt/homebrew/Cellar/litecli/1.11.0/libexec/lib/python3.12/site-packages/litecli/main.py", line 453, in one_iteration\n    for title, cur, headers, status in res:\n  File "/opt/homebrew/Cellar/litecli/1.11.0/libexec/lib/python3.12/site-packages/litecli/sqlexecute.py", line 132, in run\n    cur.execute(sql)\nsqlite3.OperationalError: near "qqq": syntax error\n'
2024-05-11 18:34:43,993 (4609/MainThread) litecli.main ERROR - sql: 'current_date', error: OperationalError('near "current_date": syntax error')
2024-05-11 18:34:43,993 (4609/MainThread) litecli.main ERROR - traceback: 'Traceback (most recent call last):\n  File "/opt/homebrew/Cellar/litecli/1.11.0/libexec/lib/python3.12/site-packages/litecli/sqlexecute.py", line 125, in run\n    for result in special.execute(cur, sql):\n                  ^^^^^^^^^^^^^^^^^^^^^^^^^\n  File "/opt/homebrew/Cellar/litecli/1.11.0/libexec/lib/python3.12/site-packages/litecli/packages/special/main.py", line 109, in execute\n    raise CommandNotFound\nlitecli.packages.special.main.CommandNotFound\n\nDuring handling of the above exception, another exception occurred:\n\nTraceback (most recent call last):\n  File "/opt/homebrew/Cellar/litecli/1.11.0/libexec/lib/python3.12/site-packages/litecli/main.py", line 453, in one_iteration\n    for title, cur, headers, status in res:\n  File "/opt/homebrew/Cellar/litecli/1.11.0/libexec/lib/python3.12/site-packages/litecli/sqlexecute.py", line 132, in run\n    cur.execute(sql)\nsqlite3.OperationalError: near "current_date": syntax error\n'
2024-05-11 18:34:46,507 (4609/MainThread) litecli.main ERROR - sql: 'current_date(0', error: OperationalError('near "current_date": syntax error')
2024-05-11 18:34:46,507 (4609/MainThread) litecli.main ERROR - traceback: 'Traceback (most recent call last):\n  File "/opt/homebrew/Cellar/litecli/1.11.0/libexec/lib/python3.12/site-packages/litecli/sqlexecute.py", line 125, in run\n    for result in special.execute(cur, sql):\n                  ^^^^^^^^^^^^^^^^^^^^^^^^^\n  File "/opt/homebrew/Cellar/litecli/1.11.0/libexec/lib/python3.12/site-packages/litecli/packages/special/main.py", line 109, in execute\n    raise CommandNotFound\nlitecli.packages.special.main.CommandNotFound\n\nDuring handling of the above exception, another exception occurred:\n\nTraceback (most recent call last):\n  File "/opt/homebrew/Cellar/litecli/1.11.0/libexec/lib/python3.12/site-packages/litecli/main.py", line 453, in one_iteration\n    for title, cur, headers, status in res:\n  File "/opt/homebrew/Cellar/litecli/1.11.0/libexec/lib/python3.12/site-packages/litecli/sqlexecute.py", line 132, in run\n    cur.execute(sql)\nsqlite3.OperationalError: near "current_date": syntax error\n'
2024-05-11 18:34:49,428 (4609/MainThread) litecli.main ERROR - sql: 'current_date()', error: OperationalError('near "current_date": syntax error')
2024-05-11 18:34:49,429 (4609/MainThread) litecli.main ERROR - traceback: 'Traceback (most recent call last):\n  File "/opt/homebrew/Cellar/litecli/1.11.0/libexec/lib/python3.12/site-packages/litecli/sqlexecute.py", line 125, in run\n    for result in special.execute(cur, sql):\n                  ^^^^^^^^^^^^^^^^^^^^^^^^^\n  File "/opt/homebrew/Cellar/litecli/1.11.0/libexec/lib/python3.12/site-packages/litecli/packages/special/main.py", line 109, in execute\n    raise CommandNotFound\nlitecli.packages.special.main.CommandNotFound\n\nDuring handling of the above exception, another exception occurred:\n\nTraceback (most recent call last):\n  File "/opt/homebrew/Cellar/litecli/1.11.0/libexec/lib/python3.12/site-packages/litecli/main.py", line 453, in one_iteration\n    for title, cur, headers, status in res:\n  File "/opt/homebrew/Cellar/litecli/1.11.0/libexec/lib/python3.12/site-packages/litecli/sqlexecute.py", line 132, in run\n    cur.execute(sql)\nsqlite3.OperationalError: near "current_date": syntax error\n'
2024-05-13 08:45:21,367 (71021/MainThread) litecli.main ERROR - sql: 'c', error: OperationalError('near "c": syntax error')
2024-05-13 08:45:21,371 (71021/MainThread) litecli.main ERROR - traceback: 'Traceback (most recent call last):\n  File "/opt/homebrew/Cellar/litecli/1.11.0/libexec/lib/python3.12/site-packages/litecli/sqlexecute.py", line 125, in run\n    for result in special.execute(cur, sql):\n                  ^^^^^^^^^^^^^^^^^^^^^^^^^\n  File "/opt/homebrew/Cellar/litecli/1.11.0/libexec/lib/python3.12/site-packages/litecli/packages/special/main.py", line 109, in execute\n    raise CommandNotFound\nlitecli.packages.special.main.CommandNotFound\n\nDuring handling of the above exception, another exception occurred:\n\nTraceback (most recent call last):\n  File "/opt/homebrew/Cellar/litecli/1.11.0/libexec/lib/python3.12/site-packages/litecli/main.py", line 453, in one_iteration\n    for title, cur, headers, status in res:\n  File "/opt/homebrew/Cellar/litecli/1.11.0/libexec/lib/python3.12/site-packages/litecli/sqlexecute.py", line 132, in run\n    cur.execute(sql)\nsqlite3.OperationalError: near "c": syntax error\n'
2024-05-13 08:52:38,283 (71021/MainThread) litecli.main ERROR - sql: 'select (id) from employees e1 join employees e2 group by title;', error: OperationalError('ambiguous column name: id')
2024-05-13 08:52:38,284 (71021/MainThread) litecli.main ERROR - traceback: 'Traceback (most recent call last):\n  File "/opt/homebrew/Cellar/litecli/1.11.0/libexec/lib/python3.12/site-packages/litecli/sqlexecute.py", line 125, in run\n    for result in special.execute(cur, sql):\n                  ^^^^^^^^^^^^^^^^^^^^^^^^^\n  File "/opt/homebrew/Cellar/litecli/1.11.0/libexec/lib/python3.12/site-packages/litecli/packages/special/main.py", line 109, in execute\n    raise CommandNotFound\nlitecli.packages.special.main.CommandNotFound\n\nDuring handling of the above exception, another exception occurred:\n\nTraceback (most recent call last):\n  File "/opt/homebrew/Cellar/litecli/1.11.0/libexec/lib/python3.12/site-packages/litecli/main.py", line 453, in one_iteration\n    for title, cur, headers, status in res:\n  File "/opt/homebrew/Cellar/litecli/1.11.0/libexec/lib/python3.12/site-packages/litecli/sqlexecute.py", line 132, in run\n    cur.execute(sql)\nsqlite3.OperationalError: ambiguous column name: id\n'
2024-05-13 08:52:43,857 (71021/MainThread) litecli.main ERROR - sql: 'select (e1.id) from employees e1 join employees e2 group by title;', error: OperationalError('ambiguous column name: title')
2024-05-13 08:52:43,858 (71021/MainThread) litecli.main ERROR - traceback: 'Traceback (most recent call last):\n  File "/opt/homebrew/Cellar/litecli/1.11.0/libexec/lib/python3.12/site-packages/litecli/sqlexecute.py", line 125, in run\n    for result in special.execute(cur, sql):\n                  ^^^^^^^^^^^^^^^^^^^^^^^^^\n  File "/opt/homebrew/Cellar/litecli/1.11.0/libexec/lib/python3.12/site-packages/litecli/packages/special/main.py", line 109, in execute\n    raise CommandNotFound\nlitecli.packages.special.main.CommandNotFound\n\nDuring handling of the above exception, another exception occurred:\n\nTraceback (most recent call last):\n  File "/opt/homebrew/Cellar/litecli/1.11.0/libexec/lib/python3.12/site-packages/litecli/main.py", line 453, in one_iteration\n    for title, cur, headers, status in res:\n  File "/opt/homebrew/Cellar/litecli/1.11.0/libexec/lib/python3.12/site-packages/litecli/sqlexecute.py", line 132, in run\n    cur.execute(sql)\nsqlite3.OperationalError: ambiguous column name: title\n'
2024-05-13 08:53:33,455 (71021/MainThread) litecli.main ERROR - sql: 'SELECT title, employee_id, name, other_columns\nFROM employees\nORDER BY title;\n', error: OperationalError('no such column: employee_id')
2024-05-13 08:53:33,456 (71021/MainThread) litecli.main ERROR - traceback: 'Traceback (most recent call last):\n  File "/opt/homebrew/Cellar/litecli/1.11.0/libexec/lib/python3.12/site-packages/litecli/sqlexecute.py", line 125, in run\n    for result in special.execute(cur, sql):\n                  ^^^^^^^^^^^^^^^^^^^^^^^^^\n  File "/opt/homebrew/Cellar/litecli/1.11.0/libexec/lib/python3.12/site-packages/litecli/packages/special/main.py", line 109, in execute\n    raise CommandNotFound\nlitecli.packages.special.main.CommandNotFound\n\nDuring handling of the above exception, another exception occurred:\n\nTraceback (most recent call last):\n  File "/opt/homebrew/Cellar/litecli/1.11.0/libexec/lib/python3.12/site-packages/litecli/main.py", line 453, in one_iteration\n    for title, cur, headers, status in res:\n  File "/opt/homebrew/Cellar/litecli/1.11.0/libexec/lib/python3.12/site-packages/litecli/sqlexecute.py", line 132, in run\n    cur.execute(sql)\nsqlite3.OperationalError: no such column: employee_id\n'
2024-05-13 08:53:40,410 (71021/MainThread) litecli.main ERROR - sql: 'SELECT title, id, name, other_columns\nFROM employees\nORDER BY title;\n', error: OperationalError('no such column: other_columns')
2024-05-13 08:53:40,411 (71021/MainThread) litecli.main ERROR - traceback: 'Traceback (most recent call last):\n  File "/opt/homebrew/Cellar/litecli/1.11.0/libexec/lib/python3.12/site-packages/litecli/sqlexecute.py", line 125, in run\n    for result in special.execute(cur, sql):\n                  ^^^^^^^^^^^^^^^^^^^^^^^^^\n  File "/opt/homebrew/Cellar/litecli/1.11.0/libexec/lib/python3.12/site-packages/litecli/packages/special/main.py", line 109, in execute\n    raise CommandNotFound\nlitecli.packages.special.main.CommandNotFound\n\nDuring handling of the above exception, another exception occurred:\n\nTraceback (most recent call last):\n  File "/opt/homebrew/Cellar/litecli/1.11.0/libexec/lib/python3.12/site-packages/litecli/main.py", line 453, in one_iteration\n    for title, cur, headers, status in res:\n  File "/opt/homebrew/Cellar/litecli/1.11.0/libexec/lib/python3.12/site-packages/litecli/sqlexecute.py", line 132, in run\n    cur.execute(sql)\nsqlite3.OperationalError: no such column: other_columns\n'
2024-05-13 08:59:42,692 (71021/MainThread) litecli.main ERROR - sql: 'select studio from films;', error: OperationalError('no such column: studio')
2024-05-13 08:59:42,692 (71021/MainThread) litecli.main ERROR - traceback: 'Traceback (most recent call last):\n  File "/opt/homebrew/Cellar/litecli/1.11.0/libexec/lib/python3.12/site-packages/litecli/sqlexecute.py", line 125, in run\n    for result in special.execute(cur, sql):\n                  ^^^^^^^^^^^^^^^^^^^^^^^^^\n  File "/opt/homebrew/Cellar/litecli/1.11.0/libexec/lib/python3.12/site-packages/litecli/packages/special/main.py", line 109, in execute\n    raise CommandNotFound\nlitecli.packages.special.main.CommandNotFound\n\nDuring handling of the above exception, another exception occurred:\n\nTraceback (most recent call last):\n  File "/opt/homebrew/Cellar/litecli/1.11.0/libexec/lib/python3.12/site-packages/litecli/main.py", line 453, in one_iteration\n    for title, cur, headers, status in res:\n  File "/opt/homebrew/Cellar/litecli/1.11.0/libexec/lib/python3.12/site-packages/litecli/sqlexecute.py", line 132, in run\n    cur.execute(sql)\nsqlite3.OperationalError: no such column: studio\n'
2024-05-13 08:59:46,795 (71021/MainThread) litecli.main ERROR - sql: 'select studioId from films;', error: OperationalError('no such column: studioId')
2024-05-13 08:59:46,796 (71021/MainThread) litecli.main ERROR - traceback: 'Traceback (most recent call last):\n  File "/opt/homebrew/Cellar/litecli/1.11.0/libexec/lib/python3.12/site-packages/litecli/sqlexecute.py", line 125, in run\n    for result in special.execute(cur, sql):\n                  ^^^^^^^^^^^^^^^^^^^^^^^^^\n  File "/opt/homebrew/Cellar/litecli/1.11.0/libexec/lib/python3.12/site-packages/litecli/packages/special/main.py", line 109, in execute\n    raise CommandNotFound\nlitecli.packages.special.main.CommandNotFound\n\nDuring handling of the above exception, another exception occurred:\n\nTraceback (most recent call last):\n  File "/opt/homebrew/Cellar/litecli/1.11.0/libexec/lib/python3.12/site-packages/litecli/main.py", line 453, in one_iteration\n    for title, cur, headers, status in res:\n  File "/opt/homebrew/Cellar/litecli/1.11.0/libexec/lib/python3.12/site-packages/litecli/sqlexecute.py", line 132, in run\n    cur.execute(sql)\nsqlite3.OperationalError: no such column: studioId\n'
2024-05-13 09:06:44,431 (71021/MainThread) litecli.main ERROR - sql: 'SELECT title, name from films join studio on films.studio_id = studio.id;', error: OperationalError('no such table: studio')
2024-05-13 09:06:44,432 (71021/MainThread) litecli.main ERROR - traceback: 'Traceback (most recent call last):\n  File "/opt/homebrew/Cellar/litecli/1.11.0/libexec/lib/python3.12/site-packages/litecli/sqlexecute.py", line 125, in run\n    for result in special.execute(cur, sql):\n                  ^^^^^^^^^^^^^^^^^^^^^^^^^\n  File "/opt/homebrew/Cellar/litecli/1.11.0/libexec/lib/python3.12/site-packages/litecli/packages/special/main.py", line 109, in execute\n    raise CommandNotFound\nlitecli.packages.special.main.CommandNotFound\n\nDuring handling of the above exception, another exception occurred:\n\nTraceback (most recent call last):\n  File "/opt/homebrew/Cellar/litecli/1.11.0/libexec/lib/python3.12/site-packages/litecli/main.py", line 453, in one_iteration\n    for title, cur, headers, status in res:\n  File "/opt/homebrew/Cellar/litecli/1.11.0/libexec/lib/python3.12/site-packages/litecli/sqlexecute.py", line 132, in run\n    cur.execute(sql)\nsqlite3.OperationalError: no such table: studio\n'
2024-05-13 09:08:08,445 (71021/MainThread) litecli.main ERROR - sql: 'SELECT employee.name as employee_name, department.name as department_name from employees join departments on employees.department_id = departments.id;', error: OperationalError('no such column: employee.name')
2024-05-13 09:08:08,446 (71021/MainThread) litecli.main ERROR - traceback: 'Traceback (most recent call last):\n  File "/opt/homebrew/Cellar/litecli/1.11.0/libexec/lib/python3.12/site-packages/litecli/sqlexecute.py", line 125, in run\n    for result in special.execute(cur, sql):\n                  ^^^^^^^^^^^^^^^^^^^^^^^^^\n  File "/opt/homebrew/Cellar/litecli/1.11.0/libexec/lib/python3.12/site-packages/litecli/packages/special/main.py", line 109, in execute\n    raise CommandNotFound\nlitecli.packages.special.main.CommandNotFound\n\nDuring handling of the above exception, another exception occurred:\n\nTraceback (most recent call last):\n  File "/opt/homebrew/Cellar/litecli/1.11.0/libexec/lib/python3.12/site-packages/litecli/main.py", line 453, in one_iteration\n    for title, cur, headers, status in res:\n  File "/opt/homebrew/Cellar/litecli/1.11.0/libexec/lib/python3.12/site-packages/litecli/sqlexecute.py", line 132, in run\n    cur.execute(sql)\nsqlite3.OperationalError: no such column: employee.name\n'
2024-05-13 09:08:14,075 (71021/MainThread) litecli.main ERROR - sql: 'SELECT employees.name as employee_name, department.name as department_name from employees join departments on employees.department_id = departments.id;', error: OperationalError('no such column: department.name')
2024-05-13 09:08:14,075 (71021/MainThread) litecli.main ERROR - traceback: 'Traceback (most recent call last):\n  File "/opt/homebrew/Cellar/litecli/1.11.0/libexec/lib/python3.12/site-packages/litecli/sqlexecute.py", line 125, in run\n    for result in special.execute(cur, sql):\n                  ^^^^^^^^^^^^^^^^^^^^^^^^^\n  File "/opt/homebrew/Cellar/litecli/1.11.0/libexec/lib/python3.12/site-packages/litecli/packages/special/main.py", line 109, in execute\n    raise CommandNotFound\nlitecli.packages.special.main.CommandNotFound\n\nDuring handling of the above exception, another exception occurred:\n\nTraceback (most recent call last):\n  File "/opt/homebrew/Cellar/litecli/1.11.0/libexec/lib/python3.12/site-packages/litecli/main.py", line 453, in one_iteration\n    for title, cur, headers, status in res:\n  File "/opt/homebrew/Cellar/litecli/1.11.0/libexec/lib/python3.12/site-packages/litecli/sqlexecute.py", line 132, in run\n    cur.execute(sql)\nsqlite3.OperationalError: no such column: department.name\n'
2024-05-13 09:12:49,899 (71021/MainThread) litecli.main ERROR - sql: 'select title, name from films join genre_films on films.id = genre_films.film_id;', error: OperationalError('no such column: name')
2024-05-13 09:12:49,900 (71021/MainThread) litecli.main ERROR - traceback: 'Traceback (most recent call last):\n  File "/opt/homebrew/Cellar/litecli/1.11.0/libexec/lib/python3.12/site-packages/litecli/sqlexecute.py", line 125, in run\n    for result in special.execute(cur, sql):\n                  ^^^^^^^^^^^^^^^^^^^^^^^^^\n  File "/opt/homebrew/Cellar/litecli/1.11.0/libexec/lib/python3.12/site-packages/litecli/packages/special/main.py", line 109, in execute\n    raise CommandNotFound\nlitecli.packages.special.main.CommandNotFound\n\nDuring handling of the above exception, another exception occurred:\n\nTraceback (most recent call last):\n  File "/opt/homebrew/Cellar/litecli/1.11.0/libexec/lib/python3.12/site-packages/litecli/main.py", line 453, in one_iteration\n    for title, cur, headers, status in res:\n  File "/opt/homebrew/Cellar/litecli/1.11.0/libexec/lib/python3.12/site-packages/litecli/sqlexecute.py", line 132, in run\n    cur.execute(sql)\nsqlite3.OperationalError: no such column: name\n'
2024-05-13 09:16:16,311 (71021/MainThread) litecli.main ERROR - sql: 'SELECT films.title, films.name, GROUP_CONCAT(genres.name) AS genres\nFROM films\nJOIN genre_films ON films.id = genre_films.film_id\nJOIN genres ON genre_films.genre_id = genres.id\nGROUP BY films.title, films.name;\n', error: OperationalError('no such column: films.name')
2024-05-13 09:16:16,312 (71021/MainThread) litecli.main ERROR - traceback: 'Traceback (most recent call last):\n  File "/opt/homebrew/Cellar/litecli/1.11.0/libexec/lib/python3.12/site-packages/litecli/sqlexecute.py", line 125, in run\n    for result in special.execute(cur, sql):\n                  ^^^^^^^^^^^^^^^^^^^^^^^^^\n  File "/opt/homebrew/Cellar/litecli/1.11.0/libexec/lib/python3.12/site-packages/litecli/packages/special/main.py", line 109, in execute\n    raise CommandNotFound\nlitecli.packages.special.main.CommandNotFound\n\nDuring handling of the above exception, another exception occurred:\n\nTraceback (most recent call last):\n  File "/opt/homebrew/Cellar/litecli/1.11.0/libexec/lib/python3.12/site-packages/litecli/main.py", line 453, in one_iteration\n    for title, cur, headers, status in res:\n  File "/opt/homebrew/Cellar/litecli/1.11.0/libexec/lib/python3.12/site-packages/litecli/sqlexecute.py", line 132, in run\n    cur.execute(sql)\nsqlite3.OperationalError: no such column: films.name\n'
2024-05-13 09:16:26,366 (71021/MainThread) litecli.main ERROR - sql: 'SELECT films.title, films.name, GROUP_CONCAT(genres.name) AS genres\nFROM films\nJOIN genre_films ON films.id = genre_films.film_id\nJOIN genres ON genre_films.genre_id = genres.id\nGROUP BY films.title;\n', error: OperationalError('no such column: films.name')
2024-05-13 09:16:26,367 (71021/MainThread) litecli.main ERROR - traceback: 'Traceback (most recent call last):\n  File "/opt/homebrew/Cellar/litecli/1.11.0/libexec/lib/python3.12/site-packages/litecli/sqlexecute.py", line 125, in run\n    for result in special.execute(cur, sql):\n                  ^^^^^^^^^^^^^^^^^^^^^^^^^\n  File "/opt/homebrew/Cellar/litecli/1.11.0/libexec/lib/python3.12/site-packages/litecli/packages/special/main.py", line 109, in execute\n    raise CommandNotFound\nlitecli.packages.special.main.CommandNotFound\n\nDuring handling of the above exception, another exception occurred:\n\nTraceback (most recent call last):\n  File "/opt/homebrew/Cellar/litecli/1.11.0/libexec/lib/python3.12/site-packages/litecli/main.py", line 453, in one_iteration\n    for title, cur, headers, status in res:\n  File "/opt/homebrew/Cellar/litecli/1.11.0/libexec/lib/python3.12/site-packages/litecli/sqlexecute.py", line 132, in run\n    cur.execute(sql)\nsqlite3.OperationalError: no such column: films.name\n'
2024-05-13 09:37:18,565 (71021/MainThread) litecli.main ERROR - sql: 'c', error: OperationalError('near "c": syntax error')
2024-05-13 09:37:18,566 (71021/MainThread) litecli.main ERROR - traceback: 'Traceback (most recent call last):\n  File "/opt/homebrew/Cellar/litecli/1.11.0/libexec/lib/python3.12/site-packages/litecli/sqlexecute.py", line 125, in run\n    for result in special.execute(cur, sql):\n                  ^^^^^^^^^^^^^^^^^^^^^^^^^\n  File "/opt/homebrew/Cellar/litecli/1.11.0/libexec/lib/python3.12/site-packages/litecli/packages/special/main.py", line 109, in execute\n    raise CommandNotFound\nlitecli.packages.special.main.CommandNotFound\n\nDuring handling of the above exception, another exception occurred:\n\nTraceback (most recent call last):\n  File "/opt/homebrew/Cellar/litecli/1.11.0/libexec/lib/python3.12/site-packages/litecli/main.py", line 453, in one_iteration\n    for title, cur, headers, status in res:\n  File "/opt/homebrew/Cellar/litecli/1.11.0/libexec/lib/python3.12/site-packages/litecli/sqlexecute.py", line 132, in run\n    cur.execute(sql)\nsqlite3.OperationalError: near "c": syntax error\n'
2024-05-13 09:37:20,587 (71021/MainThread) litecli.main ERROR - sql: 'clear', error: OperationalError('near "clear": syntax error')
2024-05-13 09:37:20,588 (71021/MainThread) litecli.main ERROR - traceback: 'Traceback (most recent call last):\n  File "/opt/homebrew/Cellar/litecli/1.11.0/libexec/lib/python3.12/site-packages/litecli/sqlexecute.py", line 125, in run\n    for result in special.execute(cur, sql):\n                  ^^^^^^^^^^^^^^^^^^^^^^^^^\n  File "/opt/homebrew/Cellar/litecli/1.11.0/libexec/lib/python3.12/site-packages/litecli/packages/special/main.py", line 109, in execute\n    raise CommandNotFound\nlitecli.packages.special.main.CommandNotFound\n\nDuring handling of the above exception, another exception occurred:\n\nTraceback (most recent call last):\n  File "/opt/homebrew/Cellar/litecli/1.11.0/libexec/lib/python3.12/site-packages/litecli/main.py", line 453, in one_iteration\n    for title, cur, headers, status in res:\n  File "/opt/homebrew/Cellar/litecli/1.11.0/libexec/lib/python3.12/site-packages/litecli/sqlexecute.py", line 132, in run\n    cur.execute(sql)\nsqlite3.OperationalError: near "clear": syntax error\n'
2024-05-13 09:42:41,412 (71021/MainThread) litecli.main ERROR - sql: 'select title, name, studios.name as studio_name from directors join film_directors on directors.id = film_directors.director_id join films on films.id = film_directors.film_id join films.studio_id = studios.id', error: OperationalError('near "=": syntax error')
2024-05-13 09:42:41,413 (71021/MainThread) litecli.main ERROR - traceback: 'Traceback (most recent call last):\n  File "/opt/homebrew/Cellar/litecli/1.11.0/libexec/lib/python3.12/site-packages/litecli/sqlexecute.py", line 125, in run\n    for result in special.execute(cur, sql):\n                  ^^^^^^^^^^^^^^^^^^^^^^^^^\n  File "/opt/homebrew/Cellar/litecli/1.11.0/libexec/lib/python3.12/site-packages/litecli/packages/special/main.py", line 109, in execute\n    raise CommandNotFound\nlitecli.packages.special.main.CommandNotFound\n\nDuring handling of the above exception, another exception occurred:\n\nTraceback (most recent call last):\n  File "/opt/homebrew/Cellar/litecli/1.11.0/libexec/lib/python3.12/site-packages/litecli/main.py", line 453, in one_iteration\n    for title, cur, headers, status in res:\n  File "/opt/homebrew/Cellar/litecli/1.11.0/libexec/lib/python3.12/site-packages/litecli/sqlexecute.py", line 132, in run\n    cur.execute(sql)\nsqlite3.OperationalError: near "=": syntax error\n'
2024-05-13 09:42:59,558 (71021/MainThread) litecli.main ERROR - sql: 'select title, name, studios.name as studio_name from directors join film_directors on directors.id = film_directors.director_id join films on films.id = film_directors.film_id', error: OperationalError('no such column: studios.name')
2024-05-13 09:42:59,559 (71021/MainThread) litecli.main ERROR - traceback: 'Traceback (most recent call last):\n  File "/opt/homebrew/Cellar/litecli/1.11.0/libexec/lib/python3.12/site-packages/litecli/sqlexecute.py", line 125, in run\n    for result in special.execute(cur, sql):\n                  ^^^^^^^^^^^^^^^^^^^^^^^^^\n  File "/opt/homebrew/Cellar/litecli/1.11.0/libexec/lib/python3.12/site-packages/litecli/packages/special/main.py", line 109, in execute\n    raise CommandNotFound\nlitecli.packages.special.main.CommandNotFound\n\nDuring handling of the above exception, another exception occurred:\n\nTraceback (most recent call last):\n  File "/opt/homebrew/Cellar/litecli/1.11.0/libexec/lib/python3.12/site-packages/litecli/main.py", line 453, in one_iteration\n    for title, cur, headers, status in res:\n  File "/opt/homebrew/Cellar/litecli/1.11.0/libexec/lib/python3.12/site-packages/litecli/sqlexecute.py", line 132, in run\n    cur.execute(sql)\nsqlite3.OperationalError: no such column: studios.name\n'
2024-05-13 09:43:19,494 (71021/MainThread) litecli.main ERROR - sql: 'select title, name, studios.name as studio_name from directors join film_directors on directors.id = film_directors.director_id join films on films.id = film_directors.film_id join studios on studios.id = films.studio_id', error: OperationalError('ambiguous column name: name')
2024-05-13 09:43:19,496 (71021/MainThread) litecli.main ERROR - traceback: 'Traceback (most recent call last):\n  File "/opt/homebrew/Cellar/litecli/1.11.0/libexec/lib/python3.12/site-packages/litecli/sqlexecute.py", line 125, in run\n    for result in special.execute(cur, sql):\n                  ^^^^^^^^^^^^^^^^^^^^^^^^^\n  File "/opt/homebrew/Cellar/litecli/1.11.0/libexec/lib/python3.12/site-packages/litecli/packages/special/main.py", line 109, in execute\n    raise CommandNotFound\nlitecli.packages.special.main.CommandNotFound\n\nDuring handling of the above exception, another exception occurred:\n\nTraceback (most recent call last):\n  File "/opt/homebrew/Cellar/litecli/1.11.0/libexec/lib/python3.12/site-packages/litecli/main.py", line 453, in one_iteration\n    for title, cur, headers, status in res:\n  File "/opt/homebrew/Cellar/litecli/1.11.0/libexec/lib/python3.12/site-packages/litecli/sqlexecute.py", line 132, in run\n    cur.execute(sql)\nsqlite3.OperationalError: ambiguous column name: name\n'
2024-05-13 09:53:13,471 (71021/MainThread) litecli.main ERROR - sql: 'select \n  sum(worldwide_gross) as director_total_gross, \n  directors.name, \n  studios.name as studio_name \nfrom directors \njoin film_directors on directors.id = film_directors.director_id \njoin films on films.id = film_directors.film_id \njoin studios on studios.id = films.studio_id \ngroup by directors.id\norder by director_total_gross desc limit on studio_name 3', error: OperationalError('near "on": syntax error')
2024-05-13 09:53:13,472 (71021/MainThread) litecli.main ERROR - traceback: 'Traceback (most recent call last):\n  File "/opt/homebrew/Cellar/litecli/1.11.0/libexec/lib/python3.12/site-packages/litecli/sqlexecute.py", line 125, in run\n    for result in special.execute(cur, sql):\n                  ^^^^^^^^^^^^^^^^^^^^^^^^^\n  File "/opt/homebrew/Cellar/litecli/1.11.0/libexec/lib/python3.12/site-packages/litecli/packages/special/main.py", line 109, in execute\n    raise CommandNotFound\nlitecli.packages.special.main.CommandNotFound\n\nDuring handling of the above exception, another exception occurred:\n\nTraceback (most recent call last):\n  File "/opt/homebrew/Cellar/litecli/1.11.0/libexec/lib/python3.12/site-packages/litecli/main.py", line 453, in one_iteration\n    for title, cur, headers, status in res:\n  File "/opt/homebrew/Cellar/litecli/1.11.0/libexec/lib/python3.12/site-packages/litecli/sqlexecute.py", line 132, in run\n    cur.execute(sql)\nsqlite3.OperationalError: near "on": syntax error\n'
2024-05-13 09:53:17,916 (71021/MainThread) litecli.main ERROR - sql: 'select \n  sum(worldwide_gross) as director_total_gross, \n  directors.name, \n  studios.name as studio_name \nfrom directors \njoin film_directors on directors.id = film_directors.director_id \njoin films on films.id = film_directors.film_id \njoin studios on studios.id = films.studio_id \ngroup by directors.id\norder by director_total_gross desc limit studio_name 3', error: OperationalError('near "3": syntax error')
2024-05-13 09:53:17,917 (71021/MainThread) litecli.main ERROR - traceback: 'Traceback (most recent call last):\n  File "/opt/homebrew/Cellar/litecli/1.11.0/libexec/lib/python3.12/site-packages/litecli/sqlexecute.py", line 125, in run\n    for result in special.execute(cur, sql):\n                  ^^^^^^^^^^^^^^^^^^^^^^^^^\n  File "/opt/homebrew/Cellar/litecli/1.11.0/libexec/lib/python3.12/site-packages/litecli/packages/special/main.py", line 109, in execute\n    raise CommandNotFound\nlitecli.packages.special.main.CommandNotFound\n\nDuring handling of the above exception, another exception occurred:\n\nTraceback (most recent call last):\n  File "/opt/homebrew/Cellar/litecli/1.11.0/libexec/lib/python3.12/site-packages/litecli/main.py", line 453, in one_iteration\n    for title, cur, headers, status in res:\n  File "/opt/homebrew/Cellar/litecli/1.11.0/libexec/lib/python3.12/site-packages/litecli/sqlexecute.py", line 132, in run\n    cur.execute(sql)\nsqlite3.OperationalError: near "3": syntax error\n'
2024-05-13 09:54:42,724 (71021/MainThread) litecli.main ERROR - sql: 'select \n  sum(worldwide_gross) as director_total_gross, \n  directors.name, \n  studios.name as studio_name \nfrom directors \njoin film_directors on directors.id = film_directors.director_id \njoin films on films.id = film_directors.film_id \njoin studios on studios.id = films.studio_id \ngroup by directors.id\norder by director_total_gross desc limit 3 group by studio_name', error: OperationalError('near "group": syntax error')
2024-05-13 09:54:42,724 (71021/MainThread) litecli.main ERROR - traceback: 'Traceback (most recent call last):\n  File "/opt/homebrew/Cellar/litecli/1.11.0/libexec/lib/python3.12/site-packages/litecli/sqlexecute.py", line 125, in run\n    for result in special.execute(cur, sql):\n                  ^^^^^^^^^^^^^^^^^^^^^^^^^\n  File "/opt/homebrew/Cellar/litecli/1.11.0/libexec/lib/python3.12/site-packages/litecli/packages/special/main.py", line 109, in execute\n    raise CommandNotFound\nlitecli.packages.special.main.CommandNotFound\n\nDuring handling of the above exception, another exception occurred:\n\nTraceback (most recent call last):\n  File "/opt/homebrew/Cellar/litecli/1.11.0/libexec/lib/python3.12/site-packages/litecli/main.py", line 453, in one_iteration\n    for title, cur, headers, status in res:\n  File "/opt/homebrew/Cellar/litecli/1.11.0/libexec/lib/python3.12/site-packages/litecli/sqlexecute.py", line 132, in run\n    cur.execute(sql)\nsqlite3.OperationalError: near "group": syntax error\n'
2024-05-13 14:56:00,303 (71021/MainThread) litecli.main ERROR - sql: 'c', error: OperationalError('near "c": syntax error')
2024-05-13 14:56:00,310 (71021/MainThread) litecli.main ERROR - traceback: 'Traceback (most recent call last):\n  File "/opt/homebrew/Cellar/litecli/1.11.0/libexec/lib/python3.12/site-packages/litecli/sqlexecute.py", line 125, in run\n    for result in special.execute(cur, sql):\n                  ^^^^^^^^^^^^^^^^^^^^^^^^^\n  File "/opt/homebrew/Cellar/litecli/1.11.0/libexec/lib/python3.12/site-packages/litecli/packages/special/main.py", line 109, in execute\n    raise CommandNotFound\nlitecli.packages.special.main.CommandNotFound\n\nDuring handling of the above exception, another exception occurred:\n\nTraceback (most recent call last):\n  File "/opt/homebrew/Cellar/litecli/1.11.0/libexec/lib/python3.12/site-packages/litecli/main.py", line 453, in one_iteration\n    for title, cur, headers, status in res:\n  File "/opt/homebrew/Cellar/litecli/1.11.0/libexec/lib/python3.12/site-packages/litecli/sqlexecute.py", line 132, in run\n    cur.execute(sql)\nsqlite3.OperationalError: near "c": syntax error\n'
2024-05-13 14:58:01,313 (71021/MainThread) litecli.main ERROR - sql: "SELECT DISTINCT directors.name AS director_name, studios.name AS studio_name\nFROM movie_directors\nJOIN films ON films.id = movie_directors.movie_id\nJOIN directors ON directors.id = movie_directors.director_id\nJOIN studios ON studios.id = films.studio_id\nWHERE studios.name = 'Disney';", error: OperationalError('no such table: movie_directors')
2024-05-13 14:58:01,313 (71021/MainThread) litecli.main ERROR - traceback: 'Traceback (most recent call last):\n  File "/opt/homebrew/Cellar/litecli/1.11.0/libexec/lib/python3.12/site-packages/litecli/sqlexecute.py", line 125, in run\n    for result in special.execute(cur, sql):\n                  ^^^^^^^^^^^^^^^^^^^^^^^^^\n  File "/opt/homebrew/Cellar/litecli/1.11.0/libexec/lib/python3.12/site-packages/litecli/packages/special/main.py", line 109, in execute\n    raise CommandNotFound\nlitecli.packages.special.main.CommandNotFound\n\nDuring handling of the above exception, another exception occurred:\n\nTraceback (most recent call last):\n  File "/opt/homebrew/Cellar/litecli/1.11.0/libexec/lib/python3.12/site-packages/litecli/main.py", line 453, in one_iteration\n    for title, cur, headers, status in res:\n  File "/opt/homebrew/Cellar/litecli/1.11.0/libexec/lib/python3.12/site-packages/litecli/sqlexecute.py", line 132, in run\n    cur.execute(sql)\nsqlite3.OperationalError: no such table: movie_directors\n'
2024-05-13 15:01:17,808 (71021/MainThread) litecli.main ERROR - sql: 'SELECT DISTINCT directors.name, \nFROM film_directors\nJOIN films ON films.id = film_directors.film_id\nJOIN directors ON directors.id = film_directors.director_id\nWHERE films.studio_id = 1;', error: OperationalError('near "FROM": syntax error')
2024-05-13 15:01:17,809 (71021/MainThread) litecli.main ERROR - traceback: 'Traceback (most recent call last):\n  File "/opt/homebrew/Cellar/litecli/1.11.0/libexec/lib/python3.12/site-packages/litecli/sqlexecute.py", line 125, in run\n    for result in special.execute(cur, sql):\n                  ^^^^^^^^^^^^^^^^^^^^^^^^^\n  File "/opt/homebrew/Cellar/litecli/1.11.0/libexec/lib/python3.12/site-packages/litecli/packages/special/main.py", line 109, in execute\n    raise CommandNotFound\nlitecli.packages.special.main.CommandNotFound\n\nDuring handling of the above exception, another exception occurred:\n\nTraceback (most recent call last):\n  File "/opt/homebrew/Cellar/litecli/1.11.0/libexec/lib/python3.12/site-packages/litecli/main.py", line 453, in one_iteration\n    for title, cur, headers, status in res:\n  File "/opt/homebrew/Cellar/litecli/1.11.0/libexec/lib/python3.12/site-packages/litecli/sqlexecute.py", line 132, in run\n    cur.execute(sql)\nsqlite3.OperationalError: near "FROM": syntax error\n'
2024-05-13 15:16:07,838 (95756/MainThread) litecli.main ERROR - sql: 'c', error: OperationalError('near "c": syntax error')
2024-05-13 15:16:07,843 (95756/MainThread) litecli.main ERROR - traceback: 'Traceback (most recent call last):\n  File "/opt/homebrew/Cellar/litecli/1.11.0/libexec/lib/python3.12/site-packages/litecli/sqlexecute.py", line 125, in run\n    for result in special.execute(cur, sql):\n                  ^^^^^^^^^^^^^^^^^^^^^^^^^\n  File "/opt/homebrew/Cellar/litecli/1.11.0/libexec/lib/python3.12/site-packages/litecli/packages/special/main.py", line 109, in execute\n    raise CommandNotFound\nlitecli.packages.special.main.CommandNotFound\n\nDuring handling of the above exception, another exception occurred:\n\nTraceback (most recent call last):\n  File "/opt/homebrew/Cellar/litecli/1.11.0/libexec/lib/python3.12/site-packages/litecli/main.py", line 453, in one_iteration\n    for title, cur, headers, status in res:\n  File "/opt/homebrew/Cellar/litecli/1.11.0/libexec/lib/python3.12/site-packages/litecli/sqlexecute.py", line 132, in run\n    cur.execute(sql)\nsqlite3.OperationalError: near "c": syntax error\n'
2024-05-13 15:16:57,016 (95756/MainThread) litecli.main ERROR - sql: 'select * from films order by desc', error: OperationalError('no such column: desc')
2024-05-13 15:16:57,016 (95756/MainThread) litecli.main ERROR - traceback: 'Traceback (most recent call last):\n  File "/opt/homebrew/Cellar/litecli/1.11.0/libexec/lib/python3.12/site-packages/litecli/sqlexecute.py", line 125, in run\n    for result in special.execute(cur, sql):\n                  ^^^^^^^^^^^^^^^^^^^^^^^^^\n  File "/opt/homebrew/Cellar/litecli/1.11.0/libexec/lib/python3.12/site-packages/litecli/packages/special/main.py", line 109, in execute\n    raise CommandNotFound\nlitecli.packages.special.main.CommandNotFound\n\nDuring handling of the above exception, another exception occurred:\n\nTraceback (most recent call last):\n  File "/opt/homebrew/Cellar/litecli/1.11.0/libexec/lib/python3.12/site-packages/litecli/main.py", line 453, in one_iteration\n    for title, cur, headers, status in res:\n  File "/opt/homebrew/Cellar/litecli/1.11.0/libexec/lib/python3.12/site-packages/litecli/sqlexecute.py", line 132, in run\n    cur.execute(sql)\nsqlite3.OperationalError: no such column: desc\n'
2024-05-13 15:17:38,775 (95756/MainThread) litecli.main ERROR - sql: 'select * from films order by desc limit 50', error: OperationalError('no such column: desc')
2024-05-13 15:17:38,776 (95756/MainThread) litecli.main ERROR - traceback: 'Traceback (most recent call last):\n  File "/opt/homebrew/Cellar/litecli/1.11.0/libexec/lib/python3.12/site-packages/litecli/sqlexecute.py", line 125, in run\n    for result in special.execute(cur, sql):\n                  ^^^^^^^^^^^^^^^^^^^^^^^^^\n  File "/opt/homebrew/Cellar/litecli/1.11.0/libexec/lib/python3.12/site-packages/litecli/packages/special/main.py", line 109, in execute\n    raise CommandNotFound\nlitecli.packages.special.main.CommandNotFound\n\nDuring handling of the above exception, another exception occurred:\n\nTraceback (most recent call last):\n  File "/opt/homebrew/Cellar/litecli/1.11.0/libexec/lib/python3.12/site-packages/litecli/main.py", line 453, in one_iteration\n    for title, cur, headers, status in res:\n  File "/opt/homebrew/Cellar/litecli/1.11.0/libexec/lib/python3.12/site-packages/litecli/sqlexecute.py", line 132, in run\n    cur.execute(sql)\nsqlite3.OperationalError: no such column: desc\n'
2024-05-13 15:18:05,431 (95756/MainThread) litecli.main ERROR - sql: 'update films where id > 1034 stud', error: OperationalError('near "where": syntax error')
2024-05-13 15:18:05,432 (95756/MainThread) litecli.main ERROR - traceback: 'Traceback (most recent call last):\n  File "/opt/homebrew/Cellar/litecli/1.11.0/libexec/lib/python3.12/site-packages/litecli/sqlexecute.py", line 125, in run\n    for result in special.execute(cur, sql):\n                  ^^^^^^^^^^^^^^^^^^^^^^^^^\n  File "/opt/homebrew/Cellar/litecli/1.11.0/libexec/lib/python3.12/site-packages/litecli/packages/special/main.py", line 109, in execute\n    raise CommandNotFound\nlitecli.packages.special.main.CommandNotFound\n\nDuring handling of the above exception, another exception occurred:\n\nTraceback (most recent call last):\n  File "/opt/homebrew/Cellar/litecli/1.11.0/libexec/lib/python3.12/site-packages/litecli/main.py", line 453, in one_iteration\n    for title, cur, headers, status in res:\n  File "/opt/homebrew/Cellar/litecli/1.11.0/libexec/lib/python3.12/site-packages/litecli/sqlexecute.py", line 132, in run\n    cur.execute(sql)\nsqlite3.OperationalError: near "where": syntax error\n'
2024-05-13 15:18:12,869 (95756/MainThread) litecli.main ERROR - sql: 'update films where id > 1034 studio_id = 4', error: OperationalError('near "where": syntax error')
2024-05-13 15:18:12,870 (95756/MainThread) litecli.main ERROR - traceback: 'Traceback (most recent call last):\n  File "/opt/homebrew/Cellar/litecli/1.11.0/libexec/lib/python3.12/site-packages/litecli/sqlexecute.py", line 125, in run\n    for result in special.execute(cur, sql):\n                  ^^^^^^^^^^^^^^^^^^^^^^^^^\n  File "/opt/homebrew/Cellar/litecli/1.11.0/libexec/lib/python3.12/site-packages/litecli/packages/special/main.py", line 109, in execute\n    raise CommandNotFound\nlitecli.packages.special.main.CommandNotFound\n\nDuring handling of the above exception, another exception occurred:\n\nTraceback (most recent call last):\n  File "/opt/homebrew/Cellar/litecli/1.11.0/libexec/lib/python3.12/site-packages/litecli/main.py", line 453, in one_iteration\n    for title, cur, headers, status in res:\n  File "/opt/homebrew/Cellar/litecli/1.11.0/libexec/lib/python3.12/site-packages/litecli/sqlexecute.py", line 132, in run\n    cur.execute(sql)\nsqlite3.OperationalError: near "where": syntax error\n'
2024-05-13 15:18:29,320 (95756/MainThread) litecli.main ERROR - sql: 'c', error: OperationalError('near "c": syntax error')
2024-05-13 15:18:29,321 (95756/MainThread) litecli.main ERROR - traceback: 'Traceback (most recent call last):\n  File "/opt/homebrew/Cellar/litecli/1.11.0/libexec/lib/python3.12/site-packages/litecli/sqlexecute.py", line 125, in run\n    for result in special.execute(cur, sql):\n                  ^^^^^^^^^^^^^^^^^^^^^^^^^\n  File "/opt/homebrew/Cellar/litecli/1.11.0/libexec/lib/python3.12/site-packages/litecli/packages/special/main.py", line 109, in execute\n    raise CommandNotFound\nlitecli.packages.special.main.CommandNotFound\n\nDuring handling of the above exception, another exception occurred:\n\nTraceback (most recent call last):\n  File "/opt/homebrew/Cellar/litecli/1.11.0/libexec/lib/python3.12/site-packages/litecli/main.py", line 453, in one_iteration\n    for title, cur, headers, status in res:\n  File "/opt/homebrew/Cellar/litecli/1.11.0/libexec/lib/python3.12/site-packages/litecli/sqlexecute.py", line 132, in run\n    cur.execute(sql)\nsqlite3.OperationalError: near "c": syntax error\n'
2024-05-13 15:18:32,501 (95756/MainThread) litecli.main ERROR - sql: 'c', error: OperationalError('near "c": syntax error')
2024-05-13 15:18:32,501 (95756/MainThread) litecli.main ERROR - traceback: 'Traceback (most recent call last):\n  File "/opt/homebrew/Cellar/litecli/1.11.0/libexec/lib/python3.12/site-packages/litecli/sqlexecute.py", line 125, in run\n    for result in special.execute(cur, sql):\n                  ^^^^^^^^^^^^^^^^^^^^^^^^^\n  File "/opt/homebrew/Cellar/litecli/1.11.0/libexec/lib/python3.12/site-packages/litecli/packages/special/main.py", line 109, in execute\n    raise CommandNotFound\nlitecli.packages.special.main.CommandNotFound\n\nDuring handling of the above exception, another exception occurred:\n\nTraceback (most recent call last):\n  File "/opt/homebrew/Cellar/litecli/1.11.0/libexec/lib/python3.12/site-packages/litecli/main.py", line 453, in one_iteration\n    for title, cur, headers, status in res:\n  File "/opt/homebrew/Cellar/litecli/1.11.0/libexec/lib/python3.12/site-packages/litecli/sqlexecute.py", line 132, in run\n    cur.execute(sql)\nsqlite3.OperationalError: near "c": syntax error\n'
2024-05-13 15:23:23,024 (95756/MainThread) litecli.main ERROR - sql: 'SELECT DISTINCT directors.name, studios.name\nFROM film_directors\nJOIN films ON films.id = film_directors.film_id\nJOIN directors ON directors.id = film_directors.director_id\nJOIN studios on studios.id = film_directors.studio_id\nWHERE films.studio_id = 1;', error: OperationalError('no such column: film_directors.studio_id')
2024-05-13 15:23:23,026 (95756/MainThread) litecli.main ERROR - traceback: 'Traceback (most recent call last):\n  File "/opt/homebrew/Cellar/litecli/1.11.0/libexec/lib/python3.12/site-packages/litecli/sqlexecute.py", line 125, in run\n    for result in special.execute(cur, sql):\n                  ^^^^^^^^^^^^^^^^^^^^^^^^^\n  File "/opt/homebrew/Cellar/litecli/1.11.0/libexec/lib/python3.12/site-packages/litecli/packages/special/main.py", line 109, in execute\n    raise CommandNotFound\nlitecli.packages.special.main.CommandNotFound\n\nDuring handling of the above exception, another exception occurred:\n\nTraceback (most recent call last):\n  File "/opt/homebrew/Cellar/litecli/1.11.0/libexec/lib/python3.12/site-packages/litecli/main.py", line 453, in one_iteration\n    for title, cur, headers, status in res:\n  File "/opt/homebrew/Cellar/litecli/1.11.0/libexec/lib/python3.12/site-packages/litecli/sqlexecute.py", line 132, in run\n    cur.execute(sql)\nsqlite3.OperationalError: no such column: film_directors.studio_id\n'
2024-05-13 15:26:49,564 (95756/MainThread) litecli.main ERROR - sql: 'select title, name from films join genre_films on films.id = genre_films.film_id join genres on genre_films.genre_id = genres.id join studios on studios.id = films.studio_id where studios.id = 1;', error: OperationalError('ambiguous column name: name')
2024-05-13 15:26:49,565 (95756/MainThread) litecli.main ERROR - traceback: 'Traceback (most recent call last):\n  File "/opt/homebrew/Cellar/litecli/1.11.0/libexec/lib/python3.12/site-packages/litecli/sqlexecute.py", line 125, in run\n    for result in special.execute(cur, sql):\n                  ^^^^^^^^^^^^^^^^^^^^^^^^^\n  File "/opt/homebrew/Cellar/litecli/1.11.0/libexec/lib/python3.12/site-packages/litecli/packages/special/main.py", line 109, in execute\n    raise CommandNotFound\nlitecli.packages.special.main.CommandNotFound\n\nDuring handling of the above exception, another exception occurred:\n\nTraceback (most recent call last):\n  File "/opt/homebrew/Cellar/litecli/1.11.0/libexec/lib/python3.12/site-packages/litecli/main.py", line 453, in one_iteration\n    for title, cur, headers, status in res:\n  File "/opt/homebrew/Cellar/litecli/1.11.0/libexec/lib/python3.12/site-packages/litecli/sqlexecute.py", line 132, in run\n    cur.execute(sql)\nsqlite3.OperationalError: ambiguous column name: name\n'
2024-05-13 15:32:13,554 (95756/MainThread) litecli.main ERROR - sql: 'select oscars_nominated, oscars won from films limit 1;', error: OperationalError('no such column: oscars')
2024-05-13 15:32:13,555 (95756/MainThread) litecli.main ERROR - traceback: 'Traceback (most recent call last):\n  File "/opt/homebrew/Cellar/litecli/1.11.0/libexec/lib/python3.12/site-packages/litecli/sqlexecute.py", line 125, in run\n    for result in special.execute(cur, sql):\n                  ^^^^^^^^^^^^^^^^^^^^^^^^^\n  File "/opt/homebrew/Cellar/litecli/1.11.0/libexec/lib/python3.12/site-packages/litecli/packages/special/main.py", line 109, in execute\n    raise CommandNotFound\nlitecli.packages.special.main.CommandNotFound\n\nDuring handling of the above exception, another exception occurred:\n\nTraceback (most recent call last):\n  File "/opt/homebrew/Cellar/litecli/1.11.0/libexec/lib/python3.12/site-packages/litecli/main.py", line 453, in one_iteration\n    for title, cur, headers, status in res:\n  File "/opt/homebrew/Cellar/litecli/1.11.0/libexec/lib/python3.12/site-packages/litecli/sqlexecute.py", line 132, in run\n    cur.execute(sql)\nsqlite3.OperationalError: no such column: oscars\n'
2024-05-13 15:35:58,450 (95756/MainThread) litecli.main ERROR - sql: 'select * from films limit 5 order by id desc;', error: OperationalError('near "order": syntax error')
2024-05-13 15:35:58,451 (95756/MainThread) litecli.main ERROR - traceback: 'Traceback (most recent call last):\n  File "/opt/homebrew/Cellar/litecli/1.11.0/libexec/lib/python3.12/site-packages/litecli/sqlexecute.py", line 125, in run\n    for result in special.execute(cur, sql):\n                  ^^^^^^^^^^^^^^^^^^^^^^^^^\n  File "/opt/homebrew/Cellar/litecli/1.11.0/libexec/lib/python3.12/site-packages/litecli/packages/special/main.py", line 109, in execute\n    raise CommandNotFound\nlitecli.packages.special.main.CommandNotFound\n\nDuring handling of the above exception, another exception occurred:\n\nTraceback (most recent call last):\n  File "/opt/homebrew/Cellar/litecli/1.11.0/libexec/lib/python3.12/site-packages/litecli/main.py", line 453, in one_iteration\n    for title, cur, headers, status in res:\n  File "/opt/homebrew/Cellar/litecli/1.11.0/libexec/lib/python3.12/site-packages/litecli/sqlexecute.py", line 132, in run\n    cur.execute(sql)\nsqlite3.OperationalError: near "order": syntax error\n'
2024-05-13 15:54:24,177 (95756/MainThread) litecli.main ERROR - sql: "select title, oscars_won from films order by oscars_won desc where title = 'Titanic';", error: OperationalError('near "where": syntax error')
2024-05-13 15:54:24,178 (95756/MainThread) litecli.main ERROR - traceback: 'Traceback (most recent call last):\n  File "/opt/homebrew/Cellar/litecli/1.11.0/libexec/lib/python3.12/site-packages/litecli/sqlexecute.py", line 125, in run\n    for result in special.execute(cur, sql):\n                  ^^^^^^^^^^^^^^^^^^^^^^^^^\n  File "/opt/homebrew/Cellar/litecli/1.11.0/libexec/lib/python3.12/site-packages/litecli/packages/special/main.py", line 109, in execute\n    raise CommandNotFound\nlitecli.packages.special.main.CommandNotFound\n\nDuring handling of the above exception, another exception occurred:\n\nTraceback (most recent call last):\n  File "/opt/homebrew/Cellar/litecli/1.11.0/libexec/lib/python3.12/site-packages/litecli/main.py", line 453, in one_iteration\n    for title, cur, headers, status in res:\n  File "/opt/homebrew/Cellar/litecli/1.11.0/libexec/lib/python3.12/site-packages/litecli/sqlexecute.py", line 132, in run\n    cur.execute(sql)\nsqlite3.OperationalError: near "where": syntax error\n'
2024-05-13 15:58:20,868 (95756/MainThread) litecli.main ERROR - sql: 'qqq', error: OperationalError('near "qqq": syntax error')
2024-05-13 15:58:20,869 (95756/MainThread) litecli.main ERROR - traceback: 'Traceback (most recent call last):\n  File "/opt/homebrew/Cellar/litecli/1.11.0/libexec/lib/python3.12/site-packages/litecli/sqlexecute.py", line 125, in run\n    for result in special.execute(cur, sql):\n                  ^^^^^^^^^^^^^^^^^^^^^^^^^\n  File "/opt/homebrew/Cellar/litecli/1.11.0/libexec/lib/python3.12/site-packages/litecli/packages/special/main.py", line 109, in execute\n    raise CommandNotFound\nlitecli.packages.special.main.CommandNotFound\n\nDuring handling of the above exception, another exception occurred:\n\nTraceback (most recent call last):\n  File "/opt/homebrew/Cellar/litecli/1.11.0/libexec/lib/python3.12/site-packages/litecli/main.py", line 453, in one_iteration\n    for title, cur, headers, status in res:\n  File "/opt/homebrew/Cellar/litecli/1.11.0/libexec/lib/python3.12/site-packages/litecli/sqlexecute.py", line 132, in run\n    cur.execute(sql)\nsqlite3.OperationalError: near "qqq": syntax error\n'
2024-05-13 16:01:03,207 (95756/MainThread) litecli.main ERROR - sql: 'select title from films order by oscars_win desc limit 5;', error: OperationalError('no such column: oscars_win')
2024-05-13 16:01:03,208 (95756/MainThread) litecli.main ERROR - traceback: 'Traceback (most recent call last):\n  File "/opt/homebrew/Cellar/litecli/1.11.0/libexec/lib/python3.12/site-packages/litecli/sqlexecute.py", line 125, in run\n    for result in special.execute(cur, sql):\n                  ^^^^^^^^^^^^^^^^^^^^^^^^^\n  File "/opt/homebrew/Cellar/litecli/1.11.0/libexec/lib/python3.12/site-packages/litecli/packages/special/main.py", line 109, in execute\n    raise CommandNotFound\nlitecli.packages.special.main.CommandNotFound\n\nDuring handling of the above exception, another exception occurred:\n\nTraceback (most recent call last):\n  File "/opt/homebrew/Cellar/litecli/1.11.0/libexec/lib/python3.12/site-packages/litecli/main.py", line 453, in one_iteration\n    for title, cur, headers, status in res:\n  File "/opt/homebrew/Cellar/litecli/1.11.0/libexec/lib/python3.12/site-packages/litecli/sqlexecute.py", line 132, in run\n    cur.execute(sql)\nsqlite3.OperationalError: no such column: oscars_win\n'
2024-05-13 16:02:27,199 (95756/MainThread) litecli.main ERROR - sql: 'select title, oscars_won from films where oscars_won > 9order by oscars_won desc limit 5;', error: OperationalError('unrecognized token: "9order"')
2024-05-13 16:02:27,199 (95756/MainThread) litecli.main ERROR - traceback: 'Traceback (most recent call last):\n  File "/opt/homebrew/Cellar/litecli/1.11.0/libexec/lib/python3.12/site-packages/litecli/sqlexecute.py", line 125, in run\n    for result in special.execute(cur, sql):\n                  ^^^^^^^^^^^^^^^^^^^^^^^^^\n  File "/opt/homebrew/Cellar/litecli/1.11.0/libexec/lib/python3.12/site-packages/litecli/packages/special/main.py", line 109, in execute\n    raise CommandNotFound\nlitecli.packages.special.main.CommandNotFound\n\nDuring handling of the above exception, another exception occurred:\n\nTraceback (most recent call last):\n  File "/opt/homebrew/Cellar/litecli/1.11.0/libexec/lib/python3.12/site-packages/litecli/main.py", line 453, in one_iteration\n    for title, cur, headers, status in res:\n  File "/opt/homebrew/Cellar/litecli/1.11.0/libexec/lib/python3.12/site-packages/litecli/sqlexecute.py", line 132, in run\n    cur.execute(sql)\nsqlite3.OperationalError: unrecognized token: "9order"\n'
2024-05-13 16:03:59,019 (95756/MainThread) litecli.main ERROR - sql: 'INSERT INTO films\nSELECT * FROM your_table WHERE id = 691;', error: OperationalError('no such table: your_table')
2024-05-13 16:03:59,020 (95756/MainThread) litecli.main ERROR - traceback: 'Traceback (most recent call last):\n  File "/opt/homebrew/Cellar/litecli/1.11.0/libexec/lib/python3.12/site-packages/litecli/sqlexecute.py", line 125, in run\n    for result in special.execute(cur, sql):\n                  ^^^^^^^^^^^^^^^^^^^^^^^^^\n  File "/opt/homebrew/Cellar/litecli/1.11.0/libexec/lib/python3.12/site-packages/litecli/packages/special/main.py", line 109, in execute\n    raise CommandNotFound\nlitecli.packages.special.main.CommandNotFound\n\nDuring handling of the above exception, another exception occurred:\n\nTraceback (most recent call last):\n  File "/opt/homebrew/Cellar/litecli/1.11.0/libexec/lib/python3.12/site-packages/litecli/main.py", line 453, in one_iteration\n    for title, cur, headers, status in res:\n  File "/opt/homebrew/Cellar/litecli/1.11.0/libexec/lib/python3.12/site-packages/litecli/sqlexecute.py", line 132, in run\n    cur.execute(sql)\nsqlite3.OperationalError: no such table: your_table\n'
2024-05-13 16:04:05,307 (95756/MainThread) litecli.main ERROR - sql: 'INSERT INTO films\nSELECT * FROM films WHERE id = 691;', error: IntegrityError('UNIQUE constraint failed: films.id')
2024-05-13 16:04:05,307 (95756/MainThread) litecli.main ERROR - traceback: 'Traceback (most recent call last):\n  File "/opt/homebrew/Cellar/litecli/1.11.0/libexec/lib/python3.12/site-packages/litecli/sqlexecute.py", line 125, in run\n    for result in special.execute(cur, sql):\n                  ^^^^^^^^^^^^^^^^^^^^^^^^^\n  File "/opt/homebrew/Cellar/litecli/1.11.0/libexec/lib/python3.12/site-packages/litecli/packages/special/main.py", line 109, in execute\n    raise CommandNotFound\nlitecli.packages.special.main.CommandNotFound\n\nDuring handling of the above exception, another exception occurred:\n\nTraceback (most recent call last):\n  File "/opt/homebrew/Cellar/litecli/1.11.0/libexec/lib/python3.12/site-packages/litecli/main.py", line 453, in one_iteration\n    for title, cur, headers, status in res:\n  File "/opt/homebrew/Cellar/litecli/1.11.0/libexec/lib/python3.12/site-packages/litecli/sqlexecute.py", line 132, in run\n    cur.execute(sql)\nsqlite3.IntegrityError: UNIQUE constraint failed: films.id\n'
2024-05-13 16:05:04,098 (95756/MainThread) litecli.main ERROR - sql: 'c', error: OperationalError('near "c": syntax error')
2024-05-13 16:05:04,099 (95756/MainThread) litecli.main ERROR - traceback: 'Traceback (most recent call last):\n  File "/opt/homebrew/Cellar/litecli/1.11.0/libexec/lib/python3.12/site-packages/litecli/sqlexecute.py", line 125, in run\n    for result in special.execute(cur, sql):\n                  ^^^^^^^^^^^^^^^^^^^^^^^^^\n  File "/opt/homebrew/Cellar/litecli/1.11.0/libexec/lib/python3.12/site-packages/litecli/packages/special/main.py", line 109, in execute\n    raise CommandNotFound\nlitecli.packages.special.main.CommandNotFound\n\nDuring handling of the above exception, another exception occurred:\n\nTraceback (most recent call last):\n  File "/opt/homebrew/Cellar/litecli/1.11.0/libexec/lib/python3.12/site-packages/litecli/main.py", line 453, in one_iteration\n    for title, cur, headers, status in res:\n  File "/opt/homebrew/Cellar/litecli/1.11.0/libexec/lib/python3.12/site-packages/litecli/sqlexecute.py", line 132, in run\n    cur.execute(sql)\nsqlite3.OperationalError: near "c": syntax error\n'
2024-05-13 16:05:31,469 (2630/MainThread) litecli.main ERROR - sql: 'c', error: OperationalError('near "c": syntax error')
2024-05-13 16:05:31,470 (2630/MainThread) litecli.main ERROR - traceback: 'Traceback (most recent call last):\n  File "/opt/homebrew/Cellar/litecli/1.11.0/libexec/lib/python3.12/site-packages/litecli/sqlexecute.py", line 125, in run\n    for result in special.execute(cur, sql):\n                  ^^^^^^^^^^^^^^^^^^^^^^^^^\n  File "/opt/homebrew/Cellar/litecli/1.11.0/libexec/lib/python3.12/site-packages/litecli/packages/special/main.py", line 109, in execute\n    raise CommandNotFound\nlitecli.packages.special.main.CommandNotFound\n\nDuring handling of the above exception, another exception occurred:\n\nTraceback (most recent call last):\n  File "/opt/homebrew/Cellar/litecli/1.11.0/libexec/lib/python3.12/site-packages/litecli/main.py", line 453, in one_iteration\n    for title, cur, headers, status in res:\n  File "/opt/homebrew/Cellar/litecli/1.11.0/libexec/lib/python3.12/site-packages/litecli/sqlexecute.py", line 132, in run\n    cur.execute(sql)\nsqlite3.OperationalError: near "c": syntax error\n'
2024-05-13 16:10:51,356 (2630/MainThread) litecli.main ERROR - sql: 'c', error: OperationalError('near "c": syntax error')
2024-05-13 16:10:51,358 (2630/MainThread) litecli.main ERROR - traceback: 'Traceback (most recent call last):\n  File "/opt/homebrew/Cellar/litecli/1.11.0/libexec/lib/python3.12/site-packages/litecli/sqlexecute.py", line 125, in run\n    for result in special.execute(cur, sql):\n                  ^^^^^^^^^^^^^^^^^^^^^^^^^\n  File "/opt/homebrew/Cellar/litecli/1.11.0/libexec/lib/python3.12/site-packages/litecli/packages/special/main.py", line 109, in execute\n    raise CommandNotFound\nlitecli.packages.special.main.CommandNotFound\n\nDuring handling of the above exception, another exception occurred:\n\nTraceback (most recent call last):\n  File "/opt/homebrew/Cellar/litecli/1.11.0/libexec/lib/python3.12/site-packages/litecli/main.py", line 453, in one_iteration\n    for title, cur, headers, status in res:\n  File "/opt/homebrew/Cellar/litecli/1.11.0/libexec/lib/python3.12/site-packages/litecli/sqlexecute.py", line 132, in run\n    cur.execute(sql)\nsqlite3.OperationalError: near "c": syntax error\n'
2024-05-13 16:12:16,844 (2630/MainThread) litecli.main ERROR - sql: 'select oscars_won, oscars_title from films where id = 691;', error: OperationalError('no such column: oscars_title')
2024-05-13 16:12:16,846 (2630/MainThread) litecli.main ERROR - traceback: 'Traceback (most recent call last):\n  File "/opt/homebrew/Cellar/litecli/1.11.0/libexec/lib/python3.12/site-packages/litecli/sqlexecute.py", line 125, in run\n    for result in special.execute(cur, sql):\n                  ^^^^^^^^^^^^^^^^^^^^^^^^^\n  File "/opt/homebrew/Cellar/litecli/1.11.0/libexec/lib/python3.12/site-packages/litecli/packages/special/main.py", line 109, in execute\n    raise CommandNotFound\nlitecli.packages.special.main.CommandNotFound\n\nDuring handling of the above exception, another exception occurred:\n\nTraceback (most recent call last):\n  File "/opt/homebrew/Cellar/litecli/1.11.0/libexec/lib/python3.12/site-packages/litecli/main.py", line 453, in one_iteration\n    for title, cur, headers, status in res:\n  File "/opt/homebrew/Cellar/litecli/1.11.0/libexec/lib/python3.12/site-packages/litecli/sqlexecute.py", line 132, in run\n    cur.execute(sql)\nsqlite3.OperationalError: no such column: oscars_title\n'
2024-05-13 16:17:21,002 (2630/MainThread) litecli.main ERROR - sql: 'ALTER TABLE films\nMODIFY COLUMN oscars_won INTEGER;', error: OperationalError('near "MODIFY": syntax error')
2024-05-13 16:17:21,004 (2630/MainThread) litecli.main ERROR - traceback: 'Traceback (most recent call last):\n  File "/opt/homebrew/Cellar/litecli/1.11.0/libexec/lib/python3.12/site-packages/litecli/sqlexecute.py", line 125, in run\n    for result in special.execute(cur, sql):\n                  ^^^^^^^^^^^^^^^^^^^^^^^^^\n  File "/opt/homebrew/Cellar/litecli/1.11.0/libexec/lib/python3.12/site-packages/litecli/packages/special/main.py", line 109, in execute\n    raise CommandNotFound\nlitecli.packages.special.main.CommandNotFound\n\nDuring handling of the above exception, another exception occurred:\n\nTraceback (most recent call last):\n  File "/opt/homebrew/Cellar/litecli/1.11.0/libexec/lib/python3.12/site-packages/litecli/main.py", line 453, in one_iteration\n    for title, cur, headers, status in res:\n  File "/opt/homebrew/Cellar/litecli/1.11.0/libexec/lib/python3.12/site-packages/litecli/sqlexecute.py", line 132, in run\n    cur.execute(sql)\nsqlite3.OperationalError: near "MODIFY": syntax error\n'
2024-05-13 16:21:16,778 (2630/MainThread) litecli.main ERROR - sql: 'c', error: OperationalError('near "c": syntax error')
2024-05-13 16:21:16,779 (2630/MainThread) litecli.main ERROR - traceback: 'Traceback (most recent call last):\n  File "/opt/homebrew/Cellar/litecli/1.11.0/libexec/lib/python3.12/site-packages/litecli/sqlexecute.py", line 125, in run\n    for result in special.execute(cur, sql):\n                  ^^^^^^^^^^^^^^^^^^^^^^^^^\n  File "/opt/homebrew/Cellar/litecli/1.11.0/libexec/lib/python3.12/site-packages/litecli/packages/special/main.py", line 109, in execute\n    raise CommandNotFound\nlitecli.packages.special.main.CommandNotFound\n\nDuring handling of the above exception, another exception occurred:\n\nTraceback (most recent call last):\n  File "/opt/homebrew/Cellar/litecli/1.11.0/libexec/lib/python3.12/site-packages/litecli/main.py", line 453, in one_iteration\n    for title, cur, headers, status in res:\n  File "/opt/homebrew/Cellar/litecli/1.11.0/libexec/lib/python3.12/site-packages/litecli/sqlexecute.py", line 132, in run\n    cur.execute(sql)\nsqlite3.OperationalError: near "c": syntax error\n'
2024-05-13 16:46:23,164 (9195/MainThread) litecli.main ERROR - sql: 'select oscars_nominated, oscars_won, title,  from films order by oscars_won desc limit 25;', error: OperationalError('near "from": syntax error')
2024-05-13 16:46:23,166 (9195/MainThread) litecli.main ERROR - traceback: 'Traceback (most recent call last):\n  File "/opt/homebrew/Cellar/litecli/1.11.0/libexec/lib/python3.12/site-packages/litecli/sqlexecute.py", line 125, in run\n    for result in special.execute(cur, sql):\n                  ^^^^^^^^^^^^^^^^^^^^^^^^^\n  File "/opt/homebrew/Cellar/litecli/1.11.0/libexec/lib/python3.12/site-packages/litecli/packages/special/main.py", line 109, in execute\n    raise CommandNotFound\nlitecli.packages.special.main.CommandNotFound\n\nDuring handling of the above exception, another exception occurred:\n\nTraceback (most recent call last):\n  File "/opt/homebrew/Cellar/litecli/1.11.0/libexec/lib/python3.12/site-packages/litecli/main.py", line 453, in one_iteration\n    for title, cur, headers, status in res:\n  File "/opt/homebrew/Cellar/litecli/1.11.0/libexec/lib/python3.12/site-packages/litecli/sqlexecute.py", line 132, in run\n    cur.execute(sql)\nsqlite3.OperationalError: near "from": syntax error\n'
2024-05-14 14:14:59,415 (56597/MainThread) litecli.main ERROR - sql: 'c', error: OperationalError('near "c": syntax error')
2024-05-14 14:14:59,422 (56597/MainThread) litecli.main ERROR - traceback: 'Traceback (most recent call last):\n  File "/opt/homebrew/Cellar/litecli/1.11.0/libexec/lib/python3.12/site-packages/litecli/sqlexecute.py", line 125, in run\n    for result in special.execute(cur, sql):\n                  ^^^^^^^^^^^^^^^^^^^^^^^^^\n  File "/opt/homebrew/Cellar/litecli/1.11.0/libexec/lib/python3.12/site-packages/litecli/packages/special/main.py", line 109, in execute\n    raise CommandNotFound\nlitecli.packages.special.main.CommandNotFound\n\nDuring handling of the above exception, another exception occurred:\n\nTraceback (most recent call last):\n  File "/opt/homebrew/Cellar/litecli/1.11.0/libexec/lib/python3.12/site-packages/litecli/main.py", line 453, in one_iteration\n    for title, cur, headers, status in res:\n  File "/opt/homebrew/Cellar/litecli/1.11.0/libexec/lib/python3.12/site-packages/litecli/sqlexecute.py", line 132, in run\n    cur.execute(sql)\nsqlite3.OperationalError: near "c": syntax error\n'
2024-05-14 14:15:49,519 (56597/MainThread) litecli.main ERROR - sql: 'select count(unique(title)) from films;', error: OperationalError('near "unique": syntax error')
2024-05-14 14:15:49,520 (56597/MainThread) litecli.main ERROR - traceback: 'Traceback (most recent call last):\n  File "/opt/homebrew/Cellar/litecli/1.11.0/libexec/lib/python3.12/site-packages/litecli/sqlexecute.py", line 125, in run\n    for result in special.execute(cur, sql):\n                  ^^^^^^^^^^^^^^^^^^^^^^^^^\n  File "/opt/homebrew/Cellar/litecli/1.11.0/libexec/lib/python3.12/site-packages/litecli/packages/special/main.py", line 109, in execute\n    raise CommandNotFound\nlitecli.packages.special.main.CommandNotFound\n\nDuring handling of the above exception, another exception occurred:\n\nTraceback (most recent call last):\n  File "/opt/homebrew/Cellar/litecli/1.11.0/libexec/lib/python3.12/site-packages/litecli/main.py", line 453, in one_iteration\n    for title, cur, headers, status in res:\n  File "/opt/homebrew/Cellar/litecli/1.11.0/libexec/lib/python3.12/site-packages/litecli/sqlexecute.py", line 132, in run\n    cur.execute(sql)\nsqlite3.OperationalError: near "unique": syntax error\n'
2024-05-14 14:17:41,712 (56597/MainThread) litecli.main ERROR - sql: 'SELECT id, title, year\nFROM films\nWHERE title IN (\n    SELECT title\n    FROM films\n    GROUP BY title\n    ORDER BY title\n    HAVING COUNT(*) > 1\n);', error: OperationalError('near "HAVING": syntax error')
2024-05-14 14:17:41,712 (56597/MainThread) litecli.main ERROR - traceback: 'Traceback (most recent call last):\n  File "/opt/homebrew/Cellar/litecli/1.11.0/libexec/lib/python3.12/site-packages/litecli/sqlexecute.py", line 125, in run\n    for result in special.execute(cur, sql):\n                  ^^^^^^^^^^^^^^^^^^^^^^^^^\n  File "/opt/homebrew/Cellar/litecli/1.11.0/libexec/lib/python3.12/site-packages/litecli/packages/special/main.py", line 109, in execute\n    raise CommandNotFound\nlitecli.packages.special.main.CommandNotFound\n\nDuring handling of the above exception, another exception occurred:\n\nTraceback (most recent call last):\n  File "/opt/homebrew/Cellar/litecli/1.11.0/libexec/lib/python3.12/site-packages/litecli/main.py", line 453, in one_iteration\n    for title, cur, headers, status in res:\n  File "/opt/homebrew/Cellar/litecli/1.11.0/libexec/lib/python3.12/site-packages/litecli/sqlexecute.py", line 132, in run\n    cur.execute(sql)\nsqlite3.OperationalError: near "HAVING": syntax error\n'
2024-05-14 14:17:43,284 (56597/MainThread) litecli.main ERROR - sql: 'SELECT id, title, year\nFROM films\nWHERE title IN (\n    SELECT title\n    FROM films\n    GROUP BY title\n    ORDER BY title\n    HAVING COUNT(*) > 1\n);', error: OperationalError('near "HAVING": syntax error')
2024-05-14 14:17:43,285 (56597/MainThread) litecli.main ERROR - traceback: 'Traceback (most recent call last):\n  File "/opt/homebrew/Cellar/litecli/1.11.0/libexec/lib/python3.12/site-packages/litecli/sqlexecute.py", line 125, in run\n    for result in special.execute(cur, sql):\n                  ^^^^^^^^^^^^^^^^^^^^^^^^^\n  File "/opt/homebrew/Cellar/litecli/1.11.0/libexec/lib/python3.12/site-packages/litecli/packages/special/main.py", line 109, in execute\n    raise CommandNotFound\nlitecli.packages.special.main.CommandNotFound\n\nDuring handling of the above exception, another exception occurred:\n\nTraceback (most recent call last):\n  File "/opt/homebrew/Cellar/litecli/1.11.0/libexec/lib/python3.12/site-packages/litecli/main.py", line 453, in one_iteration\n    for title, cur, headers, status in res:\n  File "/opt/homebrew/Cellar/litecli/1.11.0/libexec/lib/python3.12/site-packages/litecli/sqlexecute.py", line 132, in run\n    cur.execute(sql)\nsqlite3.OperationalError: near "HAVING": syntax error\n'
2024-05-14 14:29:49,856 (56597/MainThread) litecli.main ERROR - sql: 'DELETE FROM films\nWHERE id IN (5686, 5711, 5714, 1002, 5641, 5634, 5788, 5731,\n5710,\n5826,\n5809,\n34,\n5784,\n1048,\n1054,\n1064,\n5685,\n5779,\n1038,\n5820,\n5680,\n5695,\n5805,\n5706,\n5681,\n5662,\n5647,\n5688,\n5686,\n5677,\n);', error: OperationalError('near ")": syntax error')
2024-05-14 14:29:49,858 (56597/MainThread) litecli.main ERROR - traceback: 'Traceback (most recent call last):\n  File "/opt/homebrew/Cellar/litecli/1.11.0/libexec/lib/python3.12/site-packages/litecli/sqlexecute.py", line 125, in run\n    for result in special.execute(cur, sql):\n                  ^^^^^^^^^^^^^^^^^^^^^^^^^\n  File "/opt/homebrew/Cellar/litecli/1.11.0/libexec/lib/python3.12/site-packages/litecli/packages/special/main.py", line 109, in execute\n    raise CommandNotFound\nlitecli.packages.special.main.CommandNotFound\n\nDuring handling of the above exception, another exception occurred:\n\nTraceback (most recent call last):\n  File "/opt/homebrew/Cellar/litecli/1.11.0/libexec/lib/python3.12/site-packages/litecli/main.py", line 453, in one_iteration\n    for title, cur, headers, status in res:\n  File "/opt/homebrew/Cellar/litecli/1.11.0/libexec/lib/python3.12/site-packages/litecli/sqlexecute.py", line 132, in run\n    cur.execute(sql)\nsqlite3.OperationalError: near ")": syntax error\n'
2024-05-14 14:29:57,933 (56597/MainThread) litecli.main ERROR - sql: 'q', error: OperationalError('near "q": syntax error')
2024-05-14 14:29:57,935 (56597/MainThread) litecli.main ERROR - traceback: 'Traceback (most recent call last):\n  File "/opt/homebrew/Cellar/litecli/1.11.0/libexec/lib/python3.12/site-packages/litecli/sqlexecute.py", line 125, in run\n    for result in special.execute(cur, sql):\n                  ^^^^^^^^^^^^^^^^^^^^^^^^^\n  File "/opt/homebrew/Cellar/litecli/1.11.0/libexec/lib/python3.12/site-packages/litecli/packages/special/main.py", line 109, in execute\n    raise CommandNotFound\nlitecli.packages.special.main.CommandNotFound\n\nDuring handling of the above exception, another exception occurred:\n\nTraceback (most recent call last):\n  File "/opt/homebrew/Cellar/litecli/1.11.0/libexec/lib/python3.12/site-packages/litecli/main.py", line 453, in one_iteration\n    for title, cur, headers, status in res:\n  File "/opt/homebrew/Cellar/litecli/1.11.0/libexec/lib/python3.12/site-packages/litecli/sqlexecute.py", line 132, in run\n    cur.execute(sql)\nsqlite3.OperationalError: near "q": syntax error\n'
2024-05-14 14:30:41,653 (56597/MainThread) litecli.main ERROR - sql: 'c', error: OperationalError('near "c": syntax error')
2024-05-14 14:30:41,653 (56597/MainThread) litecli.main ERROR - traceback: 'Traceback (most recent call last):\n  File "/opt/homebrew/Cellar/litecli/1.11.0/libexec/lib/python3.12/site-packages/litecli/sqlexecute.py", line 125, in run\n    for result in special.execute(cur, sql):\n                  ^^^^^^^^^^^^^^^^^^^^^^^^^\n  File "/opt/homebrew/Cellar/litecli/1.11.0/libexec/lib/python3.12/site-packages/litecli/packages/special/main.py", line 109, in execute\n    raise CommandNotFound\nlitecli.packages.special.main.CommandNotFound\n\nDuring handling of the above exception, another exception occurred:\n\nTraceback (most recent call last):\n  File "/opt/homebrew/Cellar/litecli/1.11.0/libexec/lib/python3.12/site-packages/litecli/main.py", line 453, in one_iteration\n    for title, cur, headers, status in res:\n  File "/opt/homebrew/Cellar/litecli/1.11.0/libexec/lib/python3.12/site-packages/litecli/sqlexecute.py", line 132, in run\n    cur.execute(sql)\nsqlite3.OperationalError: near "c": syntax error\n'
2024-05-14 14:34:21,436 (56597/MainThread) litecli.main ERROR - sql: 'select id, year, title, worldwide_gross  from films where id > 4000 limit 250q', error: OperationalError('unrecognized token: "250q"')
2024-05-14 14:34:21,436 (56597/MainThread) litecli.main ERROR - traceback: 'Traceback (most recent call last):\n  File "/opt/homebrew/Cellar/litecli/1.11.0/libexec/lib/python3.12/site-packages/litecli/sqlexecute.py", line 125, in run\n    for result in special.execute(cur, sql):\n                  ^^^^^^^^^^^^^^^^^^^^^^^^^\n  File "/opt/homebrew/Cellar/litecli/1.11.0/libexec/lib/python3.12/site-packages/litecli/packages/special/main.py", line 109, in execute\n    raise CommandNotFound\nlitecli.packages.special.main.CommandNotFound\n\nDuring handling of the above exception, another exception occurred:\n\nTraceback (most recent call last):\n  File "/opt/homebrew/Cellar/litecli/1.11.0/libexec/lib/python3.12/site-packages/litecli/main.py", line 453, in one_iteration\n    for title, cur, headers, status in res:\n  File "/opt/homebrew/Cellar/litecli/1.11.0/libexec/lib/python3.12/site-packages/litecli/sqlexecute.py", line 132, in run\n    cur.execute(sql)\nsqlite3.OperationalError: unrecognized token: "250q"\n'
2024-05-14 14:36:42,045 (56597/MainThread) litecli.main ERROR - sql: 'select id, year, title, count(*) from films order by worldwide_gross desc where worldwide_gross is not null;', error: OperationalError('near "where": syntax error')
2024-05-14 14:36:42,046 (56597/MainThread) litecli.main ERROR - traceback: 'Traceback (most recent call last):\n  File "/opt/homebrew/Cellar/litecli/1.11.0/libexec/lib/python3.12/site-packages/litecli/sqlexecute.py", line 125, in run\n    for result in special.execute(cur, sql):\n                  ^^^^^^^^^^^^^^^^^^^^^^^^^\n  File "/opt/homebrew/Cellar/litecli/1.11.0/libexec/lib/python3.12/site-packages/litecli/packages/special/main.py", line 109, in execute\n    raise CommandNotFound\nlitecli.packages.special.main.CommandNotFound\n\nDuring handling of the above exception, another exception occurred:\n\nTraceback (most recent call last):\n  File "/opt/homebrew/Cellar/litecli/1.11.0/libexec/lib/python3.12/site-packages/litecli/main.py", line 453, in one_iteration\n    for title, cur, headers, status in res:\n  File "/opt/homebrew/Cellar/litecli/1.11.0/libexec/lib/python3.12/site-packages/litecli/sqlexecute.py", line 132, in run\n    cur.execute(sql)\nsqlite3.OperationalError: near "where": syntax error\n'
2024-05-14 14:37:14,522 (56597/MainThread) litecli.main ERROR - sql: 'q', error: OperationalError('near "q": syntax error')
2024-05-14 14:37:14,523 (56597/MainThread) litecli.main ERROR - traceback: 'Traceback (most recent call last):\n  File "/opt/homebrew/Cellar/litecli/1.11.0/libexec/lib/python3.12/site-packages/litecli/sqlexecute.py", line 125, in run\n    for result in special.execute(cur, sql):\n                  ^^^^^^^^^^^^^^^^^^^^^^^^^\n  File "/opt/homebrew/Cellar/litecli/1.11.0/libexec/lib/python3.12/site-packages/litecli/packages/special/main.py", line 109, in execute\n    raise CommandNotFound\nlitecli.packages.special.main.CommandNotFound\n\nDuring handling of the above exception, another exception occurred:\n\nTraceback (most recent call last):\n  File "/opt/homebrew/Cellar/litecli/1.11.0/libexec/lib/python3.12/site-packages/litecli/main.py", line 453, in one_iteration\n    for title, cur, headers, status in res:\n  File "/opt/homebrew/Cellar/litecli/1.11.0/libexec/lib/python3.12/site-packages/litecli/sqlexecute.py", line 132, in run\n    cur.execute(sql)\nsqlite3.OperationalError: near "q": syntax error\n'
2024-05-14 15:08:03,326 (56597/MainThread) litecli.main ERROR - sql: 'SELECT count(*), oscars_won FROM films GROUP BY oscars_won WHERE oscars_won >= 1;', error: OperationalError('near "WHERE": syntax error')
2024-05-14 15:08:03,327 (56597/MainThread) litecli.main ERROR - traceback: 'Traceback (most recent call last):\n  File "/opt/homebrew/Cellar/litecli/1.11.0/libexec/lib/python3.12/site-packages/litecli/sqlexecute.py", line 125, in run\n    for result in special.execute(cur, sql):\n                  ^^^^^^^^^^^^^^^^^^^^^^^^^\n  File "/opt/homebrew/Cellar/litecli/1.11.0/libexec/lib/python3.12/site-packages/litecli/packages/special/main.py", line 109, in execute\n    raise CommandNotFound\nlitecli.packages.special.main.CommandNotFound\n\nDuring handling of the above exception, another exception occurred:\n\nTraceback (most recent call last):\n  File "/opt/homebrew/Cellar/litecli/1.11.0/libexec/lib/python3.12/site-packages/litecli/main.py", line 453, in one_iteration\n    for title, cur, headers, status in res:\n  File "/opt/homebrew/Cellar/litecli/1.11.0/libexec/lib/python3.12/site-packages/litecli/sqlexecute.py", line 132, in run\n    cur.execute(sql)\nsqlite3.OperationalError: near "WHERE": syntax error\n'
2024-05-14 15:15:41,481 (56597/MainThread) litecli.main ERROR - sql: 'SELECT id, employees.name, department.name\nFROM employees\nJOIN departments\nON employees.department_id = departments.id', error: OperationalError('ambiguous column name: id')
2024-05-14 15:15:41,482 (56597/MainThread) litecli.main ERROR - traceback: 'Traceback (most recent call last):\n  File "/opt/homebrew/Cellar/litecli/1.11.0/libexec/lib/python3.12/site-packages/litecli/sqlexecute.py", line 125, in run\n    for result in special.execute(cur, sql):\n                  ^^^^^^^^^^^^^^^^^^^^^^^^^\n  File "/opt/homebrew/Cellar/litecli/1.11.0/libexec/lib/python3.12/site-packages/litecli/packages/special/main.py", line 109, in execute\n    raise CommandNotFound\nlitecli.packages.special.main.CommandNotFound\n\nDuring handling of the above exception, another exception occurred:\n\nTraceback (most recent call last):\n  File "/opt/homebrew/Cellar/litecli/1.11.0/libexec/lib/python3.12/site-packages/litecli/main.py", line 453, in one_iteration\n    for title, cur, headers, status in res:\n  File "/opt/homebrew/Cellar/litecli/1.11.0/libexec/lib/python3.12/site-packages/litecli/sqlexecute.py", line 132, in run\n    cur.execute(sql)\nsqlite3.OperationalError: ambiguous column name: id\n'
2024-05-14 15:15:49,423 (56597/MainThread) litecli.main ERROR - sql: 'SELECT employees.id, employees.name, department.name\nFROM employees\nJOIN departments\nON employees.department_id = departments.id', error: OperationalError('no such column: department.name')
2024-05-14 15:15:49,423 (56597/MainThread) litecli.main ERROR - traceback: 'Traceback (most recent call last):\n  File "/opt/homebrew/Cellar/litecli/1.11.0/libexec/lib/python3.12/site-packages/litecli/sqlexecute.py", line 125, in run\n    for result in special.execute(cur, sql):\n                  ^^^^^^^^^^^^^^^^^^^^^^^^^\n  File "/opt/homebrew/Cellar/litecli/1.11.0/libexec/lib/python3.12/site-packages/litecli/packages/special/main.py", line 109, in execute\n    raise CommandNotFound\nlitecli.packages.special.main.CommandNotFound\n\nDuring handling of the above exception, another exception occurred:\n\nTraceback (most recent call last):\n  File "/opt/homebrew/Cellar/litecli/1.11.0/libexec/lib/python3.12/site-packages/litecli/main.py", line 453, in one_iteration\n    for title, cur, headers, status in res:\n  File "/opt/homebrew/Cellar/litecli/1.11.0/libexec/lib/python3.12/site-packages/litecli/sqlexecute.py", line 132, in run\n    cur.execute(sql)\nsqlite3.OperationalError: no such column: department.name\n'
2024-05-14 15:31:34,151 (15473/MainThread) litecli.main ERROR - sql: 'SELECT employees.id as employee_id, employees.name employee_name, departments.name department_name\nFROM employees\nOUTER JOIN departments\nON employees.department_id = departments.id', error: OperationalError('unknown join type: OUTER')
2024-05-14 15:31:34,155 (15473/MainThread) litecli.main ERROR - traceback: 'Traceback (most recent call last):\n  File "/opt/homebrew/Cellar/litecli/1.11.0/libexec/lib/python3.12/site-packages/litecli/sqlexecute.py", line 125, in run\n    for result in special.execute(cur, sql):\n                  ^^^^^^^^^^^^^^^^^^^^^^^^^\n  File "/opt/homebrew/Cellar/litecli/1.11.0/libexec/lib/python3.12/site-packages/litecli/packages/special/main.py", line 109, in execute\n    raise CommandNotFound\nlitecli.packages.special.main.CommandNotFound\n\nDuring handling of the above exception, another exception occurred:\n\nTraceback (most recent call last):\n  File "/opt/homebrew/Cellar/litecli/1.11.0/libexec/lib/python3.12/site-packages/litecli/main.py", line 453, in one_iteration\n    for title, cur, headers, status in res:\n  File "/opt/homebrew/Cellar/litecli/1.11.0/libexec/lib/python3.12/site-packages/litecli/sqlexecute.py", line 132, in run\n    cur.execute(sql)\nsqlite3.OperationalError: unknown join type: OUTER\n'
2024-05-14 15:31:41,609 (15473/MainThread) litecli.main ERROR - sql: 'SELECT employees.id as employee_id, employees.name employee_name, departments.name department_name\nFROM employees\nOUT JOIN departments\nON employees.department_id = departments.id', error: OperationalError('no such column: employees.id')
2024-05-14 15:31:41,610 (15473/MainThread) litecli.main ERROR - traceback: 'Traceback (most recent call last):\n  File "/opt/homebrew/Cellar/litecli/1.11.0/libexec/lib/python3.12/site-packages/litecli/sqlexecute.py", line 125, in run\n    for result in special.execute(cur, sql):\n                  ^^^^^^^^^^^^^^^^^^^^^^^^^\n  File "/opt/homebrew/Cellar/litecli/1.11.0/libexec/lib/python3.12/site-packages/litecli/packages/special/main.py", line 109, in execute\n    raise CommandNotFound\nlitecli.packages.special.main.CommandNotFound\n\nDuring handling of the above exception, another exception occurred:\n\nTraceback (most recent call last):\n  File "/opt/homebrew/Cellar/litecli/1.11.0/libexec/lib/python3.12/site-packages/litecli/main.py", line 453, in one_iteration\n    for title, cur, headers, status in res:\n  File "/opt/homebrew/Cellar/litecli/1.11.0/libexec/lib/python3.12/site-packages/litecli/sqlexecute.py", line 132, in run\n    cur.execute(sql)\nsqlite3.OperationalError: no such column: employees.id\n'
2024-05-14 15:37:33,212 (15473/MainThread) litecli.main ERROR - sql: 'SELECT worldwide_gross, \n       title, \n       GROUP_CONCAT(directors.NAME) AS directors\n       studios.NAME AS studio_name \nFROM   directors \n       JOIN film_directors \n         ON directors.id = film_directors.director_id \n       JOIN films \n         ON films.id = film_directors.film_id \n       JOIN studios \n         ON studios.id = films.studio_id ', error: OperationalError('near "studios": syntax error')
2024-05-14 15:37:33,213 (15473/MainThread) litecli.main ERROR - traceback: 'Traceback (most recent call last):\n  File "/opt/homebrew/Cellar/litecli/1.11.0/libexec/lib/python3.12/site-packages/litecli/sqlexecute.py", line 125, in run\n    for result in special.execute(cur, sql):\n                  ^^^^^^^^^^^^^^^^^^^^^^^^^\n  File "/opt/homebrew/Cellar/litecli/1.11.0/libexec/lib/python3.12/site-packages/litecli/packages/special/main.py", line 109, in execute\n    raise CommandNotFound\nlitecli.packages.special.main.CommandNotFound\n\nDuring handling of the above exception, another exception occurred:\n\nTraceback (most recent call last):\n  File "/opt/homebrew/Cellar/litecli/1.11.0/libexec/lib/python3.12/site-packages/litecli/main.py", line 453, in one_iteration\n    for title, cur, headers, status in res:\n  File "/opt/homebrew/Cellar/litecli/1.11.0/libexec/lib/python3.12/site-packages/litecli/sqlexecute.py", line 132, in run\n    cur.execute(sql)\nsqlite3.OperationalError: near "studios": syntax error\n'
2024-05-14 15:51:18,630 (78486/MainThread) litecli.main ERROR - sql: 'DELETE FROM film_directors\nWHERE film_directors_id NOT IN (\n    SELECT MAX(fd.film_directors_id)\n    FROM film_directors AS fd\n    GROUP BY fd.film_id, fd.director_id\n);\n', error: OperationalError('no such column: fd.film_directors_id')
2024-05-14 15:51:18,633 (78486/MainThread) litecli.main ERROR - traceback: 'Traceback (most recent call last):\n  File "/opt/homebrew/Cellar/litecli/1.11.0/libexec/lib/python3.12/site-packages/litecli/sqlexecute.py", line 125, in run\n    for result in special.execute(cur, sql):\n                  ^^^^^^^^^^^^^^^^^^^^^^^^^\n  File "/opt/homebrew/Cellar/litecli/1.11.0/libexec/lib/python3.12/site-packages/litecli/packages/special/main.py", line 109, in execute\n    raise CommandNotFound\nlitecli.packages.special.main.CommandNotFound\n\nDuring handling of the above exception, another exception occurred:\n\nTraceback (most recent call last):\n  File "/opt/homebrew/Cellar/litecli/1.11.0/libexec/lib/python3.12/site-packages/litecli/main.py", line 453, in one_iteration\n    for title, cur, headers, status in res:\n  File "/opt/homebrew/Cellar/litecli/1.11.0/libexec/lib/python3.12/site-packages/litecli/sqlexecute.py", line 132, in run\n    cur.execute(sql)\nsqlite3.OperationalError: no such column: fd.film_directors_id\n'
2024-05-14 15:55:58,051 (78486/MainThread) litecli.main ERROR - sql: 'UPDATE directors\nSET name = \n    -- Uppercase the first letter of each word\n    INITCAP(name);\n', error: OperationalError('no such function: INITCAP')
2024-05-14 15:55:58,052 (78486/MainThread) litecli.main ERROR - traceback: 'Traceback (most recent call last):\n  File "/opt/homebrew/Cellar/litecli/1.11.0/libexec/lib/python3.12/site-packages/litecli/sqlexecute.py", line 125, in run\n    for result in special.execute(cur, sql):\n                  ^^^^^^^^^^^^^^^^^^^^^^^^^\n  File "/opt/homebrew/Cellar/litecli/1.11.0/libexec/lib/python3.12/site-packages/litecli/packages/special/main.py", line 109, in execute\n    raise CommandNotFound\nlitecli.packages.special.main.CommandNotFound\n\nDuring handling of the above exception, another exception occurred:\n\nTraceback (most recent call last):\n  File "/opt/homebrew/Cellar/litecli/1.11.0/libexec/lib/python3.12/site-packages/litecli/main.py", line 453, in one_iteration\n    for title, cur, headers, status in res:\n  File "/opt/homebrew/Cellar/litecli/1.11.0/libexec/lib/python3.12/site-packages/litecli/sqlexecute.py", line 132, in run\n    cur.execute(sql)\nsqlite3.OperationalError: no such function: INITCAP\n'
2024-05-14 15:58:57,175 (78486/MainThread) litecli.main ERROR - sql: 'DELETE FROM film_directors AS fd1\nWHERE EXISTS (\n    SELECT 1\n    FROM film_directors AS fd2\n    WHERE fd1.film_id = fd2.film_id\n    AND fd1.director_id = fd2.director_id\n    AND fd1.film_directors_id > fd2.film_directors_id -- Keep only the record with the lowest film_directors_id\n);\n', error: OperationalError('no such column: fd1.film_directors_id')
2024-05-14 15:58:57,177 (78486/MainThread) litecli.main ERROR - traceback: 'Traceback (most recent call last):\n  File "/opt/homebrew/Cellar/litecli/1.11.0/libexec/lib/python3.12/site-packages/litecli/sqlexecute.py", line 125, in run\n    for result in special.execute(cur, sql):\n                  ^^^^^^^^^^^^^^^^^^^^^^^^^\n  File "/opt/homebrew/Cellar/litecli/1.11.0/libexec/lib/python3.12/site-packages/litecli/packages/special/main.py", line 109, in execute\n    raise CommandNotFound\nlitecli.packages.special.main.CommandNotFound\n\nDuring handling of the above exception, another exception occurred:\n\nTraceback (most recent call last):\n  File "/opt/homebrew/Cellar/litecli/1.11.0/libexec/lib/python3.12/site-packages/litecli/main.py", line 453, in one_iteration\n    for title, cur, headers, status in res:\n  File "/opt/homebrew/Cellar/litecli/1.11.0/libexec/lib/python3.12/site-packages/litecli/sqlexecute.py", line 132, in run\n    cur.execute(sql)\nsqlite3.OperationalError: no such column: fd1.film_directors_id\n'
2024-05-14 16:01:37,324 (78486/MainThread) litecli.main ERROR - sql: 'select directors.name from directors join film_directors = film_directors.director_id = directors.id', error: OperationalError('near "=": syntax error')
2024-05-14 16:01:37,325 (78486/MainThread) litecli.main ERROR - traceback: 'Traceback (most recent call last):\n  File "/opt/homebrew/Cellar/litecli/1.11.0/libexec/lib/python3.12/site-packages/litecli/sqlexecute.py", line 125, in run\n    for result in special.execute(cur, sql):\n                  ^^^^^^^^^^^^^^^^^^^^^^^^^\n  File "/opt/homebrew/Cellar/litecli/1.11.0/libexec/lib/python3.12/site-packages/litecli/packages/special/main.py", line 109, in execute\n    raise CommandNotFound\nlitecli.packages.special.main.CommandNotFound\n\nDuring handling of the above exception, another exception occurred:\n\nTraceback (most recent call last):\n  File "/opt/homebrew/Cellar/litecli/1.11.0/libexec/lib/python3.12/site-packages/litecli/main.py", line 453, in one_iteration\n    for title, cur, headers, status in res:\n  File "/opt/homebrew/Cellar/litecli/1.11.0/libexec/lib/python3.12/site-packages/litecli/sqlexecute.py", line 132, in run\n    cur.execute(sql)\nsqlite3.OperationalError: near "=": syntax error\n'
2024-05-14 16:04:07,775 (78486/MainThread) litecli.main ERROR - sql: 'select films.id, title, directors.name, from directors join film_directors on film_directors.director_id = directors.id join films on films.id = film_directors.film_id', error: OperationalError('near "from": syntax error')
2024-05-14 16:04:07,776 (78486/MainThread) litecli.main ERROR - traceback: 'Traceback (most recent call last):\n  File "/opt/homebrew/Cellar/litecli/1.11.0/libexec/lib/python3.12/site-packages/litecli/sqlexecute.py", line 125, in run\n    for result in special.execute(cur, sql):\n                  ^^^^^^^^^^^^^^^^^^^^^^^^^\n  File "/opt/homebrew/Cellar/litecli/1.11.0/libexec/lib/python3.12/site-packages/litecli/packages/special/main.py", line 109, in execute\n    raise CommandNotFound\nlitecli.packages.special.main.CommandNotFound\n\nDuring handling of the above exception, another exception occurred:\n\nTraceback (most recent call last):\n  File "/opt/homebrew/Cellar/litecli/1.11.0/libexec/lib/python3.12/site-packages/litecli/main.py", line 453, in one_iteration\n    for title, cur, headers, status in res:\n  File "/opt/homebrew/Cellar/litecli/1.11.0/libexec/lib/python3.12/site-packages/litecli/sqlexecute.py", line 132, in run\n    cur.execute(sql)\nsqlite3.OperationalError: near "from": syntax error\n'
2024-05-14 16:16:26,879 (78486/MainThread) litecli.main ERROR - sql: 'SELECT age FROM employees WHERE department_id = 1;\nUNION\nSELECT age FROM employees WHERE department_id = 2;', error: OperationalError('near "UNION": syntax error')
2024-05-14 16:16:26,880 (78486/MainThread) litecli.main ERROR - traceback: 'Traceback (most recent call last):\n  File "/opt/homebrew/Cellar/litecli/1.11.0/libexec/lib/python3.12/site-packages/litecli/sqlexecute.py", line 125, in run\n    for result in special.execute(cur, sql):\n                  ^^^^^^^^^^^^^^^^^^^^^^^^^\n  File "/opt/homebrew/Cellar/litecli/1.11.0/libexec/lib/python3.12/site-packages/litecli/packages/special/main.py", line 109, in execute\n    raise CommandNotFound\nlitecli.packages.special.main.CommandNotFound\n\nDuring handling of the above exception, another exception occurred:\n\nTraceback (most recent call last):\n  File "/opt/homebrew/Cellar/litecli/1.11.0/libexec/lib/python3.12/site-packages/litecli/main.py", line 453, in one_iteration\n    for title, cur, headers, status in res:\n  File "/opt/homebrew/Cellar/litecli/1.11.0/libexec/lib/python3.12/site-packages/litecli/sqlexecute.py", line 132, in run\n    cur.execute(sql)\nsqlite3.OperationalError: near "UNION": syntax error\n'
2024-05-14 16:16:48,526 (78486/MainThread) litecli.main ERROR - sql: 'SELECT age FROM employees WHERE department_id = 1;\nUNION\nSELECT age FROM employees WHERE department_id = 2;', error: OperationalError('near "UNION": syntax error')
2024-05-14 16:16:48,527 (78486/MainThread) litecli.main ERROR - traceback: 'Traceback (most recent call last):\n  File "/opt/homebrew/Cellar/litecli/1.11.0/libexec/lib/python3.12/site-packages/litecli/sqlexecute.py", line 125, in run\n    for result in special.execute(cur, sql):\n                  ^^^^^^^^^^^^^^^^^^^^^^^^^\n  File "/opt/homebrew/Cellar/litecli/1.11.0/libexec/lib/python3.12/site-packages/litecli/packages/special/main.py", line 109, in execute\n    raise CommandNotFound\nlitecli.packages.special.main.CommandNotFound\n\nDuring handling of the above exception, another exception occurred:\n\nTraceback (most recent call last):\n  File "/opt/homebrew/Cellar/litecli/1.11.0/libexec/lib/python3.12/site-packages/litecli/main.py", line 453, in one_iteration\n    for title, cur, headers, status in res:\n  File "/opt/homebrew/Cellar/litecli/1.11.0/libexec/lib/python3.12/site-packages/litecli/sqlexecute.py", line 132, in run\n    cur.execute(sql)\nsqlite3.OperationalError: near "UNION": syntax error\n'
2024-05-14 16:17:00,405 (78486/MainThread) litecli.main ERROR - sql: 'SELECT name, age FROM employees WHERE department_id = 1;\nUNION\nSELECT name, age FROM employees WHERE department_id = 2;', error: OperationalError('near "UNION": syntax error')
2024-05-14 16:17:00,406 (78486/MainThread) litecli.main ERROR - traceback: 'Traceback (most recent call last):\n  File "/opt/homebrew/Cellar/litecli/1.11.0/libexec/lib/python3.12/site-packages/litecli/sqlexecute.py", line 125, in run\n    for result in special.execute(cur, sql):\n                  ^^^^^^^^^^^^^^^^^^^^^^^^^\n  File "/opt/homebrew/Cellar/litecli/1.11.0/libexec/lib/python3.12/site-packages/litecli/packages/special/main.py", line 109, in execute\n    raise CommandNotFound\nlitecli.packages.special.main.CommandNotFound\n\nDuring handling of the above exception, another exception occurred:\n\nTraceback (most recent call last):\n  File "/opt/homebrew/Cellar/litecli/1.11.0/libexec/lib/python3.12/site-packages/litecli/main.py", line 453, in one_iteration\n    for title, cur, headers, status in res:\n  File "/opt/homebrew/Cellar/litecli/1.11.0/libexec/lib/python3.12/site-packages/litecli/sqlexecute.py", line 132, in run\n    cur.execute(sql)\nsqlite3.OperationalError: near "UNION": syntax error\n'
2024-05-14 16:17:37,911 (78486/MainThread) litecli.main ERROR - sql: 'SELECT name, age FROM employees WHERE department_id = 1;\nUNION ALL\nSELECT name, age FROM employees WHERE department_id = 2;', error: OperationalError('near "UNION": syntax error')
2024-05-14 16:17:37,911 (78486/MainThread) litecli.main ERROR - traceback: 'Traceback (most recent call last):\n  File "/opt/homebrew/Cellar/litecli/1.11.0/libexec/lib/python3.12/site-packages/litecli/sqlexecute.py", line 125, in run\n    for result in special.execute(cur, sql):\n                  ^^^^^^^^^^^^^^^^^^^^^^^^^\n  File "/opt/homebrew/Cellar/litecli/1.11.0/libexec/lib/python3.12/site-packages/litecli/packages/special/main.py", line 109, in execute\n    raise CommandNotFound\nlitecli.packages.special.main.CommandNotFound\n\nDuring handling of the above exception, another exception occurred:\n\nTraceback (most recent call last):\n  File "/opt/homebrew/Cellar/litecli/1.11.0/libexec/lib/python3.12/site-packages/litecli/main.py", line 453, in one_iteration\n    for title, cur, headers, status in res:\n  File "/opt/homebrew/Cellar/litecli/1.11.0/libexec/lib/python3.12/site-packages/litecli/sqlexecute.py", line 132, in run\n    cur.execute(sql)\nsqlite3.OperationalError: near "UNION": syntax error\n'
2024-05-14 16:19:59,087 (78486/MainThread) litecli.main ERROR - sql: 'ALTER TABLE employees\nADD CONSTRAINT fk_department\nFOREIGN KEY (department_id)\nREFERENCES departments(id);', error: OperationalError('near "CONSTRAINT": syntax error')
2024-05-14 16:19:59,088 (78486/MainThread) litecli.main ERROR - traceback: 'Traceback (most recent call last):\n  File "/opt/homebrew/Cellar/litecli/1.11.0/libexec/lib/python3.12/site-packages/litecli/sqlexecute.py", line 125, in run\n    for result in special.execute(cur, sql):\n                  ^^^^^^^^^^^^^^^^^^^^^^^^^\n  File "/opt/homebrew/Cellar/litecli/1.11.0/libexec/lib/python3.12/site-packages/litecli/packages/special/main.py", line 109, in execute\n    raise CommandNotFound\nlitecli.packages.special.main.CommandNotFound\n\nDuring handling of the above exception, another exception occurred:\n\nTraceback (most recent call last):\n  File "/opt/homebrew/Cellar/litecli/1.11.0/libexec/lib/python3.12/site-packages/litecli/main.py", line 453, in one_iteration\n    for title, cur, headers, status in res:\n  File "/opt/homebrew/Cellar/litecli/1.11.0/libexec/lib/python3.12/site-packages/litecli/sqlexecute.py", line 132, in run\n    cur.execute(sql)\nsqlite3.OperationalError: near "CONSTRAINT": syntax error\n'
2024-05-14 16:21:02,323 (78486/MainThread) litecli.main ERROR - sql: 'c', error: OperationalError('near "c": syntax error')
2024-05-14 16:21:02,324 (78486/MainThread) litecli.main ERROR - traceback: 'Traceback (most recent call last):\n  File "/opt/homebrew/Cellar/litecli/1.11.0/libexec/lib/python3.12/site-packages/litecli/sqlexecute.py", line 125, in run\n    for result in special.execute(cur, sql):\n                  ^^^^^^^^^^^^^^^^^^^^^^^^^\n  File "/opt/homebrew/Cellar/litecli/1.11.0/libexec/lib/python3.12/site-packages/litecli/packages/special/main.py", line 109, in execute\n    raise CommandNotFound\nlitecli.packages.special.main.CommandNotFound\n\nDuring handling of the above exception, another exception occurred:\n\nTraceback (most recent call last):\n  File "/opt/homebrew/Cellar/litecli/1.11.0/libexec/lib/python3.12/site-packages/litecli/main.py", line 453, in one_iteration\n    for title, cur, headers, status in res:\n  File "/opt/homebrew/Cellar/litecli/1.11.0/libexec/lib/python3.12/site-packages/litecli/sqlexecute.py", line 132, in run\n    cur.execute(sql)\nsqlite3.OperationalError: near "c": syntax error\n'
2024-05-14 16:22:14,328 (78486/MainThread) litecli.main ERROR - sql: 'ALTER TABLE employees\nADD CONSTRAINT fk_department\nFOREIGN KEY (department_id) REFERENCES departments(id);', error: OperationalError('near "CONSTRAINT": syntax error')
2024-05-14 16:22:14,330 (78486/MainThread) litecli.main ERROR - traceback: 'Traceback (most recent call last):\n  File "/opt/homebrew/Cellar/litecli/1.11.0/libexec/lib/python3.12/site-packages/litecli/sqlexecute.py", line 125, in run\n    for result in special.execute(cur, sql):\n                  ^^^^^^^^^^^^^^^^^^^^^^^^^\n  File "/opt/homebrew/Cellar/litecli/1.11.0/libexec/lib/python3.12/site-packages/litecli/packages/special/main.py", line 109, in execute\n    raise CommandNotFound\nlitecli.packages.special.main.CommandNotFound\n\nDuring handling of the above exception, another exception occurred:\n\nTraceback (most recent call last):\n  File "/opt/homebrew/Cellar/litecli/1.11.0/libexec/lib/python3.12/site-packages/litecli/main.py", line 453, in one_iteration\n    for title, cur, headers, status in res:\n  File "/opt/homebrew/Cellar/litecli/1.11.0/libexec/lib/python3.12/site-packages/litecli/sqlexecute.py", line 132, in run\n    cur.execute(sql)\nsqlite3.OperationalError: near "CONSTRAINT": syntax error\n'
2024-05-14 18:49:42,557 (2373/MainThread) litecli.main ERROR - sql: "UPDATE directors\nSET name = CONCAT(\n               UPPER(SUBSTRING(name, 1, 1)), -- Capitalize first letter of first name\n               LOWER(SUBSTRING(name, 2, CHARINDEX(' ', name) - 1)), -- Lowercase rest of first name\n               ' ', -- Add space\n               UPPER(SUBSTRING(name, CHARINDEX(' ', name) + 1, 1)), -- Capitalize first letter of middle name\n               LOWER(SUBSTRING(name, CHARINDEX(' ', name) + 2, CHARINDEX(' ', name, CHARINDEX(' ', name) + 1) - CHARINDEX(' ', name) - 1)), -- Lowercase rest of middle name\n               ' ', -- Add space\n               UPPER(SUBSTRING(name, CHARINDEX(' ', name, CHARINDEX(' ', name) + 1) + 1, 1)), -- Capitalize first letter of last name\n               LOWER(SUBSTRING(name, CHARINDEX(' ', name, CHARINDEX(' ', name) + 1) + 2, LEN(name) - CHARINDEX(' ', name, CHARINDEX(' ', name) + 1))) -- Lowercase rest of last name\n           )\n", error: OperationalError('no such function: CHARINDEX')
2024-05-14 18:49:42,559 (2373/MainThread) litecli.main ERROR - traceback: 'Traceback (most recent call last):\n  File "/opt/homebrew/Cellar/litecli/1.11.0/libexec/lib/python3.12/site-packages/litecli/sqlexecute.py", line 125, in run\n    for result in special.execute(cur, sql):\n                  ^^^^^^^^^^^^^^^^^^^^^^^^^\n  File "/opt/homebrew/Cellar/litecli/1.11.0/libexec/lib/python3.12/site-packages/litecli/packages/special/main.py", line 109, in execute\n    raise CommandNotFound\nlitecli.packages.special.main.CommandNotFound\n\nDuring handling of the above exception, another exception occurred:\n\nTraceback (most recent call last):\n  File "/opt/homebrew/Cellar/litecli/1.11.0/libexec/lib/python3.12/site-packages/litecli/main.py", line 453, in one_iteration\n    for title, cur, headers, status in res:\n  File "/opt/homebrew/Cellar/litecli/1.11.0/libexec/lib/python3.12/site-packages/litecli/sqlexecute.py", line 132, in run\n    cur.execute(sql)\nsqlite3.OperationalError: no such function: CHARINDEX\n'
2024-05-14 18:49:58,907 (2373/MainThread) litecli.main ERROR - sql: "-- Define a custom function to capitalize the first letter of each word\nCREATE FUNCTION capitalizeWords(input TEXT) RETURNS TEXT\nBEGIN\n    RETURN (\n        SELECT REPLACE(UPPER(SUBSTR(input, 1, 1)) || LOWER(SUBSTR(input, 2)), ' ', '')\n    );\nEND;\n", error: OperationalError('near "FUNCTION": syntax error')
2024-05-14 18:49:58,908 (2373/MainThread) litecli.main ERROR - traceback: 'Traceback (most recent call last):\n  File "/opt/homebrew/Cellar/litecli/1.11.0/libexec/lib/python3.12/site-packages/litecli/sqlexecute.py", line 125, in run\n    for result in special.execute(cur, sql):\n                  ^^^^^^^^^^^^^^^^^^^^^^^^^\n  File "/opt/homebrew/Cellar/litecli/1.11.0/libexec/lib/python3.12/site-packages/litecli/packages/special/main.py", line 109, in execute\n    raise CommandNotFound\nlitecli.packages.special.main.CommandNotFound\n\nDuring handling of the above exception, another exception occurred:\n\nTraceback (most recent call last):\n  File "/opt/homebrew/Cellar/litecli/1.11.0/libexec/lib/python3.12/site-packages/litecli/main.py", line 453, in one_iteration\n    for title, cur, headers, status in res:\n  File "/opt/homebrew/Cellar/litecli/1.11.0/libexec/lib/python3.12/site-packages/litecli/sqlexecute.py", line 132, in run\n    cur.execute(sql)\nsqlite3.OperationalError: near "FUNCTION": syntax error\n'
2024-05-14 18:50:13,675 (2373/MainThread) litecli.main ERROR - sql: 'UPDATE directors\nSET name = (\n    SELECT GROUP_CONCAT(UPPER(SUBSTR(word, 1, 1)) || LOWER(SUBSTR(word, 2)), \' \')\n    FROM (\n        SELECT DISTINCT word\n        FROM directors, json_each(\'["\' || REPLACE(name, \' \', \'","\') || \'"]\')\n    )\n);\n', error: OperationalError('no such column: word')
2024-05-14 18:50:13,676 (2373/MainThread) litecli.main ERROR - traceback: 'Traceback (most recent call last):\n  File "/opt/homebrew/Cellar/litecli/1.11.0/libexec/lib/python3.12/site-packages/litecli/sqlexecute.py", line 125, in run\n    for result in special.execute(cur, sql):\n                  ^^^^^^^^^^^^^^^^^^^^^^^^^\n  File "/opt/homebrew/Cellar/litecli/1.11.0/libexec/lib/python3.12/site-packages/litecli/packages/special/main.py", line 109, in execute\n    raise CommandNotFound\nlitecli.packages.special.main.CommandNotFound\n\nDuring handling of the above exception, another exception occurred:\n\nTraceback (most recent call last):\n  File "/opt/homebrew/Cellar/litecli/1.11.0/libexec/lib/python3.12/site-packages/litecli/main.py", line 453, in one_iteration\n    for title, cur, headers, status in res:\n  File "/opt/homebrew/Cellar/litecli/1.11.0/libexec/lib/python3.12/site-packages/litecli/sqlexecute.py", line 132, in run\n    cur.execute(sql)\nsqlite3.OperationalError: no such column: word\n'
2024-05-14 18:50:37,257 (2373/MainThread) litecli.main ERROR - sql: "UPDATE directors\nSET name = (\n    SELECT GROUP_CONCAT(UPPER(SUBSTR(word, 1, 1)) || LOWER(SUBSTR(word, 2)), ' ')\n    FROM (\n        SELECT DISTINCT SUBSTR(name, start, length) AS word\n        FROM (\n            SELECT name,\n                   (SELECT SUM(CASE WHEN SUBSTR(name, x, 1) = ' ' THEN 1 ELSE 0 END) + 1\n                    FROM generate_series(1, LENGTH(name)) AS x\n                    WHERE SUBSTR(name, x, 1) = ' ' OR x = LENGTH(name) + 1) AS word_count,\n                   generate_series(1, LENGTH(name)) AS start,\n                   (SELECT CASE WHEN INSTR(name || ' ', ' ', start) = 0 THEN LENGTH(name) + 1\n                                ELSE INSTR(name || ' ', ' ', start) END - start) AS length\n            FROM directors\n        ) AS words\n    ) AS name\n);\n", error: OperationalError('no such table: generate_series')
2024-05-14 18:50:37,258 (2373/MainThread) litecli.main ERROR - traceback: 'Traceback (most recent call last):\n  File "/opt/homebrew/Cellar/litecli/1.11.0/libexec/lib/python3.12/site-packages/litecli/sqlexecute.py", line 125, in run\n    for result in special.execute(cur, sql):\n                  ^^^^^^^^^^^^^^^^^^^^^^^^^\n  File "/opt/homebrew/Cellar/litecli/1.11.0/libexec/lib/python3.12/site-packages/litecli/packages/special/main.py", line 109, in execute\n    raise CommandNotFound\nlitecli.packages.special.main.CommandNotFound\n\nDuring handling of the above exception, another exception occurred:\n\nTraceback (most recent call last):\n  File "/opt/homebrew/Cellar/litecli/1.11.0/libexec/lib/python3.12/site-packages/litecli/main.py", line 453, in one_iteration\n    for title, cur, headers, status in res:\n  File "/opt/homebrew/Cellar/litecli/1.11.0/libexec/lib/python3.12/site-packages/litecli/sqlexecute.py", line 132, in run\n    cur.execute(sql)\nsqlite3.OperationalError: no such table: generate_series\n'
2024-05-14 18:52:06,845 (2373/MainThread) litecli.main ERROR - sql: "UPDATE directors\nSET name = (\n    SELECT GROUP_CONCAT(UPPER(SUBSTR(word, 1, 1)) || LOWER(SUBSTR(word, 2)), ' ')\n    FROM (\n        SELECT DISTINCT SUBSTR(t.name, m.start + 1, m.length) AS word\n        FROM directors AS t\n        JOIN (\n            SELECT ROWID,\n                   LENGTH(name) - LENGTH(REPLACE(name, ' ', '')) + 1 AS word_count\n            FROM directors\n        ) AS wc ON t.ROWID = wc.ROWID\n        JOIN (\n            SELECT ROWID,\n                   LENGTH(SUBSTR(name, 0, INSTR(name || ' ', ' ') + 1)) AS start,\n                   INSTR(name || ' ', ' ', 1, m.n) - INSTR(name || ' ', ' ') AS length\n            FROM directors,\n                 generate_series(1, (SELECT MAX(word_count) FROM directors)) AS m\n        ) AS m ON t.ROWID = m.ROWID\n    )\n);\n", error: OperationalError('no such table: generate_series')
2024-05-14 18:52:06,846 (2373/MainThread) litecli.main ERROR - traceback: 'Traceback (most recent call last):\n  File "/opt/homebrew/Cellar/litecli/1.11.0/libexec/lib/python3.12/site-packages/litecli/sqlexecute.py", line 125, in run\n    for result in special.execute(cur, sql):\n                  ^^^^^^^^^^^^^^^^^^^^^^^^^\n  File "/opt/homebrew/Cellar/litecli/1.11.0/libexec/lib/python3.12/site-packages/litecli/packages/special/main.py", line 109, in execute\n    raise CommandNotFound\nlitecli.packages.special.main.CommandNotFound\n\nDuring handling of the above exception, another exception occurred:\n\nTraceback (most recent call last):\n  File "/opt/homebrew/Cellar/litecli/1.11.0/libexec/lib/python3.12/site-packages/litecli/main.py", line 453, in one_iteration\n    for title, cur, headers, status in res:\n  File "/opt/homebrew/Cellar/litecli/1.11.0/libexec/lib/python3.12/site-packages/litecli/sqlexecute.py", line 132, in run\n    cur.execute(sql)\nsqlite3.OperationalError: no such table: generate_series\n'
2024-05-14 18:52:20,515 (2373/MainThread) litecli.main ERROR - sql: "WITH RECURSIVE SplitNames AS (\n    SELECT\n        name,\n        SUBSTR(name, 1, INSTR(name || ' ', ' ') - 1) AS word,\n        SUBSTR(name, INSTR(name || ' ', ' ') + 1) AS remaining\n    FROM directors\n    WHERE name LIKE '% %'\n    UNION ALL\n    SELECT\n        name,\n        SUBSTR(remaining, 1, INSTR(remaining || ' ', ' ') - 1) AS word,\n        SUBSTR(remaining, INSTR(remaining || ' ', ' ') + 1) AS remaining\n    FROM SplitNames\n    WHERE remaining LIKE '% %'\n    UNION ALL\n    SELECT\n        name,\n        remaining AS word,\n        NULL AS remaining\n    FROM SplitNames\n    WHERE remaining NOT LIKE '% %'\n)\nUPDATE directors\nSET name = (\n    SELECT GROUP_CONCAT(UPPER(SUBSTR(word, 1, 1)) || LOWER(SUBSTR(word, 2)), ' ')\n    FROM SplitNames\n    WHERE name = directors.name\n);\n", error: IntegrityError('NOT NULL constraint failed: directors.name')
2024-05-14 18:52:20,516 (2373/MainThread) litecli.main ERROR - traceback: 'Traceback (most recent call last):\n  File "/opt/homebrew/Cellar/litecli/1.11.0/libexec/lib/python3.12/site-packages/litecli/sqlexecute.py", line 125, in run\n    for result in special.execute(cur, sql):\n                  ^^^^^^^^^^^^^^^^^^^^^^^^^\n  File "/opt/homebrew/Cellar/litecli/1.11.0/libexec/lib/python3.12/site-packages/litecli/packages/special/main.py", line 109, in execute\n    raise CommandNotFound\nlitecli.packages.special.main.CommandNotFound\n\nDuring handling of the above exception, another exception occurred:\n\nTraceback (most recent call last):\n  File "/opt/homebrew/Cellar/litecli/1.11.0/libexec/lib/python3.12/site-packages/litecli/main.py", line 453, in one_iteration\n    for title, cur, headers, status in res:\n  File "/opt/homebrew/Cellar/litecli/1.11.0/libexec/lib/python3.12/site-packages/litecli/sqlexecute.py", line 132, in run\n    cur.execute(sql)\nsqlite3.IntegrityError: NOT NULL constraint failed: directors.name\n'
2024-05-14 18:52:45,253 (2373/MainThread) litecli.main ERROR - sql: "WITH RECURSIVE SplitNames AS (\n    SELECT\n        ROWID,\n        name,\n        SUBSTR(name, 1, INSTR(name || ' ', ' ') - 1) AS word,\n        SUBSTR(name, INSTR(name || ' ', ' ') + 1) AS remaining\n    FROM directors\n    WHERE name LIKE '% %'\n    UNION ALL\n    SELECT\n        ROWID,\n        name,\n        SUBSTR(remaining, 1, INSTR(remaining || ' ', ' ') - 1) AS word,\n        SUBSTR(remaining, INSTR(remaining || ' ', ' ') + 1) AS remaining\n    FROM SplitNames\n    WHERE remaining LIKE '% %'\n    UNION ALL\n    SELECT\n        ROWID,\n        name,\n        remaining AS word,\n        NULL AS remaining\n    FROM SplitNames\n    WHERE remaining NOT LIKE '% %'\n)\nUPDATE directors\nSET name = (\n    SELECT GROUP_CONCAT(UPPER(SUBSTR(word, 1, 1)) || LOWER(SUBSTR(word, 2)), ' ')\n    FROM SplitNames\n    WHERE directors.ROWID = SplitNames.ROWID\n);\n", error: IntegrityError('NOT NULL constraint failed: directors.name')
2024-05-14 18:52:45,253 (2373/MainThread) litecli.main ERROR - traceback: 'Traceback (most recent call last):\n  File "/opt/homebrew/Cellar/litecli/1.11.0/libexec/lib/python3.12/site-packages/litecli/sqlexecute.py", line 125, in run\n    for result in special.execute(cur, sql):\n                  ^^^^^^^^^^^^^^^^^^^^^^^^^\n  File "/opt/homebrew/Cellar/litecli/1.11.0/libexec/lib/python3.12/site-packages/litecli/packages/special/main.py", line 109, in execute\n    raise CommandNotFound\nlitecli.packages.special.main.CommandNotFound\n\nDuring handling of the above exception, another exception occurred:\n\nTraceback (most recent call last):\n  File "/opt/homebrew/Cellar/litecli/1.11.0/libexec/lib/python3.12/site-packages/litecli/main.py", line 453, in one_iteration\n    for title, cur, headers, status in res:\n  File "/opt/homebrew/Cellar/litecli/1.11.0/libexec/lib/python3.12/site-packages/litecli/sqlexecute.py", line 132, in run\n    cur.execute(sql)\nsqlite3.IntegrityError: NOT NULL constraint failed: directors.name\n'
2024-05-14 19:00:59,781 (3321/MainThread) litecli.main ERROR - sql: 'select id, employee_id from employees;', error: OperationalError('no such column: employee_id')
2024-05-14 19:00:59,783 (3321/MainThread) litecli.main ERROR - traceback: 'Traceback (most recent call last):\n  File "/opt/homebrew/Cellar/litecli/1.11.0/libexec/lib/python3.12/site-packages/litecli/sqlexecute.py", line 125, in run\n    for result in special.execute(cur, sql):\n                  ^^^^^^^^^^^^^^^^^^^^^^^^^\n  File "/opt/homebrew/Cellar/litecli/1.11.0/libexec/lib/python3.12/site-packages/litecli/packages/special/main.py", line 109, in execute\n    raise CommandNotFound\nlitecli.packages.special.main.CommandNotFound\n\nDuring handling of the above exception, another exception occurred:\n\nTraceback (most recent call last):\n  File "/opt/homebrew/Cellar/litecli/1.11.0/libexec/lib/python3.12/site-packages/litecli/main.py", line 453, in one_iteration\n    for title, cur, headers, status in res:\n  File "/opt/homebrew/Cellar/litecli/1.11.0/libexec/lib/python3.12/site-packages/litecli/sqlexecute.py", line 132, in run\n    cur.execute(sql)\nsqlite3.OperationalError: no such column: employee_id\n'
2024-05-14 20:01:44,904 (12858/MainThread) litecli.main ERROR - sql: 'select * from films limit 10 where id > 1034 and id < 1070;', error: OperationalError('near "where": syntax error')
2024-05-14 20:01:44,907 (12858/MainThread) litecli.main ERROR - traceback: 'Traceback (most recent call last):\n  File "/opt/homebrew/Cellar/litecli/1.11.0/libexec/lib/python3.12/site-packages/litecli/sqlexecute.py", line 125, in run\n    for result in special.execute(cur, sql):\n                  ^^^^^^^^^^^^^^^^^^^^^^^^^\n  File "/opt/homebrew/Cellar/litecli/1.11.0/libexec/lib/python3.12/site-packages/litecli/packages/special/main.py", line 109, in execute\n    raise CommandNotFound\nlitecli.packages.special.main.CommandNotFound\n\nDuring handling of the above exception, another exception occurred:\n\nTraceback (most recent call last):\n  File "/opt/homebrew/Cellar/litecli/1.11.0/libexec/lib/python3.12/site-packages/litecli/main.py", line 453, in one_iteration\n    for title, cur, headers, status in res:\n  File "/opt/homebrew/Cellar/litecli/1.11.0/libexec/lib/python3.12/site-packages/litecli/sqlexecute.py", line 132, in run\n    cur.execute(sql)\nsqlite3.OperationalError: near "where": syntax error\n'
2024-05-14 20:03:21,655 (12858/MainThread) litecli.main ERROR - sql: 'select * from films limit 10 where id > 1034 and id < 1070;', error: OperationalError('near "where": syntax error')
2024-05-14 20:03:21,656 (12858/MainThread) litecli.main ERROR - traceback: 'Traceback (most recent call last):\n  File "/opt/homebrew/Cellar/litecli/1.11.0/libexec/lib/python3.12/site-packages/litecli/sqlexecute.py", line 125, in run\n    for result in special.execute(cur, sql):\n                  ^^^^^^^^^^^^^^^^^^^^^^^^^\n  File "/opt/homebrew/Cellar/litecli/1.11.0/libexec/lib/python3.12/site-packages/litecli/packages/special/main.py", line 109, in execute\n    raise CommandNotFound\nlitecli.packages.special.main.CommandNotFound\n\nDuring handling of the above exception, another exception occurred:\n\nTraceback (most recent call last):\n  File "/opt/homebrew/Cellar/litecli/1.11.0/libexec/lib/python3.12/site-packages/litecli/main.py", line 453, in one_iteration\n    for title, cur, headers, status in res:\n  File "/opt/homebrew/Cellar/litecli/1.11.0/libexec/lib/python3.12/site-packages/litecli/sqlexecute.py", line 132, in run\n    cur.execute(sql)\nsqlite3.OperationalError: near "where": syntax error\n'
2024-05-14 20:44:31,860 (18492/MainThread) litecli.main ERROR - sql: "select id, title from films where name = 'Maestro'", error: OperationalError('no such column: name')
2024-05-14 20:44:31,864 (18492/MainThread) litecli.main ERROR - traceback: 'Traceback (most recent call last):\n  File "/opt/homebrew/Cellar/litecli/1.11.0/libexec/lib/python3.12/site-packages/litecli/sqlexecute.py", line 125, in run\n    for result in special.execute(cur, sql):\n                  ^^^^^^^^^^^^^^^^^^^^^^^^^\n  File "/opt/homebrew/Cellar/litecli/1.11.0/libexec/lib/python3.12/site-packages/litecli/packages/special/main.py", line 109, in execute\n    raise CommandNotFound\nlitecli.packages.special.main.CommandNotFound\n\nDuring handling of the above exception, another exception occurred:\n\nTraceback (most recent call last):\n  File "/opt/homebrew/Cellar/litecli/1.11.0/libexec/lib/python3.12/site-packages/litecli/main.py", line 453, in one_iteration\n    for title, cur, headers, status in res:\n  File "/opt/homebrew/Cellar/litecli/1.11.0/libexec/lib/python3.12/site-packages/litecli/sqlexecute.py", line 132, in run\n    cur.execute(sql)\nsqlite3.OperationalError: no such column: name\n'
2024-05-14 20:48:20,593 (18492/MainThread) litecli.main ERROR - sql: 'select * from oscars where year > 2023', error: OperationalError('no such column: year')
2024-05-14 20:48:20,594 (18492/MainThread) litecli.main ERROR - traceback: 'Traceback (most recent call last):\n  File "/opt/homebrew/Cellar/litecli/1.11.0/libexec/lib/python3.12/site-packages/litecli/sqlexecute.py", line 125, in run\n    for result in special.execute(cur, sql):\n                  ^^^^^^^^^^^^^^^^^^^^^^^^^\n  File "/opt/homebrew/Cellar/litecli/1.11.0/libexec/lib/python3.12/site-packages/litecli/packages/special/main.py", line 109, in execute\n    raise CommandNotFound\nlitecli.packages.special.main.CommandNotFound\n\nDuring handling of the above exception, another exception occurred:\n\nTraceback (most recent call last):\n  File "/opt/homebrew/Cellar/litecli/1.11.0/libexec/lib/python3.12/site-packages/litecli/main.py", line 453, in one_iteration\n    for title, cur, headers, status in res:\n  File "/opt/homebrew/Cellar/litecli/1.11.0/libexec/lib/python3.12/site-packages/litecli/sqlexecute.py", line 132, in run\n    cur.execute(sql)\nsqlite3.OperationalError: no such column: year\n'
2024-05-14 20:49:18,973 (21546/MainThread) litecli.main ERROR - sql: 'gs', error: OperationalError('near "gs": syntax error')
2024-05-14 20:49:18,975 (21546/MainThread) litecli.main ERROR - traceback: 'Traceback (most recent call last):\n  File "/opt/homebrew/Cellar/litecli/1.11.0/libexec/lib/python3.12/site-packages/litecli/sqlexecute.py", line 125, in run\n    for result in special.execute(cur, sql):\n                  ^^^^^^^^^^^^^^^^^^^^^^^^^\n  File "/opt/homebrew/Cellar/litecli/1.11.0/libexec/lib/python3.12/site-packages/litecli/packages/special/main.py", line 109, in execute\n    raise CommandNotFound\nlitecli.packages.special.main.CommandNotFound\n\nDuring handling of the above exception, another exception occurred:\n\nTraceback (most recent call last):\n  File "/opt/homebrew/Cellar/litecli/1.11.0/libexec/lib/python3.12/site-packages/litecli/main.py", line 453, in one_iteration\n    for title, cur, headers, status in res:\n  File "/opt/homebrew/Cellar/litecli/1.11.0/libexec/lib/python3.12/site-packages/litecli/sqlexecute.py", line 132, in run\n    cur.execute(sql)\nsqlite3.OperationalError: near "gs": syntax error\n'
2024-05-14 21:14:47,724 (24934/MainThread) litecli.main ERROR - sql: 'SELECT films.id, \n       title, \n       directors.NAME \nFROM   directors \n       JOIN film_directors \n         ON film_directors.director_id = directors.id \n       JOIN films \n         ON films.id = film_directors.film_id ', error: OperationalError('no such table: directors')
2024-05-14 21:14:47,727 (24934/MainThread) litecli.main ERROR - traceback: 'Traceback (most recent call last):\n  File "/opt/homebrew/Cellar/litecli/1.11.0/libexec/lib/python3.12/site-packages/litecli/sqlexecute.py", line 125, in run\n    for result in special.execute(cur, sql):\n                  ^^^^^^^^^^^^^^^^^^^^^^^^^\n  File "/opt/homebrew/Cellar/litecli/1.11.0/libexec/lib/python3.12/site-packages/litecli/packages/special/main.py", line 109, in execute\n    raise CommandNotFound\nlitecli.packages.special.main.CommandNotFound\n\nDuring handling of the above exception, another exception occurred:\n\nTraceback (most recent call last):\n  File "/opt/homebrew/Cellar/litecli/1.11.0/libexec/lib/python3.12/site-packages/litecli/main.py", line 453, in one_iteration\n    for title, cur, headers, status in res:\n  File "/opt/homebrew/Cellar/litecli/1.11.0/libexec/lib/python3.12/site-packages/litecli/sqlexecute.py", line 132, in run\n    cur.execute(sql)\nsqlite3.OperationalError: no such table: directors\n'
